Workbook
Name accper: Calculation!$C$10
Name AER: #REF!
Name AER: #REF!
Name AFFH: #REF!
Name AFFH: #REF!
Name AFS: #REF!
Name AFS: #REF!
Name AGCCJP: [1]Data!#REF!
Name AGCCJP: [2]Data!#REF!
Name Alternate_Nationality: #REF!
Name AltNationality_Score: Calculation!$B$14
Name AM: #REF!
Name AM: [3]Sector!#REF!
Name AML_Risk_level: #REF!
Name AML_Risk_level: #REF!
Name AML_Risk_Score: #REF!
Name amlo_range: '[4]Landing Page'!$C$11,'[4]Landing Page'!$C$15
Name amlo_range: '[4]Landing Page'!$C$11,'[4]Landing Page'!$C$15
Name amlo_range: '[4]Landing Page'!$C$11,'[4]Landing Page'!$C$15
Name amlo_range: '[5]Landing Page'!$C$11,'[5]Landing Page'!$C$12,'[5]Landing Page'!$C$15
Name AMLRO: #REF!
Name APA: #REF!
Name APA: [3]Sector!#REF!
Name ASWMRS: #REF!
Name ASWMRS: #REF!
Name Beneficiary_type: #REF!
Name BeneficiaryType_Score: Calculation!$B$10
Name BenfType: #REF!
Name BirthCountry_Score: Calculation!$B$12
Name BMGESD: #REF!
Name BMGESD: [3]Sector!#REF!
Name Branch_Code: #REF!
Name Branch_Name: #REF!
Name BTPM: #REF!
Name BTPM: [3]Sector!#REF!
Name CB: #REF!
Name CB: [3]Sector!#REF!
Name CCAS: #REF!
Name CCAS: [3]Sector!#REF!
Name CEPM: #REF!
Name CEPM: [3]Sector!#REF!
Name Channel_Info: '[4]Landing Page'!$C$57:$C$60,'[4]Landing Page'!$F$57:$F$60
Name Channel_Info: '[5]Landing Page'!$C$57:$C$60,'[5]Landing Page'!$F$57:$F$60
Name Channel_Info: '[4]Landing Page'!$C$57:$C$60,'[4]Landing Page'!$F$57:$F$60
Name Channel_Info: '[4]Landing Page'!$C$57:$C$60,'[4]Landing Page'!$F$57:$F$60
Name Channel_Info: '[6]Landing Page'!$C$63:$C$66,'[6]Landing Page'!$F$63:$F$66
Name CM: #REF!
Name CM: [3]Sector!#REF!
Name Comments: '[4]Landing Page'!#REF!
Name Comments: '[5]Landing Page'!#REF!
Name Comments: '[4]Landing Page'!#REF!
Name Comments: '[4]Landing Page'!#REF!
Name Comments: #REF!
Name Construction: #REF!
Name Construction: #REF!
Name countr: [1]Data!$B$3:$B$164
Name countr: [7]Data!$B$3:$B$164
Name countr: [7]Data!$B$3:$B$164
Name countr: [7]Data!$B$3:$B$164
Name countr: [7]Data!$B$3:$B$164

Sheet Guidelines
A1: Purpose | C1: The purpose of this model is to dynamically calculate the customer risk rating of an Individual customer: - At the time of on-boarding a new customer - Periodic review of an existing customer - Trigger based event for an existing customer
A3: Model description | C3: The Customer Risk Assessment Model is based on five compliance risk factors: "Customer Type", "Geography", "Products & Services" , "Channel & Interface" and "Transaction". Within each risk factor, parameters have been defined and assigned a risk score. Subsequently each risk factor has been assigned a weight basis which the client's final risk rating is computed.
A5: Input guidelines | C5: 1. Ensure accurate information is entered in the model. For any information that is unavailable, it is advisable to obtain it from the customers. 2. Avoid using "Not Applicable" or "Others" until and unless necessary.
A7: Output | C7: Based on the input data, the model will generate a risk rating of the customer.

Sheet Working
A3: Customer Information
A5: Customer Name | B5: Mr. ____ | D5: Type of Event | E5: Periodic assessment
A6: Customer Relationship | B6: Existing
A7: Customer ID (CIF) | D7: Description
A8: Customer Status | B8: Active
A9: Customer Segment | B9: Assessed Professional
A10: Average Expected Transaction Value Per Annum | B10: Above USD 5 million
A11: PEP Status | B11: Not Applicable
A12: Residency Status (UAE) | B12: Non Resident
A13: Country of Residence | B13: Jordan
A14: Country of Birth | B14: Jordan
A15: Primary Nationality | B15: Jordan
A16: Source of Wealth Jurisdiction | B16: Jordan
A17: Source of Fund Jurisdiction | B17: Jordan
A18: Does the Customer have Dual Nationality | B18: Yes
A19: Alternate Nationality | B19: Not applicable
A20: Screening Matches (Sanction) | B20: No Match
A22: Business/Employment Information
A24: Employment Status | B24: Business Owner | D24: Description
A25: Profession | B25: Business(Owner)
A26: Nature of Business | B26: Construction (including contracting)
A27: Signatory Mandate | B27: Single Authorized Signatory
A41: Product/Service Information
E42: Comment and Rationale
A43: Product (Highest Risk) | B43: Bonds
A44: Services (Highest Risk) | B44: Hold and Control Client Money
A46: Customer Interface and Channel Information
A48: Product and Services Relation Initiation Method | B48: Face to Face | D48: Product and Services Service Delivery Method | E48: E Channel
A50: Transaction Information
A52: Number of Investigations Carried Out in Last 1 Year | B52: 0 | D52: Description
A53: Number of STR Filed in Last 1 Year | B53: 0
A60: Relationship Manager
A62: RM Name
A63: RM ID
A64: RM Comment
A65: Prepared by | D65: Reviewed by
A66: Preparation Date(DD/MM/YYYY) | D66: Review Date(DD/MM/YYYY)
D67: Signature
A69: MLRO Assessment
A71: MLRO Name
...

Sheet Calculation
A1: Parameter | B1: Selected Score | C1: Parameter Weightage (%) | D1: Weightage Score | E1: Risk Factor score | F1: Risk Factor | G1: Final Risk Factor weightage (%)
A2: Customer segment | B2: 0 | C2: 0 | D2: =B2*(C2/100) -> 0 | E2: =D3+D5+D6+D7+D8+D10 -> 2.6 | F2: Customer type Risk | G2: 35
A3: Average expected transaction value per annum | B3: =VLOOKUP(Working!B10,'Customer Type Risk'!C38:D40,2,FALSE) -> 3 | C3: 15 | D3: =B3*(C3/100) -> 0.45
A4: PEP Status | B4: =VLOOKUP(Working!B11,'Customer Type Risk'!C34:D37,2,FALSE) -> 0 | C4: =Working!B11 -> Not Applicable | D4: =PEP_Score -> 0
A5: Residency Status | B5: =VLOOKUP(Working!B12,'Customer Type Risk'!C10:D11,2,FALSE) -> 3 | C5: 20 | D5: =B5*(C5/100) -> 0.6
A6: Employment Status | B6: =VLOOKUP(Working!B24,'Customer Type Risk'!C13:D23,2,FALSE) -> 3 | C6: 15 | D6: =B6*(C6/100) -> 0.45
A7: Profession | B7: =VLOOKUP(Working!B25,'Customer Type Risk'!I10:K746,2,FALSE) -> 3 | C7: 20 | D7: =B7*(C7/100) -> 0.6
A8: Nature of business | B8: =VLOOKUP(Working!B26,'Customer Type Risk'!O10:P180,2,FALSE) -> 2 | C8: 20 | D8: =B8*(C8/100) -> 0.4
A9: Screening matches | B9: =VLOOKUP(Working!B20,'Customer Type Risk'!C42:E46,2,FALSE) -> 0 | C9: =VLOOKUP(Working!B20,'Customer Type Risk'!C42:E46,3,FALSE) -> Allowed | D9: =B9 -> 0
A10: Signatory Mandate | B10: =VLOOKUP(Working!B27,'Customer Type Risk'!C28:D32,2,FALSE) -> 1 | C10: 10 | D10: =B10*(C10/100) -> 0.1
A11: Country of Residence | B11: =VLOOKUP(Working!B13,'Country Risk'!B11:J261,9,FALSE) -> 1.35 | C11: Take greatest score | E11: =MAX(B11:B16) -> 1.35 | F11: Geography Risk | G11: 30
A12: Country of Birth | B12: =VLOOKUP(Working!B14,'Country Risk'!B11:J261,9,FALSE) -> 1.35
A13: Primary Nationality | B13: =VLOOKUP(Working!B15,'Country Risk'!B11:J261,9,FALSE) -> 1.35
A14: Alternate Nationality | B14: =VLOOKUP(Working!B19,'Country Risk'!B10:J261,9,FALSE) -> 1
A15: Source of Wealth Jurisdiction | B15: =VLOOKUP(Working!B16,'Country Risk'!B11:J261,9,FALSE) -> 1.35
A16: Source of Fund Jurisdiction | B16: =VLOOKUP(Working!B17,'Country Risk'!B11:J261,9,FALSE) -> 1.35
A17: Product | B17: =VLOOKUP(Working!B43,'Product Risk'!$B$12:$C$26,2,FALSE) -> 1.2222222 | C17: Take greatest score | D17: =B17 -> 1.2222222 | E17: =IF(B18>=B17,B18,B17) -> 2.14 | F17: Product Risk | G17: 25
A18: Service | B18: =ROUND(VLOOKUP(Working!B44,'Service Risk'!$B$12:$C$18,2,FALSE),2) -> 2.14 | D18: =B18 -> 2.14
A19: Relation initiation method | B19: =VLOOKUP(Working!B48,'Delivery Channel Risk'!$B$5:$C$7,2,FALSE) -> 1.4 | C19: Take score and apply 50% | D19: =B19 -> 1.4 | E19: =(D19*50%)+(D20*50%) -> 1.8 | F19: Channel risk | G19: 10
A20: Service Delivery Method | B20: =VLOOKUP(Working!E48,'Delivery Channel Risk'!$B$17:$C$19,2,FALSE) -> 2.2 | C20: Take score and apply 50% | D20: =B20 -> 2.2
A21: Transaction Investigation Risk | B21: =VLOOKUP(Working!B52,'Transaction Investigation Risk'!C7:D9,2,FALSE) -> 0 | C21: Override if High | E21: =IF(B21=3,"HIGH","No Override") -> No Override | F21: Transaction and STR risk
A22: STR | B22: =VLOOKUP(Working!B53,'Transaction Investigation Risk'!C13:D14,2,FALSE) -> 0 | C22: Override if High | E22: =IF(B22=3,"HIGH","No Override") -> No Override
E23: =_xlfn.IFNA(E2*(G2/100)+E11*(G11/100)+E17*(G17/100)+E19*(G19/100),0) -> 2.03 | F23: Overall score
A25: Risk Level | B25: To | C25: From | D25: Final number score | E25: Over Ride to High Risk Factors
A26: High Risk | B26: 2.01 | C26: 3 | D26: 3 | E26: PEP | F26: =IF(PEP_Score=3,"PEP Override","No") -> No
A27: Medium Risk | B27: 1.01 | C27: 2 | D27: 2 | E27: Screening | F27: =IF(B9=3,"Screening Override","No") -> No
A28: Low Risk | B28: 0 | C28: 1 | D28: 1 | E28: Transaction | F28: =IF(B21=3,"Transaction Override","No") -> No
E29: STR | F29: =IF(B22=3,"STR Override","No") -> No
E30: Over Ride to High Risk | F30: =IF(OR(B4=3,B9=3,B21=3,B22=3),"Yes","No") -> No
E31: Prohibition Factors
E32: Screening | F32: =IF(B9=4,"yes","No") -> No
E33: Nature of Business | F33: =IF(Industry_Score=4,"Yes","No") -> No
E34: Nationality | F34: =IF(OR(PrmNationality_Score>=5,AltNationality_Score>=5,BirthCountry_Score>=5),"Yes","No") -> No
E35: Residency | F35: =IF(OR(ResidenceCountry_Score>=4,B15>=4),"Yes","No") -> No
E36: Prohibit | F36: =IF(OR(F32="Yes",F33="Yes",F34="Yes",F35="Yes"),"Yes","No") -> No

Sheet Sheet2
A1: jap2023*

Sheet Review Periodicity
A1: Review Periodicity
A3: High Risk | B3: 12
A4: Medium Risk | B4: 24
A5: Low Risk | B5: 36

Sheet Customer Type Risk
A1: AML Individual Customer Risk Rating
A2: Rating scale
A3: Ranking | B3: Rating
A4: High | B4: 3
A5: Medium | B5: 2
A6: Low | B6: 1
A8: INDIVIDUAL CUSTOMER
A9: Risk Factor | B9: Weightage | C9: Status | D9: Rating | E9: Override To | G9: Risk Factor | H9: Weightage | I9: Type | J9: Rating | K9: Override To | M9: Risk Factor | N9: Weightage | O9: Type | P9: Rating | Q9: Override To
A10: Residence Status | B10: 0.2 | C10: Resident | D10: 1 | G10: Profession | H10: 0.2 | I10: Accountant | J10: 3 | M10: Nature of Business | N10: 0.2 | O10: Activities of call centers | P10: 1
C11: Non Resident | D11: 3 | I11: Accounting Clerk | J11: 1 | O11: Activities of holding companies | P11: 3
I12: Accounting Manager | J12: 3 | O12: Activities of membership organizations | P12: 1
A13: Employment Status | B13: 0.15 | C13: Salaried from government/ semi-government sector | D13: 1 | I13: Actor | J13: 2 | O13: Administration of financial markets | P13: 3
C14: Salaried from private sector (Including multi-national companies) | D14: 2 | I14: Administration Manager | J14: 1 | O14: Administration/Clerical Services | P14: 1
C15: Salaried from free-zone corporations | D15: 2 | I15: Administrative Officer | J15: 1 | O15: Advertising and Marketing | P15: 1
C16: Self Employed/Freelancer | D16: 3 | I16: Advertising Designer | J16: 1 | O16: Aerospace manufacturing and related technologies | P16: 3
C17: Business Owner | D17: 3 | I17: Advertising Representative | J17: 1 | O17: Agriculture | P17: 1
C18: Student | D18: 1 | I18: Aged Care Services Manager | J18: 1 | O18: Alcohol and Drug Abuse Counseling | P18: 4 | Q18: Prohibited
C19: House Wife / Dependent | D19: 2 | I19: Agricultural Manager | J19: 1 | O19: All Others | P19: 2
C20: Retired | D20: 1 | I20: Agricultural Mechanic | J20: 1 | O20: Amusement Parks, Circuses, Carnivals and Fortune Tellers | P20: 4 | Q20: Prohibited
C21: Unemployed | D21: 3 | I21: Agricultural Technician | J21: 1 | O21: Animal and Poultry Farming | P21: 1
C22: Others | D22: 3 | I22: Agriculture Engineer | J22: 2 | O22: Art or Antique Dealer | P22: 3 | Q22: High Risk
C23: Employee | D23: 1 | I23: Agriculture Labourer | J23: 1 | O23: Asset Management | P23: 3 | Q23: High Risk
I24: Air Conditioning Assistant | J24: 1 | O24: Auction Houses | P24: 3 | Q24: High Risk
A25: Customer Segment | B25: 0 | C25: Assessed Professional | D25: 1 | I25: Air Conditioning Mechanic | J25: 1 | O25: Bail and Bond Payment Providers | P25: 4 | Q25: Prohibited
C26: Deemed Professional | D26: 1 | I26: Air Freight Clerk | J26: 1 | O26: Ballet & Ballroom Institutions | P26: 4 | Q26: Prohibited
I27: Air Traffic Controller | J27: 1 | O27: Bands, Orchestras, and Miscellaneous Entertainers | P27: 4 | Q27: Prohibited
A28: Signatory Mandate | B28: 0.1 | C28: Single Authorized Signatory | D28: 1 | I28: Aircarft Deport Operator | J28: 1 | O28: Basic chemicals manufacturing and trade (Non-Defense related) | P28: 1
C29: Multiple Authorized Signatories | D29: 2 | I29: Aircraft Electrician | J29: 1 | O29: Brokerage - Mortgage and Loans | P29: 4 | Q29: Prohibited
C30: Power of Attorney | D30: 3 | I30: Aircraft Engine Mechanic | J30: 1 | O30: Brokerage - Others | P30: 3 | Q30: High Risk
C31: Parent/Legal Guardian | D31: 2 | I31: Aircraft Fuelling Operator | J31: 1 | O31: Building and Industrial cleaning activities | P31: 1
C32: Joint Account | D32: 2 | I32: Airframe Mechanic | J32: 1 | O32: Bullion / Commodity Traders | P32: 3 | Q32: High Risk
I33: Airport Check-in Agent | J33: 3 | K33: High | O33: Casinos, Gambling, Betting and Adult Entertainment | P33: 4 | Q33: Prohibited
A34: PEP Status | B34: Override | C34: Domestic PEP | D34: 2 | I34: Airport Director | J34: 3 | O34: Central Banks | P34: 3 | Q34: High Risk
C35: Foreign PEP | D35: 3 | E35: High Risk | I35: All Vehicles Driver | J35: 1 | O35: Central Government – UAE, GCC or FATF Member State | P35: 1
C36: Head of International Organization | D36: 2 | I36: Aluminium Fabricator | J36: 1 | O36: Charities and Trade Unions (including association and clubs) | P36: 3 | Q36: High Risk
C37: Not Applicable | D37: 0 | I37: Anaesthetist | J37: 1 | O37: Chemicals manufacturing and trade | P37: 3 | Q37: High Risk
A38: Average expected transaction value per annum | B38: 0.15 | C38: Up to USD 1 million | D38: 1 | I38: Aquaculture Production Manager | J38: 1 | O38: Chemicals manufacturing and trade (UN Member Country Government Defense related) | P38: 1
C39: USD 1 million to USD 5 million | D39: 2 | I39: Aquaculture Rearing Technician | J39: 1 | O39: Cigar Stores and Stands | P39: 4 | Q39: Prohibited
C40: Above USD 5 million | D40: 3 | I40: Arabic Coffee Maker | J40: 1 | O40: Cinemas (including Motion Picture, Video Tape, Theatrical Production and Distribution) | P40: 3 | Q40: High Risk
I41: Arabic Food Cook | J41: 2 | O41: Civil Servants (including Police) | P41: 2
...

Sheet Country Risk
A1: AML Country Risk Rating
B2: Rating scale
B3: Ranking | C3: Range lower | D3: Range upper
B4: High | C4: 2.01 | D4: 3
B5: Medium | C5: 1.01 | D5: 2
B6: Low | C6: 0 | D6: 1
B8: Country | C8: FATF AML/CFT Deficient Country | D8: BASEL Index * | E8: Sanctions | F8: Terrorist Safe Havens | G8: Overall Country Rating | H8: Overall Country Ranking | I8: Firm's Risk Override | J8: Firm's Score Override | L8: Basel Index Covers:
B9: Weightage | C9: 0.3 | D9: 0.35 | E9: 0.3 | F9: 0.05 | G9: =SUM(C9:F9) -> 1 | L9: ML/TF Risk | M9: 0.65
B10: Not applicable | C10: 1 | D10: 1 | E10: 1 | F10: 1 | G10: =C10*$C$9+D10*$D$9+E10*$E$9+F10*$F$9 -> 1 | H10: =IF(AND(G10>=$C$6,G10<=$D$6),$B$6,IF(AND(G10>=$C$5,G10<=$D$5),$B$5,IF(AND(G10>=$C$4,G10<=$D$4),$B$4))) -> Low | J10: =IF(OR(I10="Prohibited", I10="FATF Grey List"), IF(I10="Prohibited", 4, 3), G10) -> 1 | K10: =IF(AND(J10>=$C$6,J10<=$D$6),$B$6,IF(AND(J10>=$C$5,J10<=$D$5),$B$5,IF(AND(J10>=$C$4,J10<=$D$4),$B$4,IF(AND(J10>=#REF!,J10<=#REF!),#REF!)))) -> Low | L10: FATF Mutual Evaluation Reports | M10: 0.35
B11: United Arab Emirates | C11: =[11]FATF!D3 -> 1 | D11: =[11]BASEL!H4 -> 2 | E11: 1 | F11: 1 | G11: =C11*$C$9+D11*$D$9+E11*$E$9+F11*$F$9 -> 1.35 | H11: =IF(AND(G11>=$C$6,G11<=$D$6),$B$6,IF(AND(G11>=$C$5,G11<=$D$5),$B$5,IF(AND(G11>=$C$4,G11<=$D$4),$B$4,IF(AND(G11>=#REF!,G11<=#REF!),#REF!)))) -> Medium | J11: =IF(OR(I11="Prohibited", I11="FATF Grey List"), IF(I11="Prohibited", 4, 3), G11) -> 1.35 | K11: =IF(AND(J11>=$C$6,J11<=$D$6),$B$6,IF(AND(J11>=$C$5,J11<=$D$5),$B$5,IF(AND(J11>=$C$4,J11<=$D$4),$B$4,IF(AND(J11>=#REF!,J11<=#REF!),#REF!)))) -> Medium | L11: Financial Secrecy Index | M11: 0.15
B12: Afghanistan | C12: 2 | D12: =[11]BASEL!H5 -> 3 | E12: 2 | F12: 3 | G12: =C12*$C$9+D12*$D$9+E12*$E$9+F12*$F$9 -> 2.4 | H12: =IF(AND(G12>=$C$6,G12<=$D$6),$B$6,IF(AND(G12>=$C$5,G12<=$D$5),$B$5,IF(AND(G12>=$C$4,G12<=$D$4),$B$4))) -> High | J12: =IF(OR(I12="Prohibited", I12="FATF Grey List"), IF(I12="Prohibited", 4, 3), G12) -> 2.4 | K12: =IF(AND(J12>=$C$6,J12<=$D$6),$B$6,IF(AND(J12>=$C$5,J12<=$D$5),$B$5,IF(AND(J12>=$C$4,J12<=$D$4),$B$4,IF(AND(J12>=#REF!,J12<=#REF!),#REF!)))) -> High | L12: US International Narcotics Control Strategy Report | M12: 0.05
B13: Aland Islands** | C13: 2 | D13: 2 | E13: 1 | F13: 1 | G13: =C13*$C$9+D13*$D$9+E13*$E$9+F13*$F$9 -> 1.65 | H13: =IF(AND(G13>=$C$6,G13<=$D$6),$B$6,IF(AND(G13>=$C$5,G13<=$D$5),$B$5,IF(AND(G13>=$C$4,G13<=$D$4),$B$4))) -> Medium | J13: =IF(OR(I13="Prohibited", I13="FATF Grey List"), IF(I13="Prohibited", 4, 3), G13) -> 1.65 | K13: =IF(AND(J13>=$C$6,J13<=$D$6),$B$6,IF(AND(J13>=$C$5,J13<=$D$5),$B$5,IF(AND(J13>=$C$4,J13<=$D$4),$B$4,IF(AND(J13>=#REF!,J13<=#REF!),#REF!)))) -> Medium | L13: Trafficking in persons | M13: 0.05
B14: Albania | C14: =[11]FATF!D6 -> 1 | D14: =[11]BASEL!H7 -> 2 | E14: 2 | F14: 1 | G14: =C14*$C$9+D14*$D$9+E14*$E$9+F14*$F$9 -> 1.65 | H14: =IF(AND(G14>=$C$6,G14<=$D$6),$B$6,IF(AND(G14>=$C$5,G14<=$D$5),$B$5,IF(AND(G14>=$C$4,G14<=$D$4),$B$4))) -> Medium | J14: =IF(OR(I14="Prohibited", I14="FATF Grey List"), IF(I14="Prohibited", 4, 3), G14) -> 1.65 | K14: =IF(AND(J14>=$C$6,J14<=$D$6),$B$6,IF(AND(J14>=$C$5,J14<=$D$5),$B$5,IF(AND(J14>=$C$4,J14<=$D$4),$B$4,IF(AND(J14>=#REF!,J14<=#REF!),#REF!)))) -> Medium | L14: Environmental Crime | M14: 0.05
B15: Algeria | C15: =[11]FATF!D7 -> 1 | D15: =[11]BASEL!H8 -> 3 | E15: 1 | F15: 1 | G15: =C15*$C$9+D15*$D$9+E15*$E$9+F15*$F$9 -> 1.7 | H15: =IF(AND(G15>=$C$6,G15<=$D$6),$B$6,IF(AND(G15>=$C$5,G15<=$D$5),$B$5,IF(AND(G15>=$C$4,G15<=$D$4),$B$4))) -> Medium | I15: FATF Grey List | J15: =IF(OR(I15="Prohibited", I15="FATF Grey List"), IF(I15="Prohibited", 4, 3), G15) -> 3 | K15: =IF(AND(J15>=$C$6,J15<=$D$6),$B$6,IF(AND(J15>=$C$5,J15<=$D$5),$B$5,IF(AND(J15>=$C$4,J15<=$D$4),$B$4,IF(AND(J15>=#REF!,J15<=#REF!),#REF!)))) -> High | L15: Corruption Risk | M15: 0.1
B16: American Samoa** | C16: 1 | D16: 1 | E16: 1 | F16: 1 | G16: =C16*$C$9+D16*$D$9+E16*$E$9+F16*$F$9 -> 1 | H16: =IF(AND(G16>=$C$6,G16<=$D$6),$B$6,IF(AND(G16>=$C$5,G16<=$D$5),$B$5,IF(AND(G16>=$C$4,G16<=$D$4),$B$4))) -> Low | J16: =IF(OR(I16="Prohibited", I16="FATF Grey List"), IF(I16="Prohibited", 4, 3), G16) -> 1 | K16: =IF(AND(J16>=$C$6,J16<=$D$6),$B$6,IF(AND(J16>=$C$5,J16<=$D$5),$B$5,IF(AND(J16>=$C$4,J16<=$D$4),$B$4,IF(AND(J16>=#REF!,J16<=#REF!),#REF!)))) -> Low | L16: TI Corruption Perceptions Index | M16: 0.05
B17: Andorra | C17: =[11]FATF!D9 -> 1 | D17: =[11]BASEL!H10 -> 1 | E17: 1 | F17: 1 | G17: =C17*$C$9+D17*$D$9+E17*$E$9+F17*$F$9 -> 1 | H17: =IF(AND(G17>=$C$6,G17<=$D$6),$B$6,IF(AND(G17>=$C$5,G17<=$D$5),$B$5,IF(AND(G17>=$C$4,G17<=$D$4),$B$4))) -> Low | J17: =IF(OR(I17="Prohibited", I17="FATF Grey List"), IF(I17="Prohibited", 4, 3), G17) -> 1 | K17: =IF(AND(J17>=$C$6,J17<=$D$6),$B$6,IF(AND(J17>=$C$5,J17<=$D$5),$B$5,IF(AND(J17>=$C$4,J17<=$D$4),$B$4,IF(AND(J17>=#REF!,J17<=#REF!),#REF!)))) -> Low | L17: TRACE Bribery Risk Matrix | M17: 0.05
B18: Angola | C18: =[11]FATF!D10 -> 1 | D18: =[11]BASEL!H11 -> 3 | E18: 1 | F18: 1 | G18: =C18*$C$9+D18*$D$9+E18*$E$9+F18*$F$9 -> 1.7 | H18: =IF(AND(G18>=$C$6,G18<=$D$6),$B$6,IF(AND(G18>=$C$5,G18<=$D$5),$B$5,IF(AND(G18>=$C$4,G18<=$D$4),$B$4))) -> Medium | I18: FATF Grey List | J18: =IF(OR(I18="Prohibited", I18="FATF Grey List"), IF(I18="Prohibited", 4, 3), G18) -> 3 | K18: =IF(AND(J18>=$C$6,J18<=$D$6),$B$6,IF(AND(J18>=$C$5,J18<=$D$5),$B$5,IF(AND(J18>=$C$4,J18<=$D$4),$B$4,IF(AND(J18>=#REF!,J18<=#REF!),#REF!)))) -> High | L18: Financial Transparency & Standards | M18: 0.1
B19: Anguilla | C19: =[11]FATF!D11 -> 1 | D19: =[11]BASEL!H12 -> 1 | E19: 1 | F19: 1 | G19: =C19*$C$9+D19*$D$9+E19*$E$9+F19*$F$9 -> 1 | H19: =IF(AND(G19>=$C$6,G19<=$D$6),$B$6,IF(AND(G19>=$C$5,G19<=$D$5),$B$5,IF(AND(G19>=$C$4,G19<=$D$4),$B$4))) -> Low | J19: =IF(OR(I19="Prohibited", I19="FATF Grey List"), IF(I19="Prohibited", 4, 3), G19) -> 1 | K19: =IF(AND(J19>=$C$6,J19<=$D$6),$B$6,IF(AND(J19>=$C$5,J19<=$D$5),$B$5,IF(AND(J19>=$C$4,J19<=$D$4),$B$4,IF(AND(J19>=#REF!,J19<=#REF!),#REF!)))) -> Low | L19: WB - Corporate Transparency Index | M19: 0.025
B20: Antarctica** | C20: 1 | D20: 1 | E20: 1 | F20: 1 | G20: =C20*$C$9+D20*$D$9+E20*$E$9+F20*$F$9 -> 1 | H20: =IF(AND(G20>=$C$6,G20<=$D$6),$B$6,IF(AND(G20>=$C$5,G20<=$D$5),$B$5,IF(AND(G20>=$C$4,G20<=$D$4),$B$4))) -> Low | J20: =IF(OR(I20="Prohibited", I20="FATF Grey List"), IF(I20="Prohibited", 4, 3), G20) -> 1 | K20: =IF(AND(J20>=$C$6,J20<=$D$6),$B$6,IF(AND(J20>=$C$5,J20<=$D$5),$B$5,IF(AND(J20>=$C$4,J20<=$D$4),$B$4,IF(AND(J20>=#REF!,J20<=#REF!),#REF!)))) -> Low | L20: WEF GCR Strength of auditing and reporting standards | M20: 0.05
B21: Antigua and Barbuda | C21: =[11]FATF!D13 -> 1 | D21: =[11]BASEL!H14 -> 2 | E21: 1 | F21: 1 | G21: =C21*$C$9+D21*$D$9+E21*$E$9+F21*$F$9 -> 1.35 | H21: =IF(AND(G21>=$C$6,G21<=$D$6),$B$6,IF(AND(G21>=$C$5,G21<=$D$5),$B$5,IF(AND(G21>=$C$4,G21<=$D$4),$B$4))) -> Medium | J21: =IF(OR(I21="Prohibited", I21="FATF Grey List"), IF(I21="Prohibited", 4, 3), G21) -> 1.35 | K21: =IF(AND(J21>=$C$6,J21<=$D$6),$B$6,IF(AND(J21>=$C$5,J21<=$D$5),$B$5,IF(AND(J21>=$C$4,J21<=$D$4),$B$4,IF(AND(J21>=#REF!,J21<=#REF!),#REF!)))) -> Medium | L21: WB IDA IRAI Financial Sector Regulations | M21: 0.025
B22: Argentina | C22: =[11]FATF!D14 -> 1 | D22: =[11]BASEL!H15 -> 2 | E22: 2 | F22: 1 | G22: =C22*$C$9+D22*$D$9+E22*$E$9+F22*$F$9 -> 1.65 | H22: =IF(AND(G22>=$C$6,G22<=$D$6),$B$6,IF(AND(G22>=$C$5,G22<=$D$5),$B$5,IF(AND(G22>=$C$4,G22<=$D$4),$B$4))) -> Medium | J22: =IF(OR(I22="Prohibited", I22="FATF Grey List"), IF(I22="Prohibited", 4, 3), G22) -> 1.65 | K22: =IF(AND(J22>=$C$6,J22<=$D$6),$B$6,IF(AND(J22>=$C$5,J22<=$D$5),$B$5,IF(AND(J22>=$C$4,J22<=$D$4),$B$4,IF(AND(J22>=#REF!,J22<=#REF!),#REF!)))) -> Medium | L22: Public Transparency & Accountability | M22: 0.05
B23: Armenia | C23: =[11]FATF!D15 -> 1 | D23: =[11]BASEL!H16 -> 2 | E23: 2 | F23: 1 | G23: =C23*$C$9+D23*$D$9+E23*$E$9+F23*$F$9 -> 1.65 | H23: =IF(AND(G23>=$C$6,G23<=$D$6),$B$6,IF(AND(G23>=$C$5,G23<=$D$5),$B$5,IF(AND(G23>=$C$4,G23<=$D$4),$B$4))) -> Medium | J23: =IF(OR(I23="Prohibited", I23="FATF Grey List"), IF(I23="Prohibited", 4, 3), G23) -> 1.65 | K23: =IF(AND(J23>=$C$6,J23<=$D$6),$B$6,IF(AND(J23>=$C$5,J23<=$D$5),$B$5,IF(AND(J23>=$C$4,J23<=$D$4),$B$4,IF(AND(J23>=#REF!,J23<=#REF!),#REF!)))) -> Medium | L23: Open Budget Index | M23: 0.01667
B24: Aruba | C24: =[11]FATF!D16 -> 1 | D24: =[11]BASEL!H17 -> 2 | E24: 1 | F24: 1 | G24: =C24*$C$9+D24*$D$9+E24*$E$9+F24*$F$9 -> 1.35 | H24: =IF(AND(G24>=$C$6,G24<=$D$6),$B$6,IF(AND(G24>=$C$5,G24<=$D$5),$B$5,IF(AND(G24>=$C$4,G24<=$D$4),$B$4))) -> Medium | J24: =IF(OR(I24="Prohibited", I24="FATF Grey List"), IF(I24="Prohibited", 4, 3), G24) -> 1.35 | K24: =IF(AND(J24>=$C$6,J24<=$D$6),$B$6,IF(AND(J24>=$C$5,J24<=$D$5),$B$5,IF(AND(J24>=$C$4,J24<=$D$4),$B$4,IF(AND(J24>=#REF!,J24<=#REF!),#REF!)))) -> Medium | L24: Political Disclosure | M24: 0.01667
B25: Australia | C25: =[11]FATF!D17 -> 1 | D25: =[11]BASEL!H18 -> 1 | E25: 1 | F25: 1 | G25: =C25*$C$9+D25*$D$9+E25*$E$9+F25*$F$9 -> 1 | H25: =IF(AND(G25>=$C$6,G25<=$D$6),$B$6,IF(AND(G25>=$C$5,G25<=$D$5),$B$5,IF(AND(G25>=$C$4,G25<=$D$4),$B$4))) -> Low | J25: =IF(OR(I25="Prohibited", I25="FATF Grey List"), IF(I25="Prohibited", 4, 3), G25) -> 1 | K25: =IF(AND(J25>=$C$6,J25<=$D$6),$B$6,IF(AND(J25>=$C$5,J25<=$D$5),$B$5,IF(AND(J25>=$C$4,J25<=$D$4),$B$4,IF(AND(J25>=#REF!,J25<=#REF!),#REF!)))) -> Low | L25: Transparency, accountability and corruption in the public sector | M25: 0.01667
B26: Austria | C26: =[11]FATF!D18 -> 1 | D26: =[11]BASEL!H19 -> 2 | E26: 1 | F26: 1 | G26: =C26*$C$9+D26*$D$9+E26*$E$9+F26*$F$9 -> 1.35 | H26: =IF(AND(G26>=$C$6,G26<=$D$6),$B$6,IF(AND(G26>=$C$5,G26<=$D$5),$B$5,IF(AND(G26>=$C$4,G26<=$D$4),$B$4))) -> Medium | J26: =IF(OR(I26="Prohibited", I26="FATF Grey List"), IF(I26="Prohibited", 4, 3), G26) -> 1.35 | K26: =IF(AND(J26>=$C$6,J26<=$D$6),$B$6,IF(AND(J26>=$C$5,J26<=$D$5),$B$5,IF(AND(J26>=$C$4,J26<=$D$4),$B$4,IF(AND(J26>=#REF!,J26<=#REF!),#REF!)))) -> Medium | L26: Political & Legal Risk | M26: 0.1
B27: Azerbaijan | C27: =[11]FATF!D19 -> 1 | D27: =[11]BASEL!H20 -> 2 | E27: 2 | F27: 1 | G27: =C27*$C$9+D27*$D$9+E27*$E$9+F27*$F$9 -> 1.65 | H27: =IF(AND(G27>=$C$6,G27<=$D$6),$B$6,IF(AND(G27>=$C$5,G27<=$D$5),$B$5,IF(AND(G27>=$C$4,G27<=$D$4),$B$4))) -> Medium | J27: =IF(OR(I27="Prohibited", I27="FATF Grey List"), IF(I27="Prohibited", 4, 3), G27) -> 1.65 | K27: =IF(AND(J27>=$C$6,J27<=$D$6),$B$6,IF(AND(J27>=$C$5,J27<=$D$5),$B$5,IF(AND(J27>=$C$4,J27<=$D$4),$B$4,IF(AND(J27>=#REF!,J27<=#REF!),#REF!)))) -> Medium | L27: WEF GCR Institutional Strength | M27: 0.025
B28: Bahamas | C28: =[11]FATF!D20 -> 1 | D28: =[11]BASEL!H21 -> 2 | E28: 1 | F28: 1 | G28: =C28*$C$9+D28*$D$9+E28*$E$9+F28*$F$9 -> 1.35 | H28: =IF(AND(G28>=$C$6,G28<=$D$6),$B$6,IF(AND(G28>=$C$5,G28<=$D$5),$B$5,IF(AND(G28>=$C$4,G28<=$D$4),$B$4))) -> Medium | J28: =IF(OR(I28="Prohibited", I28="FATF Grey List"), IF(I28="Prohibited", 4, 3), G28) -> 1.35 | K28: =IF(AND(J28>=$C$6,J28<=$D$6),$B$6,IF(AND(J28>=$C$5,J28<=$D$5),$B$5,IF(AND(J28>=$C$4,J28<=$D$4),$B$4,IF(AND(J28>=#REF!,J28<=#REF!),#REF!)))) -> Medium | L28: WJP Rule of Law | M28: 0.025
B29: Bahrain | C29: =[11]FATF!D21 -> 1 | D29: =[11]BASEL!H22 -> 2 | E29: 1 | F29: 1 | G29: =C29*$C$9+D29*$D$9+E29*$E$9+F29*$F$9 -> 1.35 | H29: =IF(AND(G29>=$C$6,G29<=$D$6),$B$6,IF(AND(G29>=$C$5,G29<=$D$5),$B$5,IF(AND(G29>=$C$4,G29<=$D$4),$B$4))) -> Medium | J29: =IF(OR(I29="Prohibited", I29="FATF Grey List"), IF(I29="Prohibited", 4, 3), G29) -> 1.35 | K29: =IF(AND(J29>=$C$6,J29<=$D$6),$B$6,IF(AND(J29>=$C$5,J29<=$D$5),$B$5,IF(AND(J29>=$C$4,J29<=$D$4),$B$4,IF(AND(J29>=#REF!,J29<=#REF!),#REF!)))) -> Medium | L29: Freedom House Index | M29: 0.01667
B30: Bangladesh | C30: =[11]FATF!D22 -> 1 | D30: =[11]BASEL!H23 -> 2 | E30: 1 | F30: 1 | G30: =C30*$C$9+D30*$D$9+E30*$E$9+F30*$F$9 -> 1.35 | H30: =IF(AND(G30>=$C$6,G30<=$D$6),$B$6,IF(AND(G30>=$C$5,G30<=$D$5),$B$5,IF(AND(G30>=$C$4,G30<=$D$4),$B$4))) -> Medium | J30: =IF(OR(I30="Prohibited", I30="FATF Grey List"), IF(I30="Prohibited", 4, 3), G30) -> 1.35 | K30: =IF(AND(J30>=$C$6,J30<=$D$6),$B$6,IF(AND(J30>=$C$5,J30<=$D$5),$B$5,IF(AND(J30>=$C$4,J30<=$D$4),$B$4,IF(AND(J30>=#REF!,J30<=#REF!),#REF!)))) -> Medium | L30: WEF GCR Indepencence of judiciary | M30: 0.025
B31: Barbados | C31: =[11]FATF!D23 -> 1 | D31: =[11]BASEL!H24 -> 2 | E31: 1 | F31: 1 | G31: =C31*$C$9+D31*$D$9+E31*$E$9+F31*$F$9 -> 1.35 | H31: =IF(AND(G31>=$C$6,G31<=$D$6),$B$6,IF(AND(G31>=$C$5,G31<=$D$5),$B$5,IF(AND(G31>=$C$4,G31<=$D$4),$B$4))) -> Medium | J31: =IF(OR(I31="Prohibited", I31="FATF Grey List"), IF(I31="Prohibited", 4, 3), G31) -> 1.35 | K31: =IF(AND(J31>=$C$6,J31<=$D$6),$B$6,IF(AND(J31>=$C$5,J31<=$D$5),$B$5,IF(AND(J31>=$C$4,J31<=$D$4),$B$4,IF(AND(J31>=#REF!,J31<=#REF!),#REF!)))) -> Medium | L31: Press Freedom Index | M31: 0.00833
B32: Belarus | C32: =[11]FATF!D24 -> 1 | D32: =[11]BASEL!H25 -> 2 | E32: 2 | F32: 1 | G32: =C32*$C$9+D32*$D$9+E32*$E$9+F32*$F$9 -> 1.65 | H32: =IF(AND(G32>=$C$6,G32<=$D$6),$B$6,IF(AND(G32>=$C$5,G32<=$D$5),$B$5,IF(AND(G32>=$C$4,G32<=$D$4),$B$4))) -> Medium | J32: =IF(OR(I32="Prohibited", I32="FATF Grey List"), IF(I32="Prohibited", 4, 3), G32) -> 1.65 | K32: =IF(AND(J32>=$C$6,J32<=$D$6),$B$6,IF(AND(J32>=$C$5,J32<=$D$5),$B$5,IF(AND(J32>=$C$4,J32<=$D$4),$B$4,IF(AND(J32>=#REF!,J32<=#REF!),#REF!)))) -> Medium
B33: Belgium | C33: =[11]FATF!D25 -> 1 | D33: =[11]BASEL!H26 -> 2 | E33: 1 | F33: 1 | G33: =C33*$C$9+D33*$D$9+E33*$E$9+F33*$F$9 -> 1.35 | H33: =IF(AND(G33>=$C$6,G33<=$D$6),$B$6,IF(AND(G33>=$C$5,G33<=$D$5),$B$5,IF(AND(G33>=$C$4,G33<=$D$4),$B$4,IF(AND(G33>=#REF!,G33<=#REF!),#REF!)))) -> Medium | J33: =IF(OR(I33="Prohibited", I33="FATF Grey List"), IF(I33="Prohibited", 4, 3), G33) -> 1.35 | K33: =IF(AND(J33>=$C$6,J33<=$D$6),$B$6,IF(AND(J33>=$C$5,J33<=$D$5),$B$5,IF(AND(J33>=$C$4,J33<=$D$4),$B$4,IF(AND(J33>=#REF!,J33<=#REF!),#REF!)))) -> Medium
B34: Belize | C34: =[11]FATF!D26 -> 1 | D34: =[11]BASEL!H27 -> 2 | E34: 1 | F34: 1 | G34: =C34*$C$9+D34*$D$9+E34*$E$9+F34*$F$9 -> 1.35 | H34: =IF(AND(G34>=$C$6,G34<=$D$6),$B$6,IF(AND(G34>=$C$5,G34<=$D$5),$B$5,IF(AND(G34>=$C$4,G34<=$D$4),$B$4,IF(AND(G34>=#REF!,G34<=#REF!),#REF!)))) -> Medium | J34: =IF(OR(I34="Prohibited", I34="FATF Grey List"), IF(I34="Prohibited", 4, 3), G34) -> 1.35 | K34: =IF(AND(J34>=$C$6,J34<=$D$6),$B$6,IF(AND(J34>=$C$5,J34<=$D$5),$B$5,IF(AND(J34>=$C$4,J34<=$D$4),$B$4,IF(AND(J34>=#REF!,J34<=#REF!),#REF!)))) -> Medium
B35: Benin | C35: =[11]FATF!D27 -> 1 | D35: =[11]BASEL!H28 -> 2 | E35: 1 | F35: 1 | G35: =C35*$C$9+D35*$D$9+E35*$E$9+F35*$F$9 -> 1.35 | H35: =IF(AND(G35>=$C$6,G35<=$D$6),$B$6,IF(AND(G35>=$C$5,G35<=$D$5),$B$5,IF(AND(G35>=$C$4,G35<=$D$4),$B$4,IF(AND(G35>=#REF!,G35<=#REF!),#REF!)))) -> Medium | J35: =IF(OR(I35="Prohibited", I35="FATF Grey List"), IF(I35="Prohibited", 4, 3), G35) -> 1.35 | K35: =IF(AND(J35>=$C$6,J35<=$D$6),$B$6,IF(AND(J35>=$C$5,J35<=$D$5),$B$5,IF(AND(J35>=$C$4,J35<=$D$4),$B$4,IF(AND(J35>=#REF!,J35<=#REF!),#REF!)))) -> Medium
B36: Bermuda | C36: =[11]FATF!D28 -> 1 | D36: =[11]BASEL!H29 -> 2 | E36: 1 | F36: 1 | G36: =C36*$C$9+D36*$D$9+E36*$E$9+F36*$F$9 -> 1.35 | H36: =IF(AND(G36>=$C$6,G36<=$D$6),$B$6,IF(AND(G36>=$C$5,G36<=$D$5),$B$5,IF(AND(G36>=$C$4,G36<=$D$4),$B$4,IF(AND(G36>=#REF!,G36<=#REF!),#REF!)))) -> Medium | J36: =IF(OR(I36="Prohibited", I36="FATF Grey List"), IF(I36="Prohibited", 4, 3), G36) -> 1.35 | K36: =IF(AND(J36>=$C$6,J36<=$D$6),$B$6,IF(AND(J36>=$C$5,J36<=$D$5),$B$5,IF(AND(J36>=$C$4,J36<=$D$4),$B$4,IF(AND(J36>=#REF!,J36<=#REF!),#REF!)))) -> Medium
B37: Bhutan | C37: =[11]FATF!D29 -> 1 | D37: =[11]BASEL!H30 -> 2 | E37: 1 | F37: 1 | G37: =C37*$C$9+D37*$D$9+E37*$E$9+F37*$F$9 -> 1.35 | H37: =IF(AND(G37>=$C$6,G37<=$D$6),$B$6,IF(AND(G37>=$C$5,G37<=$D$5),$B$5,IF(AND(G37>=$C$4,G37<=$D$4),$B$4,IF(AND(G37>=#REF!,G37<=#REF!),#REF!)))) -> Medium | J37: =IF(OR(I37="Prohibited", I37="FATF Grey List"), IF(I37="Prohibited", 4, 3), G37) -> 1.35 | K37: =IF(AND(J37>=$C$6,J37<=$D$6),$B$6,IF(AND(J37>=$C$5,J37<=$D$5),$B$5,IF(AND(J37>=$C$4,J37<=$D$4),$B$4,IF(AND(J37>=#REF!,J37<=#REF!),#REF!)))) -> Medium
B38: Bolivia | C38: =[11]FATF!D30 -> 1 | D38: =[11]BASEL!H31 -> 2 | E38: 1 | F38: 1 | G38: =C38*$C$9+D38*$D$9+E38*$E$9+F38*$F$9 -> 1.35 | H38: =IF(AND(G38>=$C$6,G38<=$D$6),$B$6,IF(AND(G38>=$C$5,G38<=$D$5),$B$5,IF(AND(G38>=$C$4,G38<=$D$4),$B$4,IF(AND(G38>=#REF!,G38<=#REF!),#REF!)))) -> Medium | J38: =IF(OR(I38="Prohibited", I38="FATF Grey List"), IF(I38="Prohibited", 4, 3), G38) -> 1.35 | K38: =IF(AND(J38>=$C$6,J38<=$D$6),$B$6,IF(AND(J38>=$C$5,J38<=$D$5),$B$5,IF(AND(J38>=$C$4,J38<=$D$4),$B$4,IF(AND(J38>=#REF!,J38<=#REF!),#REF!)))) -> Medium
B39: Bonaire** | C39: 1 | D39: 1 | E39: 1 | F39: 1 | G39: =C39*$C$9+D39*$D$9+E39*$E$9+F39*$F$9 -> 1 | H39: =IF(AND(G39>=$C$6,G39<=$D$6),$B$6,IF(AND(G39>=$C$5,G39<=$D$5),$B$5,IF(AND(G39>=$C$4,G39<=$D$4),$B$4,IF(AND(G39>=#REF!,G39<=#REF!),#REF!)))) -> Low | J39: =IF(OR(I39="Prohibited", I39="FATF Grey List"), IF(I39="Prohibited", 4, 3), G39) -> 1 | K39: =IF(AND(J39>=$C$6,J39<=$D$6),$B$6,IF(AND(J39>=$C$5,J39<=$D$5),$B$5,IF(AND(J39>=$C$4,J39<=$D$4),$B$4,IF(AND(J39>=#REF!,J39<=#REF!),#REF!)))) -> Low
B40: Bosnia-Herzegovina | C40: =[11]FATF!D32 -> 1 | D40: =[11]BASEL!H33 -> 2 | E40: 2 | F40: 1 | G40: =C40*$C$9+D40*$D$9+E40*$E$9+F40*$F$9 -> 1.65 | H40: =IF(AND(G40>=$C$6,G40<=$D$6),$B$6,IF(AND(G40>=$C$5,G40<=$D$5),$B$5,IF(AND(G40>=$C$4,G40<=$D$4),$B$4,IF(AND(G40>=#REF!,G40<=#REF!),#REF!)))) -> Medium | J40: =IF(OR(I40="Prohibited", I40="FATF Grey List"), IF(I40="Prohibited", 4, 3), G40) -> 1.65 | K40: =IF(AND(J40>=$C$6,J40<=$D$6),$B$6,IF(AND(J40>=$C$5,J40<=$D$5),$B$5,IF(AND(J40>=$C$4,J40<=$D$4),$B$4,IF(AND(J40>=#REF!,J40<=#REF!),#REF!)))) -> Medium
B41: Botswana | C41: =[11]FATF!D33 -> 1 | D41: =[11]BASEL!H34 -> 2 | E41: 1 | F41: 1 | G41: =C41*$C$9+D41*$D$9+E41*$E$9+F41*$F$9 -> 1.35 | H41: =IF(AND(G41>=$C$6,G41<=$D$6),$B$6,IF(AND(G41>=$C$5,G41<=$D$5),$B$5,IF(AND(G41>=$C$4,G41<=$D$4),$B$4,IF(AND(G41>=#REF!,G41<=#REF!),#REF!)))) -> Medium | J41: =IF(OR(I41="Prohibited", I41="FATF Grey List"), IF(I41="Prohibited", 4, 3), G41) -> 1.35 | K41: =IF(AND(J41>=$C$6,J41<=$D$6),$B$6,IF(AND(J41>=$C$5,J41<=$D$5),$B$5,IF(AND(J41>=$C$4,J41<=$D$4),$B$4,IF(AND(J41>=#REF!,J41<=#REF!),#REF!)))) -> Medium
...

Sheet Product Risk
A1: Rating scale
A2: Ranking | B2: From | C2: To
A3: High | B3: 2.01 | C3: 3
A4: Medium | B4: 1.01 | C4: 2
A5: Low | B5: 0 | C5: 1
A8: Sl No. | B8: Products | C8: Overall Product Score | D8: Overall Product Risk Rate | E8: How easily/quickly can the product be transferred into cash or another asset class? | G8: Will the transaction be mixed with a greater or lesser number of other legitimate transactions? | I8: Will the product enable transfer of the asset out of the country in which the investment is made? | K8: Will the controller of the account be able to make any payment or transfer to another entity? | M8: Can the currency be altered easily? | O8: Can the product be used directly or indirectly to subject to fraud and market abuse? | Q8: Can the transaction, once entered, be transferred or novated to another financial institution without further assessment on the origin of the funds? | S8: Do the product features provide anonymity for the product owner, or beneficiary? | U8: Do the product features involve with technology that can be used in enabling Financial Crime?
E9: Liquidity | G9: Volume | I9: Cross Border | K9: Third-party payment | M9: Currency conversion | O9: Fraud / Market Abuse | Q9: Portability | S9: Anonymity | U9: Technology
E10: =100/900 -> 0.11111111 | G10: =100/900 -> 0.11111111 | I10: =100/900 -> 0.11111111 | K10: =100/900 -> 0.11111111 | M10: =100/900 -> 0.11111111 | O10: =100/900 -> 0.11111111 | Q10: =100/900 -> 0.11111111 | S10: =100/900 -> 0.11111111 | U10: =100/900 -> 0.11111111
E11: Option | F11: Score | G11: Option | H11: Score | I11: Option | J11: Score | K11: Option | L11: Score | M11: Option | N11: Score | O11: Option | P11: Score | Q11: Option | R11: Score | S11: Option | T11: Score | U11: Option | V11: Score
A12: 1 | B12: Equities | C12: =($E$10*F12)+($G$10*H12)+($I$10*J12)+($K$10*L12)+($M$10*N12)+($O$10*P12)+($Q$10*R12)+($S$10*T12)+($U$10*V12) -> 1.8888889 | D12: =IF(AND(C12>=$B$5,C12<=$C$5),$A$5,IF(AND(C12>=$B$4,C12<=$C$4),$A$4,IF(AND(C12>=$B$3,C12<=$C$3),$A$3))) -> Medium | E12: Quickly | F12: =VLOOKUP(E12,$F$27:$G$30,2,FALSE) -> 3 | G12: Unlikely | H12: =VLOOKUP(G12,$H$27:$I$30,2,FALSE) -> 1 | I12: Yes | J12: =VLOOKUP(I12,$J$27:$K$29,2,FALSE) -> 3 | K12: Yes | L12: =VLOOKUP(K12,$J$27:$K$29,2,FALSE) -> 3 | M12: Yes | N12: =VLOOKUP(M12,$J$27:$K$29,2,FALSE) -> 3 | O12: Unlikely | P12: =VLOOKUP(O12,$H$27:$I$30,2,FALSE) -> 1 | Q12: No | R12: =VLOOKUP(Q12,$J$27:$K$29,2,FALSE) -> 1 | S12: No | T12: =VLOOKUP(S12,$J$27:$K$29,2,FALSE) -> 1 | U12: No | V12: =VLOOKUP(U12,$J$27:$K$29,2,FALSE) -> 1
A13: 2 | B13: Bonds | C13: =($E$10*F13)+($G$10*H13)+($I$10*J13)+($K$10*L13)+($M$10*N13)+($O$10*P13)+($Q$10*R13)+($S$10*T13)+($U$10*V13) -> 1.2222222 | D13: =IF(AND(C13>=$B$5,C13<=$C$5),$A$5,IF(AND(C13>=$B$4,C13<=$C$4),$A$4,IF(AND(C13>=$B$3,C13<=$C$3),$A$3))) -> Medium | E13: Quickly | F13: =VLOOKUP(E13,$F$27:$G$30,2,FALSE) -> 3 | G13: Unlikely | H13: =VLOOKUP(G13,$H$27:$I$30,2,FALSE) -> 1 | I13: No | J13: =VLOOKUP(I13,$J$27:$K$29,2,FALSE) -> 1 | K13: No | L13: =VLOOKUP(K13,$J$27:$K$29,2,FALSE) -> 1 | M13: No | N13: =VLOOKUP(M13,$J$27:$K$29,2,FALSE) -> 1 | O13: Unlikely | P13: =VLOOKUP(O13,$H$27:$I$30,2,FALSE) -> 1 | Q13: No | R13: =VLOOKUP(Q13,$J$27:$K$29,2,FALSE) -> 1 | S13: No | T13: =VLOOKUP(S13,$J$27:$K$29,2,FALSE) -> 1 | U13: No | V13: =VLOOKUP(U13,$J$27:$K$29,2,FALSE) -> 1
A14: 3 | B14: Funds | C14: =($E$10*F14)+($G$10*H14)+($I$10*J14)+($K$10*L14)+($M$10*N14)+($O$10*P14)+($Q$10*R14)+($S$10*T14)+($U$10*V14) -> 1.7777778 | D14: =IF(AND(C14>=$B$5,C14<=$C$5),$A$5,IF(AND(C14>=$B$4,C14<=$C$4),$A$4,IF(AND(C14>=$B$3,C14<=$C$3),$A$3))) -> Medium | E14: Quickly | F14: =VLOOKUP(E14,$F$27:$G$30,2,FALSE) -> 3 | G14: Likely | H14: =VLOOKUP(G14,$H$27:$I$30,2,FALSE) -> 2 | I14: Yes | J14: =VLOOKUP(I14,$J$27:$K$29,2,FALSE) -> 3 | K14: Yes | L14: =VLOOKUP(K14,$J$27:$K$29,2,FALSE) -> 3 | M14: No | N14: =VLOOKUP(M14,$J$27:$K$29,2,FALSE) -> 1 | O14: Unlikely | P14: =VLOOKUP(O14,$H$27:$I$30,2,FALSE) -> 1 | Q14: No | R14: =VLOOKUP(Q14,$J$27:$K$29,2,FALSE) -> 1 | S14: No | T14: =VLOOKUP(S14,$J$27:$K$29,2,FALSE) -> 1 | U14: No | V14: =VLOOKUP(U14,$J$27:$K$29,2,FALSE) -> 1
A15: 4 | B15: Foreign Exchange | C15: =($E$10*F15)+($G$10*H15)+($I$10*J15)+($K$10*L15)+($M$10*N15)+($O$10*P15)+($Q$10*R15)+($S$10*T15)+($U$10*V15) -> 1.8888889 | D15: =IF(AND(C15>=$B$5,C15<=$C$5),$A$5,IF(AND(C15>=$B$4,C15<=$C$4),$A$4,IF(AND(C15>=$B$3,C15<=$C$3),$A$3))) -> Medium | E15: Quickly | F15: =VLOOKUP(E15,$F$27:$G$30,2,FALSE) -> 3 | G15: Unlikely | H15: =VLOOKUP(G15,$H$27:$I$30,2,FALSE) -> 1 | I15: Yes | J15: =VLOOKUP(I15,$J$27:$K$29,2,FALSE) -> 3 | K15: No | L15: =VLOOKUP(K15,$J$27:$K$29,2,FALSE) -> 1 | M15: Yes | N15: =VLOOKUP(M15,$J$27:$K$29,2,FALSE) -> 3 | O15: Unlikely | P15: =VLOOKUP(O15,$H$27:$I$30,2,FALSE) -> 1 | Q15: No | R15: =VLOOKUP(Q15,$J$27:$K$29,2,FALSE) -> 1 | S15: No | T15: =VLOOKUP(S15,$J$27:$K$29,2,FALSE) -> 1 | U15: Yes | V15: =VLOOKUP(U15,$J$27:$K$29,2,FALSE) -> 3
A16: 5 | B16: Precious metals | C16: =($E$10*F16)+($G$10*H16)+($I$10*J16)+($K$10*L16)+($M$10*N16)+($O$10*P16)+($Q$10*R16)+($S$10*T16)+($U$10*V16) -> 1.8888889 | D16: =IF(AND(C16>=$B$5,C16<=$C$5),$A$5,IF(AND(C16>=$B$4,C16<=$C$4),$A$4,IF(AND(C16>=$B$3,C16<=$C$3),$A$3))) -> Medium | E16: Slowly | F16: =VLOOKUP(E16,$F$27:$G$30,2,FALSE) -> 2 | G16: Likely | H16: =VLOOKUP(G16,$H$27:$I$30,2,FALSE) -> 2 | I16: Yes | J16: =VLOOKUP(I16,$J$27:$K$29,2,FALSE) -> 3 | K16: No | L16: =VLOOKUP(K16,$J$27:$K$29,2,FALSE) -> 1 | M16: No | N16: =VLOOKUP(M16,$J$27:$K$29,2,FALSE) -> 1 | O16: Highly Likely | P16: =VLOOKUP(O16,$H$27:$I$30,2,FALSE) -> 3 | Q16: No | R16: =VLOOKUP(Q16,$J$27:$K$29,2,FALSE) -> 1 | S16: Yes | T16: =VLOOKUP(S16,$J$27:$K$29,2,FALSE) -> 3 | U16: No | V16: =VLOOKUP(U16,$J$27:$K$29,2,FALSE) -> 1
A17: 6 | B17: Structured Products | C17: =($E$10*F17)+($G$10*H17)+($I$10*J17)+($K$10*L17)+($M$10*N17)+($O$10*P17)+($Q$10*R17)+($S$10*T17)+($U$10*V17) -> 2 | D17: =IF(AND(C17>=$B$5,C17<=$C$5),$A$5,IF(AND(C17>=$B$4,C17<=$C$4),$A$4,IF(AND(C17>=$B$3,C17<=$C$3),$A$3))) -> Medium | E17: Slowly | F17: =VLOOKUP(E17,$F$27:$G$30,2,FALSE) -> 2 | G17: Highly Likely | H17: =VLOOKUP(G17,$H$27:$I$30,2,FALSE) -> 3 | I17: Yes | J17: =VLOOKUP(I17,$J$27:$K$29,2,FALSE) -> 3 | K17: No | L17: =VLOOKUP(K17,$J$27:$K$29,2,FALSE) -> 1 | M17: No | N17: =VLOOKUP(M17,$J$27:$K$29,2,FALSE) -> 1 | O17: Unlikely | P17: =VLOOKUP(O17,$H$27:$I$30,2,FALSE) -> 1 | Q17: Yes | R17: =VLOOKUP(Q17,$J$27:$K$29,2,FALSE) -> 3 | S17: Yes | T17: =VLOOKUP(S17,$J$27:$K$29,2,FALSE) -> 3 | U17: No | V17: =VLOOKUP(U17,$J$27:$K$29,2,FALSE) -> 1
A18: 7 | B18: Private placements | C18: =($E$10*F18)+($G$10*H18)+($I$10*J18)+($K$10*L18)+($M$10*N18)+($O$10*P18)+($Q$10*R18)+($S$10*T18)+($U$10*V18) -> 2 | D18: =IF(AND(C18>=$B$5,C18<=$C$5),$A$5,IF(AND(C18>=$B$4,C18<=$C$4),$A$4,IF(AND(C18>=$B$3,C18<=$C$3),$A$3))) -> Medium | E18: Slowly | F18: =VLOOKUP(E18,$F$27:$G$30,2,FALSE) -> 2 | G18: Likely | H18: =VLOOKUP(G18,$H$27:$I$30,2,FALSE) -> 2 | I18: Yes | J18: =VLOOKUP(I18,$J$27:$K$29,2,FALSE) -> 3 | K18: Yes | L18: =VLOOKUP(K18,$J$27:$K$29,2,FALSE) -> 3 | M18: Yes | N18: =VLOOKUP(M18,$J$27:$K$29,2,FALSE) -> 3 | O18: Likely | P18: =VLOOKUP(O18,$H$27:$I$30,2,FALSE) -> 2 | Q18: No | R18: =VLOOKUP(Q18,$J$27:$K$29,2,FALSE) -> 1 | S18: No | T18: =VLOOKUP(S18,$J$27:$K$29,2,FALSE) -> 1 | U18: No | V18: =VLOOKUP(U18,$J$27:$K$29,2,FALSE) -> 1
A19: 8 | B19: Fiduciary Deposits | C19: =($E$10*F19)+($G$10*H19)+($I$10*J19)+($K$10*L19)+($M$10*N19)+($O$10*P19)+($Q$10*R19)+($S$10*T19)+($U$10*V19) -> 1.8888889 | D19: =IF(AND(C19>=$B$5,C19<=$C$5),$A$5,IF(AND(C19>=$B$4,C19<=$C$4),$A$4,IF(AND(C19>=$B$3,C19<=$C$3),$A$3))) -> Medium | E19: Quickly | F19: =VLOOKUP(E19,$F$27:$G$30,2,FALSE) -> 3 | G19: Highly Likely | H19: =VLOOKUP(G19,$H$27:$I$30,2,FALSE) -> 3 | I19: Yes | J19: =VLOOKUP(I19,$J$27:$K$29,2,FALSE) -> 3 | K19: No | L19: =VLOOKUP(K19,$J$27:$K$29,2,FALSE) -> 1 | M19: No | N19: =VLOOKUP(M19,$J$27:$K$29,2,FALSE) -> 1 | O19: Unlikely | P19: =VLOOKUP(O19,$H$27:$I$30,2,FALSE) -> 1 | Q19: No | R19: =VLOOKUP(Q19,$J$27:$K$29,2,FALSE) -> 1 | S19: Yes | T19: =VLOOKUP(S19,$J$27:$K$29,2,FALSE) -> 3 | U19: No | V19: =VLOOKUP(U19,$J$27:$K$29,2,FALSE) -> 1
A20: 9 | B20: Derivatives | C20: =($E$10*F20)+($G$10*H20)+($I$10*J20)+($K$10*L20)+($M$10*N20)+($O$10*P20)+($Q$10*R20)+($S$10*T20)+($U$10*V20) -> 1.2222222 | D20: =IF(AND(C20>=$B$5,C20<=$C$5),$A$5,IF(AND(C20>=$B$4,C20<=$C$4),$A$4,IF(AND(C20>=$B$3,C20<=$C$3),$A$3))) -> Medium | E20: Quickly | F20: =VLOOKUP(E20,$F$27:$G$30,2,FALSE) -> 3 | G20: Unlikely | H20: =VLOOKUP(G20,$H$27:$I$30,2,FALSE) -> 1 | I20: No | J20: =VLOOKUP(I20,$J$27:$K$29,2,FALSE) -> 1 | K20: No | L20: =VLOOKUP(K20,$J$27:$K$29,2,FALSE) -> 1 | M20: No | N20: =VLOOKUP(M20,$J$27:$K$29,2,FALSE) -> 1 | O20: Unlikely | P20: =VLOOKUP(O20,$H$27:$I$30,2,FALSE) -> 1 | Q20: No | R20: =VLOOKUP(Q20,$J$27:$K$29,2,FALSE) -> 1 | S20: No | T20: =VLOOKUP(S20,$J$27:$K$29,2,FALSE) -> 1 | U20: No | V20: =VLOOKUP(U20,$J$27:$K$29,2,FALSE) -> 1
A21: 10 | B21: Long Term Insurance | C21: =($E$10*F21)+($G$10*H21)+($I$10*J21)+($K$10*L21)+($M$10*N21)+($O$10*P21)+($Q$10*R21)+($S$10*T21)+($U$10*V21) -> 1.7777778 | D21: =IF(AND(C21>=$B$5,C21<=$C$5),$A$5,IF(AND(C21>=$B$4,C21<=$C$4),$A$4,IF(AND(C21>=$B$3,C21<=$C$3),$A$3))) -> Medium | E21: Slowly | F21: =VLOOKUP(E21,$F$27:$G$30,2,FALSE) -> 2 | G21: Likely | H21: =VLOOKUP(G21,$H$27:$I$30,2,FALSE) -> 2 | I21: Yes | J21: =VLOOKUP(I21,$J$27:$K$29,2,FALSE) -> 3 | K21: Yes | L21: =VLOOKUP(K21,$J$27:$K$29,2,FALSE) -> 3 | M21: No | N21: =VLOOKUP(M21,$J$27:$K$29,2,FALSE) -> 1 | O21: Likely | P21: =VLOOKUP(O21,$H$27:$I$30,2,FALSE) -> 2 | Q21: No | R21: =VLOOKUP(Q21,$J$27:$K$29,2,FALSE) -> 1 | S21: No | T21: =VLOOKUP(S21,$J$27:$K$29,2,FALSE) -> 1 | U21: No | V21: =VLOOKUP(U21,$J$27:$K$29,2,FALSE) -> 1
A22: 11 | B22: Systematic Investment Plan | C22: =($E$10*F22)+($G$10*H22)+($I$10*J22)+($K$10*L22)+($M$10*N22)+($O$10*P22)+($Q$10*R22)+($S$10*T22)+($U$10*V22) -> 1.8888889 | D22: =IF(AND(C22>=$B$5,C22<=$C$5),$A$5,IF(AND(C22>=$B$4,C22<=$C$4),$A$4,IF(AND(C22>=$B$3,C22<=$C$3),$A$3))) -> Medium | E22: Quickly | F22: =VLOOKUP(E22,$F$27:$G$30,2,FALSE) -> 3 | G22: Highly Likely | H22: =VLOOKUP(G22,$H$27:$I$30,2,FALSE) -> 3 | I22: Yes | J22: =VLOOKUP(I22,$J$27:$K$29,2,FALSE) -> 3 | K22: No | L22: =VLOOKUP(K22,$J$27:$K$29,2,FALSE) -> 1 | M22: Yes | N22: =VLOOKUP(M22,$J$27:$K$29,2,FALSE) -> 3 | O22: Unlikely | P22: =VLOOKUP(O22,$H$27:$I$30,2,FALSE) -> 1 | Q22: No | R22: =VLOOKUP(Q22,$J$27:$K$29,2,FALSE) -> 1 | S22: No | T22: =VLOOKUP(S22,$J$27:$K$29,2,FALSE) -> 1 | U22: No | V22: =VLOOKUP(U22,$J$27:$K$29,2,FALSE) -> 1
A23: 12 | B23: Options | C23: =($E$10*F23)+($G$10*H23)+($I$10*J23)+($K$10*L23)+($M$10*N23)+($O$10*P23)+($Q$10*R23)+($S$10*T23)+($U$10*V23) -> 1.2222222 | D23: =IF(AND(C23>=$B$5,C23<=$C$5),$A$5,IF(AND(C23>=$B$4,C23<=$C$4),$A$4,IF(AND(C23>=$B$3,C23<=$C$3),$A$3))) -> Medium | E23: Quickly | F23: =VLOOKUP(E23,$F$26:$G$29,2,FALSE) -> 3 | G23: Unlikely | H23: =VLOOKUP(G23,$H$26:$I$29,2,FALSE) -> 1 | I23: No | J23: =VLOOKUP(I23,$J$26:$K$28,2,FALSE) -> 1 | K23: No | L23: =VLOOKUP(K23,$J$26:$K$28,2,FALSE) -> 1 | M23: No | N23: =VLOOKUP(M23,$J$26:$K$28,2,FALSE) -> 1 | O23: Unlikely | P23: =VLOOKUP(O23,$H$26:$I$29,2,FALSE) -> 1 | Q23: No | R23: =VLOOKUP(Q23,$J$26:$K$28,2,FALSE) -> 1 | S23: No | T23: =VLOOKUP(S23,$J$26:$K$28,2,FALSE) -> 1 | U23: No | V23: =VLOOKUP(U23,$J$26:$K$28,2,FALSE) -> 1
A24: 13 | B24: Portfolio Bonds | C24: =($E$10*F24)+($G$10*H24)+($I$10*J24)+($K$10*L24)+($M$10*N24)+($O$10*P24)+($Q$10*R24)+($S$10*T24)+($U$10*V24) -> 1.3333333 | D24: =IF(AND(C24>=$B$5,C24<=$C$5),$A$5,IF(AND(C24>=$B$4,C24<=$C$4),$A$4,IF(AND(C24>=$B$3,C24<=$C$3),$A$3))) -> Medium | E24: Slowly | F24: =VLOOKUP(E24,$F$27:$G$30,2,FALSE) -> 2 | G24: Highly Likely | H24: =VLOOKUP(G24,$H$27:$I$30,2,FALSE) -> 3 | I24: No | J24: =VLOOKUP(I24,$J$27:$K$29,2,FALSE) -> 1 | K24: No | L24: =VLOOKUP(K24,$J$27:$K$29,2,FALSE) -> 1 | M24: No | N24: =VLOOKUP(M24,$J$27:$K$29,2,FALSE) -> 1 | O24: Unlikely | P24: =VLOOKUP(O24,$H$27:$I$30,2,FALSE) -> 1 | Q24: No | R24: =VLOOKUP(Q24,$J$27:$K$29,2,FALSE) -> 1 | S24: No | T24: =VLOOKUP(S24,$J$27:$K$29,2,FALSE) -> 1 | U24: No | V24: =VLOOKUP(U24,$J$27:$K$29,2,FALSE) -> 1
F27: Quickly | G27: 3 | H27: Highly Likely | I27: 3 | J27: Yes | K27: 3
F28: Slowly | G28: 2 | H28: Likely | I28: 2 | J28: No | K28: 1
F29: With Difficulty | G29: 1 | H29: Unlikely | I29: 1 | J29: Not Applicable | K29: 0
F30: Not Applicable | G30: 0 | H30: Not Applicable | I30: 0

Sheet Service Risk
A1: Rating scale
A2: Ranking | B2: From | C2: To
A3: High | B3: 2.01 | C3: 3
A4: Medium | B4: 1.01 | C4: 2
A5: Low | B5: 0 | C5: 1
A8: Sl No. | B8: Service | C8: Overall Product Score | D8: Overall Product Risk Rate | E8: Will the service be mixed with a greater or lesser number of other services? | G8: Will the service enable transfer of the asset out of the country in which the investment is made? | I8: Will the service enable any payment or transfer to another entity? | K8: Can the service be used directly or indirectly to subject to fraud and market abuse? | M8: Do the service features provide anonymity for the related parties? | O8: Do the service features involve with technology that can be used in enabling Financial Crime? | Q8: Do the service features obligates the firm with financial impact?
E9: Volume | G9: Cross Border | I9: Third-party payment | K9: Fraud / Market Abuse | M9: Anonymity | O9: Technology | Q9: Obligation
E10: =100/700 -> 0.14285714 | G10: =100/700 -> 0.14285714 | I10: =100/700 -> 0.14285714 | K10: =100/700 -> 0.14285714 | M10: =100/700 -> 0.14285714 | O10: =100/700 -> 0.14285714 | Q10: =100/700 -> 0.14285714
E11: Option | F11: Score | G11: Option | H11: Score | I11: Option | J11: Score | K11: Option | L11: Score | M11: Option | N11: Score | O11: Option | P11: Score | Q11: Option | R11: Score
A12: 1 | B12: Advising on Financial Products | C12: =$E$10*F12+$G$10*H12+$I$10*J12+$K$10*L12+$M$10*N12+$O$10*P12+$Q$10*R12 -> 1.4285714 | D12: =IF(AND(C12>=$B$5,C12<=$C$5),$A$5,IF(AND(C12>=$B$4,C12<=$C$4),$A$4,IF(AND(C12>=$B$3,C12<=$C$3),$A$3))) -> Medium | E12: Likely | F12: =VLOOKUP(E12,$F$19:$G$22,2,FALSE) -> 2 | G12: No | H12: =VLOOKUP(G12,$H$19:$I$21,2,FALSE) -> 1 | I12: No | J12: =VLOOKUP(I12,$H$19:$I$21,2,FALSE) -> 1 | K12: Unlikely | L12: =VLOOKUP(K12,$F$19:$G$22,2,FALSE) -> 1 | M12: No | N12: =VLOOKUP(M12,$H$19:$I$21,2,FALSE) -> 1 | O12: No | P12: =VLOOKUP(O12,$H$19:$I$21,2,FALSE) -> 1 | Q12: Yes | R12: =VLOOKUP(Q12,$H$19:$I$21,2,FALSE) -> 3
A13: 2 | B13: Arranging Custody | C13: =$E$10*F13+$G$10*H13+$I$10*J13+$K$10*L13+$M$10*N13+$O$10*P13+$Q$10*R13 -> 1.4285714 | D13: =IF(AND(C13>=$B$5,C13<=$C$5),$A$5,IF(AND(C13>=$B$4,C13<=$C$4),$A$4,IF(AND(C13>=$B$3,C13<=$C$3),$A$3))) -> Medium | E13: Likely | F13: =VLOOKUP(E13,$F$19:$G$22,2,FALSE) -> 2 | G13: No | H13: =VLOOKUP(G13,$H$19:$I$21,2,FALSE) -> 1 | I13: No | J13: =VLOOKUP(I13,$H$19:$I$21,2,FALSE) -> 1 | K13: Unlikely | L13: =VLOOKUP(K13,$F$19:$G$22,2,FALSE) -> 1 | M13: No | N13: =VLOOKUP(M13,$H$19:$I$21,2,FALSE) -> 1 | O13: No | P13: =VLOOKUP(O13,$H$19:$I$21,2,FALSE) -> 1 | Q13: Yes | R13: =VLOOKUP(Q13,$H$19:$I$21,2,FALSE) -> 3
A14: 3 | B14: Arranging Deals in Investments | C14: =$E$10*F14+$G$10*H14+$I$10*J14+$K$10*L14+$M$10*N14+$O$10*P14+$Q$10*R14 -> 1.4285714 | D14: =IF(AND(C14>=$B$5,C14<=$C$5),$A$5,IF(AND(C14>=$B$4,C14<=$C$4),$A$4,IF(AND(C14>=$B$3,C14<=$C$3),$A$3))) -> Medium | E14: Likely | F14: =VLOOKUP(E14,$F$19:$G$22,2,FALSE) -> 2 | G14: No | H14: =VLOOKUP(G14,$H$19:$I$21,2,FALSE) -> 1 | I14: No | J14: =VLOOKUP(I14,$H$19:$I$21,2,FALSE) -> 1 | K14: Unlikely | L14: =VLOOKUP(K14,$F$19:$G$22,2,FALSE) -> 1 | M14: No | N14: =VLOOKUP(M14,$H$19:$I$21,2,FALSE) -> 1 | O14: No | P14: =VLOOKUP(O14,$H$19:$I$21,2,FALSE) -> 1 | Q14: Yes | R14: =VLOOKUP(Q14,$H$19:$I$21,2,FALSE) -> 3
A15: 4 | B15: Managing Assets (LPOA) | C15: =$E$10*F15+$G$10*H15+$I$10*J15+$K$10*L15+$M$10*N15+$O$10*P15+$Q$10*R15 -> 1.1428571 | D15: =IF(AND(C15>=$B$5,C15<=$C$5),$A$5,IF(AND(C15>=$B$4,C15<=$C$4),$A$4,IF(AND(C15>=$B$3,C15<=$C$3),$A$3))) -> Medium | E15: Unlikely | F15: =VLOOKUP(E15,$F$19:$G$22,2,FALSE) -> 1 | G15: No | H15: =VLOOKUP(G15,$H$19:$I$21,2,FALSE) -> 1 | I15: No | J15: =VLOOKUP(I15,$H$19:$I$21,2,FALSE) -> 1 | K15: Likely | L15: =VLOOKUP(K15,$F$19:$G$22,2,FALSE) -> 2 | M15: No | N15: =VLOOKUP(M15,$H$19:$I$21,2,FALSE) -> 1 | O15: No | P15: =VLOOKUP(O15,$H$19:$I$21,2,FALSE) -> 1 | Q15: No | R15: =VLOOKUP(Q15,$H$19:$I$21,2,FALSE) -> 1
A16: 5 | B16: Discretionary Mandates - control only | C16: =$E$10*F16+$G$10*H16+$I$10*J16+$K$10*L16+$M$10*N16+$O$10*P16+$Q$10*R16 -> 2.1428571 | D16: =IF(AND(C16>=$B$5,C16<=$C$5),$A$5,IF(AND(C16>=$B$4,C16<=$C$4),$A$4,IF(AND(C16>=$B$3,C16<=$C$3),$A$3))) -> High | E16: Likely | F16: =VLOOKUP(E16,$F$19:$G$22,2,FALSE) -> 2 | G16: Yes | H16: =VLOOKUP(G16,$H$19:$I$21,2,FALSE) -> 3 | I16: Yes | J16: =VLOOKUP(I16,$H$19:$I$21,2,FALSE) -> 3 | K16: Likely | L16: =VLOOKUP(K16,$F$19:$G$22,2,FALSE) -> 2 | M16: No | N16: =VLOOKUP(M16,$H$19:$I$21,2,FALSE) -> 1 | O16: No | P16: =VLOOKUP(O16,$H$19:$I$21,2,FALSE) -> 1 | Q16: Yes | R16: =VLOOKUP(Q16,$H$19:$I$21,2,FALSE) -> 3
A17: 6 | B17: Hold and Control Client Money | C17: =$E$10*F17+$G$10*H17+$I$10*J17+$K$10*L17+$M$10*N17+$O$10*P17+$Q$10*R17 -> 2.1428571 | D17: =IF(AND(C17>=$B$5,C17<=$C$5),$A$5,IF(AND(C17>=$B$4,C17<=$C$4),$A$4,IF(AND(C17>=$B$3,C17<=$C$3),$A$3))) -> High | E17: Unlikely | F17: =VLOOKUP(E17,$F$19:$G$22,2,FALSE) -> 1 | G17: Yes | H17: =VLOOKUP(G17,$H$19:$I$21,2,FALSE) -> 3 | I17: Yes | J17: =VLOOKUP(I17,$H$19:$I$21,2,FALSE) -> 3 | K17: Highly Likely | L17: =VLOOKUP(K17,$F$19:$G$22,2,FALSE) -> 3 | M17: No | N17: =VLOOKUP(M17,$H$19:$I$21,2,FALSE) -> 1 | O17: No | P17: =VLOOKUP(O17,$H$19:$I$21,2,FALSE) -> 1 | Q17: Yes | R17: =VLOOKUP(Q17,$H$19:$I$21,2,FALSE) -> 3
A18: 7 | B18: Arranging and Advising on Credit | C18: =$E$10*F18+$G$10*H18+$I$10*J18+$K$10*L18+$M$10*N18+$O$10*P18+$Q$10*R18 -> 1.4285714 | D18: =IF(AND(C18>=$B$5,C18<=$C$5),$A$5,IF(AND(C18>=$B$4,C18<=$C$4),$A$4,IF(AND(C18>=$B$3,C18<=$C$3),$A$3))) -> Medium | E18: Highly Likely | F18: =VLOOKUP(E18,$F$19:$G$22,2,FALSE) -> 3 | G18: No | H18: =VLOOKUP(G18,$H$19:$I$21,2,FALSE) -> 1 | I18: No | J18: =VLOOKUP(I18,$H$19:$I$21,2,FALSE) -> 1 | K18: Likely | L18: =VLOOKUP(K18,$F$19:$G$22,2,FALSE) -> 2 | M18: No | N18: =VLOOKUP(M18,$H$19:$I$21,2,FALSE) -> 1 | O18: No | P18: =VLOOKUP(O18,$H$19:$I$21,2,FALSE) -> 1 | Q18: No | R18: =VLOOKUP(Q18,$H$19:$I$21,2,FALSE) -> 1
E19: 3 | F19: Highly Likely | G19: 3 | H19: Yes | I19: 3
E20: 2 | F20: Likely | G20: 2 | H20: No | I20: 1
E21: 1 | F21: Unlikely | G21: 1 | H21: Not Applicable | I21: 0
E22: 0 | F22: Not Applicable | G22: 0

Sheet Delivery Channel Risk
A2: Sl No. | B2: Relationship Initiation Method | C2: Overall Service Score | D2: Overall Service Risk Rate | E2: Volume | G2: Third Party Involvment | I2: Anonymity | K2: Technology (Complex and Dependent) | M2: Fraud Liklihood
E3: =100/500 -> 0.2 | G3: =100/500 -> 0.2 | I3: =100/500 -> 0.2 | K3: =100/500 -> 0.2 | M3: =100/500 -> 0.2
E4: Option | F4: Score | G4: Option | H4: Score | I4: Option | J4: Score | K4: Option | L4: Score | M4: Option | N4: Score
A5: 1 | B5: Face to Face | C5: =F5*$E$3+H5*$G$3+J5*$I$3+L5*$K$3+N5*$M$3 -> 1.4 | D5: =IF(AND(C5>=$B$25,C5<=$C$25),$A$25,IF(AND(C5>=$B$24,C5<=$C$24),$A$24,IF(AND(C5>=$B$23,C5<=$C$23),$A$23))) -> Medium | E5: Highly Likely | F5: =VLOOKUP(E5,$F$8:$G$11,2,FALSE) -> 3 | G5: Unlikely | H5: =VLOOKUP(G5,$F$8:$G$11,2,FALSE) -> 1 | I5: No | J5: =VLOOKUP(I5,$H$8:$I$10,2,FALSE) -> 1 | K5: No | L5: =VLOOKUP(K5,$H$8:$I$10,2,FALSE) -> 1 | M5: No | N5: =VLOOKUP(M5,$H$8:$I$10,2,FALSE) -> 1
A6: 2 | B6: E Channel | C6: =F6*$E$3+H6*$G$3+J6*$I$3+L6*$K$3+N6*$M$3 -> 2 | D6: =IF(AND(C6>=$B$25,C6<=$C$25),$A$25,IF(AND(C6>=$B$24,C6<=$C$24),$A$24,IF(AND(C6>=$B$23,C6<=$C$23),$A$23))) -> Medium | E6: Unlikely | F6: =VLOOKUP(E6,$F$8:$G$11,2,FALSE) -> 1 | G6: Likely | H6: =VLOOKUP(G6,$F$8:$G$11,2,FALSE) -> 2 | I6: No | J6: =VLOOKUP(I6,$H$8:$I$10,2,FALSE) -> 1 | K6: Yes | L6: =VLOOKUP(K6,$H$8:$I$10,2,FALSE) -> 3 | M6: Yes | N6: =VLOOKUP(M6,$H$8:$I$10,2,FALSE) -> 3
A7: 3 | B7: Through Third Party | C7: =F7*$E$3+H7*$G$3+J7*$I$3+L7*$K$3+N7*$M$3 -> 2.2 | D7: =IF(AND(C7>=$B$25,C7<=$C$25),$A$25,IF(AND(C7>=$B$24,C7<=$C$24),$A$24,IF(AND(C7>=$B$23,C7<=$C$23),$A$23))) -> High | E7: Unlikely | F7: =VLOOKUP(E7,$F$8:$G$11,2,FALSE) -> 1 | G7: Highly Likely | H7: =VLOOKUP(G7,$F$8:$G$11,2,FALSE) -> 3 | I7: Yes | J7: =VLOOKUP(I7,$H$8:$I$10,2,FALSE) -> 3 | K7: No | L7: =VLOOKUP(K7,$H$8:$I$10,2,FALSE) -> 1 | M7: Yes | N7: =VLOOKUP(M7,$H$8:$I$10,2,FALSE) -> 3
E8: 3 | F8: Highly Likely | G8: 3 | H8: Yes | I8: 3
E9: 2 | F9: Likely | G9: 2 | H9: No | I9: 1
E10: 1 | F10: Unlikely | G10: 1 | H10: Not Applicable | I10: 0
E11: 0 | F11: Not Applicable | G11: 0
A14: Sl No. | B14: Delivery Method | C14: Overall Service Score | D14: Overall Service Risk Rate | E14: Volume | G14: Third Party Involvment | I14: Anonymity | K14: Technology (Complex and Dependent) | M14: Fraud Liklihood
E15: =100/500 -> 0.2 | G15: =100/500 -> 0.2 | I15: =100/500 -> 0.2 | K15: =100/500 -> 0.2 | M15: =100/500 -> 0.2
E16: Option | F16: Score | G16: Option | H16: Score | I16: Option | J16: Score | K16: Option | L16: Score | M16: Option | N16: Score
A17: 1 | B17: Face to Face | C17: =F17*$E$3+H17*$G$3+J17*$I$3+L17*$K$3+N17*$M$3 -> 1 | D17: =IF(AND(C17>=$B$25,C17<=$C$25),$A$25,IF(AND(C17>=$B$24,C17<=$C$24),$A$24,IF(AND(C17>=$B$23,C17<=$C$23),$A$23))) -> Low | E17: Unlikely | F17: =VLOOKUP(E17,$F$8:$G$11,2,FALSE) -> 1 | G17: Unlikely | H17: =VLOOKUP(G17,$F$8:$G$11,2,FALSE) -> 1 | I17: No | J17: =VLOOKUP(I17,$H$8:$I$10,2,FALSE) -> 1 | K17: No | L17: =VLOOKUP(K17,$H$8:$I$10,2,FALSE) -> 1 | M17: No | N17: =VLOOKUP(M17,$H$8:$I$10,2,FALSE) -> 1
A18: 2 | B18: E Channel | C18: =F18*$E$3+H18*$G$3+J18*$I$3+L18*$K$3+N18*$M$3 -> 2.2 | D18: =IF(AND(C18>=$B$25,C18<=$C$25),$A$25,IF(AND(C18>=$B$24,C18<=$C$24),$A$24,IF(AND(C18>=$B$23,C18<=$C$23),$A$23))) -> High | E18: Highly Likely | F18: =VLOOKUP(E18,$F$8:$G$11,2,FALSE) -> 3 | G18: Unlikely | H18: =VLOOKUP(G18,$F$8:$G$11,2,FALSE) -> 1 | I18: No | J18: =VLOOKUP(I18,$H$8:$I$10,2,FALSE) -> 1 | K18: Yes | L18: =VLOOKUP(K18,$H$8:$I$10,2,FALSE) -> 3 | M18: Yes | N18: =VLOOKUP(M18,$H$8:$I$10,2,FALSE) -> 3
A19: 3 | B19: Through Third Party | C19: =F19*$E$3+H19*$G$3+J19*$I$3+L19*$K$3+N19*$M$3 -> 1.8 | D19: =IF(AND(C19>=$B$25,C19<=$C$25),$A$25,IF(AND(C19>=$B$24,C19<=$C$24),$A$24,IF(AND(C19>=$B$23,C19<=$C$23),$A$23))) -> Medium | E19: Unlikely | F19: =VLOOKUP(E19,$F$8:$G$11,2,FALSE) -> 1 | G19: Highly Likely | H19: =VLOOKUP(G19,$F$8:$G$11,2,FALSE) -> 3 | I19: No | J19: =VLOOKUP(I19,$H$8:$I$10,2,FALSE) -> 1 | K19: No | L19: =VLOOKUP(K19,$H$8:$I$10,2,FALSE) -> 1 | M19: Yes | N19: =VLOOKUP(M19,$H$8:$I$10,2,FALSE) -> 3
A21: Rating scale
A22: Ranking | B22: From | C22: To
A23: High | B23: 2.01 | C23: 3
A24: Medium | B24: 1.01 | C24: 2
A25: Low | B25: 0 | C25: 1

Sheet Transaction Investigation Risk
B5: Number of investigations carried out in last Year
B6: S.no | C6: Number | D6: Rating | E6: Override To
B7: 1 | C7: 0 | D7: 0
B8: 2 | C8: upto 1 | D8: 2
B9: 3 | C9: 2 and above | D9: 3
B11: Number of STR filed in last Year
B12: S.no | C12: Number | D12: Rating | E12: Override To
B13: 1 | C13: 0 | D13: 0
B14: 2 | C14: 1 and above | D14: 3
