Workbook

Sheet Cover
B2: BONDS | L2: Notes
B3: Criteria | D3: Y/N | E3: # positions
B4: 1D Price Change < -1.0%? | D4: =IF(MIN(Bonds!V:V)<-1%,"Y","-") -> - | E4: =COUNTIF(Bonds!V:V,"<-1.0%") -> 0 | L4: Credit Bank of Moscow bond maturing 29/01/2025
B5: 5D Price Change < -5.0%? | D5: =IF(MIN(Bonds!W:W)<-5%,"Y","-") -> - | E5: =COUNTIF(Bonds!W:W,"<-5.0%") -> 0 | L5: USD 50k notional in both Samitar and Dorabelle
B6: 1D Price Change > +1.0%? | D6: =IF(MAX(Bonds!V:V)>1%,"Y","-") -> - | E6: =COUNTIF(Bonds!V:V,">1.0%") -> 0
B7: 5D Price Change > +5.0%? | D7: =IF(MAX(Bonds!W:W)>5%,"Y","-") -> - | E7: =COUNTIF(Bonds!W:W,">5.0%") -> 0 | L7: Country Garden Holding bond (Chinese real estate developer)
L8: XS2100725949 defaulted
L9: USD 200k notional in Rakhi Bedi and Rupal Shah
B10: EQUITIES | L10: Maturing on 14/01/2027
B11: Criteria | D11: Y/N | E11: # positions
B12: 1D Price Change < -5%? | D12: =IF(MIN(Equities!V:V)<-5%,"Y","-") -> - | E12: =COUNTIF(Equities!V:V,"<-5%") -> 0 | L12: All SPs maturing on 10 July 2025
B13: 5D Price Change < -10%? | D13: =IF(MIN(Equities!W:W)<-10%,"Y","-") -> Y | E13: =COUNTIF(Equities!W:W,"<-10%") -> 9
B14: 1D Price Change > +5%? | D14: =IF(MAX(Equities!V:V)>5%,"Y","-") -> - | E14: =COUNTIF(Equities!V:V,">5%") -> 0
B15: 5D Price Change > +10%? | D15: =IF(MAX(Equities!W:W)>10%,"Y","-") -> Y | E15: =COUNTIF(Equities!W:W,">10%") -> 19
B18: MF and ETFs
B19: Criteria | D19: Y/N | E19: # positions
B20: 1D Price Change < -5%? | D20: =IF(MIN('MF and ETFs'!V:V)<-5%,"Y","-") -> - | E20: =COUNTIF('MF and ETFs'!V:V,"<-5%") -> 0
B21: 5D Price Change < -10%? | D21: =IF(MIN('MF and ETFs'!W:W)<-10%,"Y","-") -> - | E21: =COUNTIF('MF and ETFs'!W:W,"<-10%") -> 0
B22: 1D Price Change > +5%? | D22: =IF(MAX('MF and ETFs'!V:V)>5%,"Y","-") -> Y | E22: =COUNTIF('MF and ETFs'!V:V,">5%") -> 8
B23: 5D Price Change > +10%? | D23: =IF(MAX('MF and ETFs'!W:W)>10%,"Y","-") -> - | E23: =COUNTIF('MF and ETFs'!W:W,">10%") -> 0
B26: Commodities
B27: Criteria | D27: Y/N | E27: # positions
B28: 1D Price Change < -5%? | D28: =IF(MIN(Commodities!P:P)<-5%,"Y","-") -> - | E28: =COUNTIF(Commodities!P:P,"<-5%") -> 0
B29: 5D Price Change < -10%? | D29: =IF(MIN(Commodities!Q:Q)<-10%,"Y","-") -> - | E29: =COUNTIF(Commodities!Q:Q,"<-10%") -> 0
B30: 1D Price Change > +5%? | D30: =IF(MAX(Commodities!P:P)>5%,"Y","-") -> - | E30: =COUNTIF(Commodities!P:P,">5%") -> 0
B31: 5D Price Change > +10%? | D31: =IF(MAX(Commodities!Q:Q)>10%,"Y","-") -> - | E31: =COUNTIF(Commodities!Q:Q,">10%") -> 0

Sheet Cash
A2: Last Updated | G2: 45769
A4: RM | B4: Client | C4: Account no. | D4: Custodian | E4: Cash ($) | F4: Fiduciary Deposit ($) | G4: Total ($)
A5: KS | B5: Abdallah Amina Ahmad and Abdallah Aisha Ahmed | C5: 2025141.001 | D5: LGT Geneva | E5: 9108.7578 | F5: 0 | G5: =SUM(E5:F5) -> 9108.7578
A6: SYB | B6: Affan Umair Butt | C6: 0835-3878934-0 | D6: Credit Suisse | E6: 217437.85 | F6: 0 | G6: =SUM(E6:F6) -> 217437.85
A7: SYB | B7: AKCT | C7: 4371511 | D7: Soc Gen | E7: 9599.8874 | F7: 0 | G7: 0
A8: SYB | B8: Asar Mashkoor | C8: 4380370 | D8: Soc Gen | E8: 414925.72 | F8: 0 | G8: =SUM(E8:F8) -> 414925.72
A9: KS | B9: Ashkara Limited | C9: 2620510.015 | D9: LGT Geneva | E9: 284298.04 | F9: 0 | G9: =SUM(E9:F9) -> 284298.04
A10: KS | B10: Dorabelle Limited | C10: 2620512.011 | D10: LGT Geneva | E10: 152687.13 | F10: 0 | G10: =SUM(E10:F10) -> 152687.13
A11: KS | B11: Haresh Bhatia | C11: 2620173.01 | D11: LGT Geneva | E11: 88764.177 | F11: 0 | G11: =SUM(E11:F11) -> 88764.177
A12: SYB | B12: HEPS International | C12: 4378920 | D12: Soc Gen | E12: 35910.989 | F12: 0 | G12: =SUM(E12:F12) -> 35910.989
A13: SYB | B13: Janez Bence | C13: '0176010 | D13: Soc Gen | E13: 202949.9 | F13: 367000 | G13: =SUM(E13:F13) -> 569949.9
A14: SS | B14: Jaskanwar Singh | C14: 4392470 | D14: Soc Gen | E14: 60040.469 | F14: 0 | G14: =SUM(E14:F14) -> 60040.469
A15: SYB | B15: Kalpesh Shah and Mira Shah | C15: 4379151 | D15: Soc Gen | E15: 25322.4 | F15: 196000 | G15: =SUM(E15:F15) -> 221322.4
A16: KS | B16: Konesi Limited | C16: 2029866.007 | D16: LGT Geneva | E16: 88968.602 | F16: 0 | G16: =SUM(E16:F16) -> 88968.602
A17: SYB | B17: Kundan Choudhary | C17: 4380430 | D17: Soc Gen | E17: 79559.135 | F17: 825000 | G17: =SUM(E17:F17) -> 904559.13
A18: KS | B18: Laka Enterprises Limited | C18: 2011892.087 | D18: LGT Geneva | E18: 248298.11 | F18: 0 | G18: =SUM(E18:F18) -> 248298.11
A19: SYB | B19: Napier Hall Trust | C19: 4382430 | D19: Soc Gen | E19: 2279357.7 | F19: 0 | G19: =SUM(E19:F19) -> 2279357.7
A20: KS | B20: Neekash Investment Limited | C20: 2620031.028 | D20: LGT Geneva | E20: 38638.669 | F20: 0 | G20: =SUM(E20:F20) -> 38638.669
A21: KS | B21: Rakhi Bedi - RB | C21: 2620061 | D21: LGT Geneva | E21: 63329.194 | F21: 0 | G21: =SUM(E21:F21) -> 63329.194
A22: KS | B22: Rupal Shah - RS | C22: 2620058 | D22: LGT Geneva | E22: 72822.048 | F22: 0 | G22: =SUM(E22:F22) -> 72822.048
A23: SS | B23: S Sizon | C23: 1000015111 | D23: FAB UAE | E23: 16119.99 | F23: 0 | G23: =SUM(E23:F23) -> 16119.99
A24: KS | B24: Samitar Limited | C24: 2620509.02 | D24: LGT Geneva | E24: 122400.53 | F24: 0 | G24: =SUM(E24:F24) -> 122400.53

Sheet Bonds
L1: Maturity in current month highlighted | N1: Call date in current month highlighted | U1: +/- 5% higlighted | V1: +/- 1% highlighted | W1: +/- 5% highlighted
A2: RM | B2: Client | C2: Account no. | D2: Custodian | E2: Name | F2: Ccy | G2: ISIN | H2: Moodys / Fitch / S&P | I2: Coupon | J2: Yld. to Wrst. | K2: Rank | L2: Maturity | M2: Duration | N2: Next Call Dt. | O2: Notional | P2: Pur. Price | Q2: Ind. Bid | R2: Pur. Value ($) | S2: Mkt. Value + Accrued ($) | T2: P/L ($) | U2: % P/L | V2: 1D Price Change | W2: 5D Price Change | X2: 1M Price Change | Y2: 3M Price Change | Z2: 6M Price Change | AA2: YTD | AB2: Portfolio Wt % | AC2: Total Return ($) | AD2: Industry | AE2: Ind. Ask | AF2: Notional ($) | AG2: Purchase Value | AH2: Market Value | AI2: ID_ISIN | AJ2: Country of Risk | AK2: Asset Class | AL2: Sub Classification | AM2: Z Spread | AN2: For YTW Formula | AO2: Accrued Interest | AP2: Accrued Interest ($) | AQ2: Weight in bond portfolio % | AR2: Market Value ($) ex Accrued | AS2: Years to Maturity | AT2: Non-Viability Check | AU2: Coupon Type | BG2: ISIN | BH2: LTV | BI2: PRR | BJ2: Pur. Date | BK2: FX at the time of pur.
A3: KS | B3: Abdallah Amina Ahmad and Abdallah Aisha Ahmed | C3: 2025141.001 | D3: LGT Geneva | E3: =_xll.BDP(AI3,"ds520") -> #N/A Connection | F3: =_xll.BDP(AI3,"crncy") -> #N/A Connection | G3: GB00BMBL1D50 | H3: =IF(_xll.BDP(AI3,"RTG_MOODY")="#N/A N/A","N/A",_xll.BDP(AI3,"RTG_MOODY"))&","&IF(_xll.BDP(AI3,"RTG_FITCH")="#N/A N/A","N/A",_xll.BDP(AI3,"RTG_FITCH"))&","&IF(_xll.BDP(AI3,"RTG_SP")="#N/A N/A","N/A",_xll.BDP(AI3,"RTG_SP")) -> #N/A Connection,#N/A Connection,#N/A Connection | I3: =_xll.BDP(AI3,"cpn")/100 -> #VALUE! | J3: =_xll.BDP($G3&" isin","YAS_BOND_YLD", "YAS_YLD_FLAG=15", "user_local_trade_date",AN3,"Yas_bond_px",$Q3)/100 -> #VALUE! | K3: =_xll.BDP(AI3,"PAYMENT_RANK") -> #N/A Connection | L3: =IF((TEXT(_xll.BDP(AI3,"MATURITY"),"DD/MM/YYYY")="#N/A Field Not Applicable"),"Perp",TEXT(_xll.BDP(AI3,"MATURITY"),"DD/MM/YYYY")) -> #N/A Connection | M3: =(IF(_xll.BDP($AI3&" ISIN","DU003")="#n/a n/a"," ",_xll.BDP($AI3&" ISIN","DU003"))) -> #N/A Connection | N3: =IF(_xll.BDP(AI3,"CALLABLE")="Y",_xll.BDP(AI3,"NXT_CALL_DT")," ") | O3: 74235 | P3: 31.66217 | Q3: =_xll.BDP(AI3,"px_bid") -> #N/A Connection | R3: =IF(F3="USD",AG3,(((_xll.BDP(F3&"USD CURNCY","PX_LAST")))*AG3)) -> #VALUE! | S3: =IF(F3="USD",AH3,(((_xll.BDP(F3&"USD CURNCY","PX_LAST")))*AH3))+AP3 -> #VALUE! | T3: =U3*R3 -> #VALUE! | U3: =(Q3-P3)/P3 -> #VALUE! | V3: {=IFERROR(_xll.BDP($G3&" ISIN","CHG_PCT_1D")/100,"")} | W3: {=IFERROR(_xll.BDP($G3&" ISIN","CHG_PCT_5D")/100,"")} | X3: {=_xll.BDP($G3&" ISIN","CHG_PCT_1M")/100} -> #VALUE! | Y3: {=_xll.BDP($G3&" ISIN","CHG_PCT_3M")/100} -> #VALUE! | Z3: {=_xll.BDP($G3&" ISIN","CHG_PCT_6M")/100} -> #VALUE! | AA3: {=_xll.BDP($G3&" ISIN","CHG_PCT_YTD")/100} -> #VALUE! | AB3: =S3/$H$35 -> #VALUE! | AC3: =((AF3*I3)* ((TODAY()-BJ3)/360))+(Q3-P3)%*AF3 -> #VALUE! | AD3: =_xll.BDP(AI3,"DS199") -> #N/A Connection | AE3: =_xll.BDP(AI3,"px_ask") -> #N/A Connection | AF3: =IF(F3="USD",O3,(((_xll.BDP(F3&"USD CURNCY","PX_LAST")))*O3)) -> #VALUE! | AG3: =O3*P3/100 -> 23504.412 | AH3: =Q3*O3/100 -> #VALUE! | AI3: =G3& " ISIN" -> GB00BMBL1D50 ISIN | AJ3: {=VLOOKUP(IF(NOT(_xll.BDP($G3&" CORP",$CA$4)="#N/A N/A"),(_xll.BDP($G3&" CORP",$CA$4)),"-"), '[1]Country Codes'!$A$2:$B$253,2,0)} -> #N/A | AK3: {=IF(OR(_xll.BDP($AI3,"EX028")= "#N/A N/A", _xll.BDP($AI3,"EX028")="#N/A FIELD NOT APPLICABLE"), " ", _xll.BDP($AI3,"EX028"))} -> #N/A Connection | AL3: =(IF(_xll.BDP($AI3&" ISIN","DZ282")="Y","Single line Bonds Cocos","Single line Bonds ex Cocos")) -> Single line Bonds ex Cocos | AM3: =(IF(_xll.BDP($G3&" ISIN","SP153")="#n/a n/a"," ",_xll.BDP($G3&" ISIN","SP153"))) -> #N/A Connection | AN3: =TODAY() -> 45783 | AO3: =(((_xll.BDP(AI3,"DS032"))/365)*I3)*O3 -> #VALUE! | AP3: =IF(F3="USD",AO3,(((_xll.BDP(F3&"USD CURNCY","PX_LAST")))*AO3)) -> #VALUE! | AQ3: =S3/$S$104 -> #VALUE! | AR3: =S3-AP3 -> #VALUE! | AS3: =IF((TEXT(_xll.BDP(AI3,"MATURITY"),"DD/MM/YYYY")="#N/A Field Not Applicable"),"Perp",_xll.BDP(AI3,"DS252")) -> #N/A Connection | AT3: =(IF(_xll.BDP($AI3&" ISIN","DT247")="Y","Yes","No")) -> No | AU3: =PROPER(IF(OR(_xll.BDP($AI3,"CPN_TYP")="#n/a N/A",_xll.BDP($AI3,"CPN_TYP")= "#N/A FIELD NOT APPLICABLE"), " ", _xll.BDP($AI3,"CPN_TYP"))) -> #N/A Connection | BG3: =G3 -> GB00BMBL1D50 | BH3: 0.8 | BI3: 2 | BJ3: 45509 | BK3: 1
A4: KS | B4: Abdallah Amina Ahmad and Abdallah Aisha Ahmed | C4: 2025141.001 | D4: LGT Geneva | E4: =_xll.BDP(AI4,"ds520") -> #N/A Connection | F4: =_xll.BDP(AI4,"crncy") -> #N/A Connection | G4: PAL63444B5A9 | H4: =IF(_xll.BDP(AI4,"RTG_MOODY")="#N/A N/A","N/A",_xll.BDP(AI4,"RTG_MOODY"))&","&IF(_xll.BDP(AI4,"RTG_FITCH")="#N/A N/A","N/A",_xll.BDP(AI4,"RTG_FITCH"))&","&IF(_xll.BDP(AI4,"RTG_SP")="#N/A N/A","N/A",_xll.BDP(AI4,"RTG_SP")) -> #N/A Connection,#N/A Connection,#N/A Connection | I4: =_xll.BDP(AI4,"cpn")/100 -> #VALUE! | J4: =_xll.BDP($G4&" isin","YAS_BOND_YLD", "YAS_YLD_FLAG=15", "user_local_trade_date",AN4,"Yas_bond_px",$Q4)/100 -> #VALUE! | K4: =_xll.BDP(AI4,"PAYMENT_RANK") -> #N/A Connection | L4: =IF((TEXT(_xll.BDP(AI4,"MATURITY"),"DD/MM/YYYY")="#N/A Field Not Applicable"),"Perp",TEXT(_xll.BDP(AI4,"MATURITY"),"DD/MM/YYYY")) -> #N/A Connection | M4: =(IF(_xll.BDP($AI4&" ISIN","DU003")="#n/a n/a"," ",_xll.BDP($AI4&" ISIN","DU003"))) -> #N/A Connection | N4: =IF(_xll.BDP(AI4,"CALLABLE")="Y",_xll.BDP(AI4,"NXT_CALL_DT")," ") | O4: 200000 | P4: 98.78 | Q4: =_xll.BDP(AI4,"px_bid") -> #N/A Connection | R4: =IF(F4="USD",AG4,(((_xll.BDP(F4&"USD CURNCY","PX_LAST")))*AG4)) -> #VALUE! | S4: =IF(F4="USD",AH4,(((_xll.BDP(F4&"USD CURNCY","PX_LAST")))*AH4))+AP4 -> #VALUE! | T4: =U4*R4 -> #VALUE! | U4: =(Q4-P4)/P4 -> #VALUE! | V4: {=IFERROR(_xll.BDP($G4&" ISIN","CHG_PCT_1D")/100,"")} | W4: {=IFERROR(_xll.BDP($G4&" ISIN","CHG_PCT_5D")/100,"")} | X4: {=_xll.BDP($G4&" ISIN","CHG_PCT_1M")/100} -> #VALUE! | Y4: {=_xll.BDP($G4&" ISIN","CHG_PCT_3M")/100} -> #VALUE! | Z4: {=_xll.BDP($G4&" ISIN","CHG_PCT_6M")/100} -> #VALUE! | AA4: {=_xll.BDP($G4&" ISIN","CHG_PCT_YTD")/100} -> #VALUE! | AB4: =S4/$H$35 -> #VALUE! | AC4: =((AF4*I4)* ((TODAY()-BJ4)/360))+(Q4-P4)%*AF4 -> #VALUE! | AD4: =_xll.BDP(AI4,"DS199") -> #N/A Connection | AE4: =_xll.BDP(AI4,"px_ask") -> #N/A Connection | AF4: =IF(F4="USD",O4,(((_xll.BDP(F4&"USD CURNCY","PX_LAST")))*O4)) -> #VALUE! | AG4: =O4*P4/100 -> 197560 | AH4: =Q4*O4/100 -> #VALUE! | AI4: =G4& " ISIN" -> PAL63444B5A9 ISIN | AJ4: {=VLOOKUP(IF(NOT(_xll.BDP($G4&" CORP",$CA$4)="#N/A N/A"),(_xll.BDP($G4&" CORP",$CA$4)),"-"), '[1]Country Codes'!$A$2:$B$253,2,0)} -> #N/A | AK4: {=IF(OR(_xll.BDP($AI4,"EX028")= "#N/A N/A", _xll.BDP($AI4,"EX028")="#N/A FIELD NOT APPLICABLE"), " ", _xll.BDP($AI4,"EX028"))} -> #N/A Connection | AL4: =(IF(_xll.BDP($AI4&" ISIN","DZ282")="Y","Single line Bonds Cocos","Single line Bonds ex Cocos")) -> Single line Bonds ex Cocos | AM4: =(IF(_xll.BDP($G4&" ISIN","SP153")="#n/a n/a"," ",_xll.BDP($G4&" ISIN","SP153"))) -> #N/A Connection | AN4: =TODAY() -> 45783 | AO4: =(((_xll.BDP(AI4,"DS032"))/365)*I4)*O4 -> #VALUE! | AP4: =IF(F4="USD",AO4,(((_xll.BDP(F4&"USD CURNCY","PX_LAST")))*AO4)) -> #VALUE! | AQ4: =S4/$S$104 -> #VALUE! | AR4: =S4-AP4 -> #VALUE! | AS4: =IF((TEXT(_xll.BDP(AI4,"MATURITY"),"DD/MM/YYYY")="#N/A Field Not Applicable"),"Perp",_xll.BDP(AI4,"DS252")) -> #N/A Connection | AT4: =(IF(_xll.BDP($AI4&" ISIN","DT247")="Y","Yes","No")) -> No | AU4: =PROPER(IF(OR(_xll.BDP($AI4,"CPN_TYP")="#n/a N/A",_xll.BDP($AI4,"CPN_TYP")= "#N/A FIELD NOT APPLICABLE"), " ", _xll.BDP($AI4,"CPN_TYP"))) -> #N/A Connection | BG4: =G4 -> PAL63444B5A9 | BH4: 0.75 | BI4: 3 | BJ4: 45125 | BK4: 1
A5: KS | B5: Abdallah Amina Ahmad and Abdallah Aisha Ahmed | C5: 2025141.001 | D5: LGT Geneva | E5: =_xll.BDP(AI5,"ds520") -> #N/A Connection | F5: =_xll.BDP(AI5,"crncy") -> #N/A Connection | G5: USF2280BAA47 | H5: =IF(_xll.BDP(AI5,"RTG_MOODY")="#N/A N/A","N/A",_xll.BDP(AI5,"RTG_MOODY"))&","&IF(_xll.BDP(AI5,"RTG_FITCH")="#N/A N/A","N/A",_xll.BDP(AI5,"RTG_FITCH"))&","&IF(_xll.BDP(AI5,"RTG_SP")="#N/A N/A","N/A",_xll.BDP(AI5,"RTG_SP")) -> #N/A Connection,#N/A Connection,#N/A Connection | I5: =_xll.BDP(AI5,"cpn")/100 -> #VALUE! | J5: =_xll.BDP($G5&" isin","YAS_BOND_YLD", "YAS_YLD_FLAG=15", "user_local_trade_date",AN5,"Yas_bond_px",$Q5)/100 -> #VALUE! | K5: =_xll.BDP(AI5,"PAYMENT_RANK") -> #N/A Connection | L5: =IF((TEXT(_xll.BDP(AI5,"MATURITY"),"DD/MM/YYYY")="#N/A Field Not Applicable"),"Perp",TEXT(_xll.BDP(AI5,"MATURITY"),"DD/MM/YYYY")) -> #N/A Connection | M5: =(IF(_xll.BDP($AI5&" ISIN","DU003")="#n/a n/a"," ",_xll.BDP($AI5&" ISIN","DU003"))) -> #N/A Connection | N5: =IF(_xll.BDP(AI5,"CALLABLE")="Y",_xll.BDP(AI5,"NXT_CALL_DT")," ") | O5: 200000 | P5: 100.038 | Q5: =_xll.BDP(AI5,"px_bid") -> #N/A Connection | R5: =IF(F5="USD",AG5,(((_xll.BDP(F5&"USD CURNCY","PX_LAST")))*AG5)) -> #VALUE! | S5: =IF(F5="USD",AH5,(((_xll.BDP(F5&"USD CURNCY","PX_LAST")))*AH5))+AP5 -> #VALUE! | T5: =U5*R5 -> #VALUE! | U5: =(Q5-P5)/P5 -> #VALUE! | V5: {=IFERROR(_xll.BDP($G5&" ISIN","CHG_PCT_1D")/100,"")} | W5: {=IFERROR(_xll.BDP($G5&" ISIN","CHG_PCT_5D")/100,"")} | X5: {=_xll.BDP($G5&" ISIN","CHG_PCT_1M")/100} -> #VALUE! | Y5: {=_xll.BDP($G5&" ISIN","CHG_PCT_3M")/100} -> #VALUE! | Z5: {=_xll.BDP($G5&" ISIN","CHG_PCT_6M")/100} -> #VALUE! | AA5: {=_xll.BDP($G5&" ISIN","CHG_PCT_YTD")/100} -> #VALUE! | AB5: =S5/$H$35 -> #VALUE! | AC5: =((AF5*I5)* ((TODAY()-BJ5)/360))+(Q5-P5)%*AF5 -> #VALUE! | AD5: =_xll.BDP(AI5,"DS199") -> #N/A Connection | AE5: =_xll.BDP(AI5,"px_ask") -> #N/A Connection | AF5: =IF(F5="USD",O5,(((_xll.BDP(F5&"USD CURNCY","PX_LAST")))*O5)) -> #VALUE! | AG5: =O5*P5/100 -> 200076 | AH5: =Q5*O5/100 -> #VALUE! | AI5: =G5& " ISIN" -> USF2280BAA47 ISIN | AJ5: {=VLOOKUP(IF(NOT(_xll.BDP($G5&" CORP",$CA$4)="#N/A N/A"),(_xll.BDP($G5&" CORP",$CA$4)),"-"), '[1]Country Codes'!$A$2:$B$253,2,0)} -> #N/A | AK5: {=IF(OR(_xll.BDP($AI5,"EX028")= "#N/A N/A", _xll.BDP($AI5,"EX028")="#N/A FIELD NOT APPLICABLE"), " ", _xll.BDP($AI5,"EX028"))} -> #N/A Connection | AL5: =(IF(_xll.BDP($AI5&" ISIN","DZ282")="Y","Single line Bonds Cocos","Single line Bonds ex Cocos")) -> Single line Bonds ex Cocos | AM5: =(IF(_xll.BDP($G5&" ISIN","SP153")="#n/a n/a"," ",_xll.BDP($G5&" ISIN","SP153"))) -> #N/A Connection | AN5: =TODAY() -> 45783 | AO5: =(((_xll.BDP(AI5,"DS032"))/365)*I5)*O5 -> #VALUE! | AP5: =IF(F5="USD",AO5,(((_xll.BDP(F5&"USD CURNCY","PX_LAST")))*AO5)) -> #VALUE! | AQ5: =S5/$S$104 -> #VALUE! | AR5: =S5-AP5 -> #VALUE! | AS5: =IF((TEXT(_xll.BDP(AI5,"MATURITY"),"DD/MM/YYYY")="#N/A Field Not Applicable"),"Perp",_xll.BDP(AI5,"DS252")) -> #N/A Connection | AT5: =(IF(_xll.BDP($AI5&" ISIN","DT247")="Y","Yes","No")) -> No | AU5: =PROPER(IF(OR(_xll.BDP($AI5,"CPN_TYP")="#n/a N/A",_xll.BDP($AI5,"CPN_TYP")= "#N/A FIELD NOT APPLICABLE"), " ", _xll.BDP($AI5,"CPN_TYP"))) -> #N/A Connection | BG5: =G5 -> USF2280BAA47 | BH5: 0.65 | BI5: 5 | BJ5: 45560 | BK5: 1
A6: SYB | B6: Affan Umair Butt | C6: 0835-3878934-0 | D6: Credit Suisse | E6: =_xll.BDP(AI6,"ds520") -> #N/A Connection | F6: =_xll.BDP(AI6,"crncy") -> #N/A Connection | G6: XS2568343672 | H6: =IF(_xll.BDP(AI6,"RTG_MOODY")="#N/A N/A","N/A",_xll.BDP(AI6,"RTG_MOODY"))&","&IF(_xll.BDP(AI6,"RTG_FITCH")="#N/A N/A","N/A",_xll.BDP(AI6,"RTG_FITCH"))&","&IF(_xll.BDP(AI6,"RTG_SP")="#N/A N/A","N/A",_xll.BDP(AI6,"RTG_SP")) -> #N/A Connection,#N/A Connection,#N/A Connection | I6: =_xll.BDP(AI6,"cpn")/100 -> #VALUE! | J6: =_xll.BDP($G6&" isin","YAS_BOND_YLD", "YAS_YLD_FLAG=15", "user_local_trade_date",AN6,"Yas_bond_px",$Q6)/100 -> #VALUE! | K6: =_xll.BDP(AI6,"PAYMENT_RANK") -> #N/A Connection | L6: =IF((TEXT(_xll.BDP(AI6,"MATURITY"),"DD/MM/YYYY")="#N/A Field Not Applicable"),"Perp",TEXT(_xll.BDP(AI6,"MATURITY"),"DD/MM/YYYY")) -> #N/A Connection | M6: =(IF(_xll.BDP($AI6&" ISIN","DU003")="#n/a n/a"," ",_xll.BDP($AI6&" ISIN","DU003"))) -> #N/A Connection | N6: =IF(_xll.BDP(AI6,"CALLABLE")="Y",_xll.BDP(AI6,"NXT_CALL_DT")," ") | O6: 300000 | P6: 98.6 | Q6: =_xll.BDP(AI6,"px_bid") -> #N/A Connection | R6: =IF(F6="USD",AG6,(((_xll.BDP(F6&"USD CURNCY","PX_LAST")))*AG6)) -> #VALUE! | S6: =IF(F6="USD",AH6,(((_xll.BDP(F6&"USD CURNCY","PX_LAST")))*AH6))+AP6 -> #VALUE! | T6: =U6*R6 -> #VALUE! | U6: =(Q6-P6)/P6 -> #VALUE! | V6: {=IFERROR(_xll.BDP($G6&" ISIN","CHG_PCT_1D")/100,"")} | W6: {=IFERROR(_xll.BDP($G6&" ISIN","CHG_PCT_5D")/100,"")} | X6: {=_xll.BDP($G6&" ISIN","CHG_PCT_1M")/100} -> #VALUE! | Y6: {=_xll.BDP($G6&" ISIN","CHG_PCT_3M")/100} -> #VALUE! | Z6: {=_xll.BDP($G6&" ISIN","CHG_PCT_6M")/100} -> #VALUE! | AA6: {=_xll.BDP($G6&" ISIN","CHG_PCT_YTD")/100} -> #VALUE! | AB6: =S6/$H$36 -> #VALUE! | AC6: =((AF6*I6)* ((TODAY()-BJ6)/360))+(Q6-P6)%*AF6 -> #VALUE! | AD6: =_xll.BDP(AI6,"DS199") -> #N/A Connection | AE6: =_xll.BDP(AI6,"px_ask") -> #N/A Connection | AF6: =IF(F6="USD",O6,(((_xll.BDP(F6&"USD CURNCY","PX_LAST")))*O6)) -> #VALUE! | AG6: =O6*P6/100 -> 295800 | AH6: =Q6*O6/100 -> #VALUE! | AI6: =G6& " ISIN" -> XS2568343672 ISIN | AJ6: {=VLOOKUP(IF(NOT(_xll.BDP($G6&" CORP",$CA$5)="#N/A N/A"),(_xll.BDP($G6&" CORP",$CA$5)),"-"), '[1]Country Codes'!$A$2:$B$253,2,0)} -> #N/A | AK6: {=IF(OR(_xll.BDP($AI6,"EX028")= "#N/A N/A", _xll.BDP($AI6,"EX028")="#N/A FIELD NOT APPLICABLE"), " ", _xll.BDP($AI6,"EX028"))} -> #N/A Connection | AL6: =(IF(_xll.BDP($AI6&" ISIN","DZ282")="Y","Single line Bonds Cocos","Single line Bonds ex Cocos")) -> Single line Bonds ex Cocos | AM6: =(IF(_xll.BDP($G6&" ISIN","SP153")="#n/a n/a"," ",_xll.BDP($G6&" ISIN","SP153"))) -> #N/A Connection | AN6: =TODAY() -> 45783 | AO6: =(((_xll.BDP(AI6,"DS032"))/365)*I6)*O6 -> #VALUE! | AP6: =IF(F6="USD",AO6,(((_xll.BDP(F6&"USD CURNCY","PX_LAST")))*AO6)) -> #VALUE! | AQ6: =S6/$S$106 -> #VALUE! | AR6: =S6-AP6 -> #VALUE! | AS6: =IF((TEXT(_xll.BDP(AI6,"MATURITY"),"DD/MM/YYYY")="#N/A Field Not Applicable"),"Perp",_xll.BDP(AI6,"DS252")) -> #N/A Connection | AT6: =(IF(_xll.BDP($AI6&" ISIN","DT247")="Y","Yes","No")) -> No | AU6: =PROPER(IF(OR(_xll.BDP($AI6,"CPN_TYP")="#n/a N/A",_xll.BDP($AI6,"CPN_TYP")= "#N/A FIELD NOT APPLICABLE"), " ", _xll.BDP($AI6,"CPN_TYP"))) -> #N/A Connection | BG6: =G6 -> XS2568343672 | BH6: 0.74056137 | BI6: 3 | BJ6: 45125 | BK6: 1
A7: SYB | B7: Affan Umair Butt | C7: 0835-3878934-0 | D7: Credit Suisse | E7: =_xll.BDP(AI7,"ds520") -> #N/A Connection | F7: =_xll.BDP(AI7,"crncy") -> #N/A Connection | G7: XS2384355520 | H7: =IF(_xll.BDP(AI7,"RTG_MOODY")="#N/A N/A","N/A",_xll.BDP(AI7,"RTG_MOODY"))&","&IF(_xll.BDP(AI7,"RTG_FITCH")="#N/A N/A","N/A",_xll.BDP(AI7,"RTG_FITCH"))&","&IF(_xll.BDP(AI7,"RTG_SP")="#N/A N/A","N/A",_xll.BDP(AI7,"RTG_SP")) -> #N/A Connection,#N/A Connection,#N/A Connection | I7: =_xll.BDP(AI7,"cpn")/100 -> #VALUE! | J7: =_xll.BDP($G7&" isin","YAS_BOND_YLD", "YAS_YLD_FLAG=15", "user_local_trade_date",AN7,"Yas_bond_px",$Q7)/100 -> #VALUE! | K7: =_xll.BDP(AI7,"PAYMENT_RANK") -> #N/A Connection | L7: =IF((TEXT(_xll.BDP(AI7,"MATURITY"),"DD/MM/YYYY")="#N/A Field Not Applicable"),"Perp",TEXT(_xll.BDP(AI7,"MATURITY"),"DD/MM/YYYY")) -> #N/A Connection | M7: =(IF(_xll.BDP($AI7&" ISIN","DU003")="#n/a n/a"," ",_xll.BDP($AI7&" ISIN","DU003"))) -> #N/A Connection | N7: =IF(_xll.BDP(AI7,"CALLABLE")="Y",_xll.BDP(AI7,"NXT_CALL_DT")," ") | O7: 300000 | P7: 102.95 | Q7: =_xll.BDP(AI7,"px_bid") -> #N/A Connection | R7: =IF(F7="USD",AG7,(((_xll.BDP(F7&"USD CURNCY","PX_LAST")))*AG7)) -> #VALUE! | S7: =IF(F7="USD",AH7,(((_xll.BDP(F7&"USD CURNCY","PX_LAST")))*AH7))+AP7 -> #VALUE! | T7: =U7*R7 -> #VALUE! | U7: =(Q7-P7)/P7 -> #VALUE! | V7: {=IFERROR(_xll.BDP($G7&" ISIN","CHG_PCT_1D")/100,"")} | W7: {=IFERROR(_xll.BDP($G7&" ISIN","CHG_PCT_5D")/100,"")} | X7: {=_xll.BDP($G7&" ISIN","CHG_PCT_1M")/100} -> #VALUE! | Y7: {=_xll.BDP($G7&" ISIN","CHG_PCT_3M")/100} -> #VALUE! | Z7: {=_xll.BDP($G7&" ISIN","CHG_PCT_6M")/100} -> #VALUE! | AA7: {=_xll.BDP($G7&" ISIN","CHG_PCT_YTD")/100} -> #VALUE! | AB7: =S7/$H$36 -> #VALUE! | AC7: =((AF7*I7)* ((TODAY()-BJ7)/360))+(Q7-P7)%*AF7 -> #VALUE! | AD7: =_xll.BDP(AI7,"DS199") -> #N/A Connection | AE7: =_xll.BDP(AI7,"px_ask") -> #N/A Connection | AF7: =IF(F7="USD",O7,(((_xll.BDP(F7&"USD CURNCY","PX_LAST")))*O7)) -> #VALUE! | AG7: =O7*P7/100 -> 308850 | AH7: =Q7*O7/100 -> #VALUE! | AI7: =G7& " ISIN" -> XS2384355520 ISIN | AJ7: {=VLOOKUP(IF(NOT(_xll.BDP($G7&" CORP",$CA$5)="#N/A N/A"),(_xll.BDP($G7&" CORP",$CA$5)),"-"), '[1]Country Codes'!$A$2:$B$253,2,0)} -> #N/A | AK7: {=IF(OR(_xll.BDP($AI7,"EX028")= "#N/A N/A", _xll.BDP($AI7,"EX028")="#N/A FIELD NOT APPLICABLE"), " ", _xll.BDP($AI7,"EX028"))} -> #N/A Connection | AL7: =(IF(_xll.BDP($AI7&" ISIN","DZ282")="Y","Single line Bonds Cocos","Single line Bonds ex Cocos")) -> Single line Bonds ex Cocos | AM7: =(IF(_xll.BDP($G7&" ISIN","SP153")="#n/a n/a"," ",_xll.BDP($G7&" ISIN","SP153"))) -> #N/A Connection | AN7: =TODAY() -> 45783 | AO7: =(((_xll.BDP(AI7,"DS032"))/365)*I7)*O7 -> #VALUE! | AP7: =IF(F7="USD",AO7,(((_xll.BDP(F7&"USD CURNCY","PX_LAST")))*AO7)) -> #VALUE! | AQ7: =S7/$S$106 -> #VALUE! | AR7: =S7-AP7 -> #VALUE! | AS7: =IF((TEXT(_xll.BDP(AI7,"MATURITY"),"DD/MM/YYYY")="#N/A Field Not Applicable"),"Perp",_xll.BDP(AI7,"DS252")) -> #N/A Connection | AT7: =(IF(_xll.BDP($AI7&" ISIN","DT247")="Y","Yes","No")) -> No | AU7: =PROPER(IF(OR(_xll.BDP($AI7,"CPN_TYP")="#n/a N/A",_xll.BDP($AI7,"CPN_TYP")= "#N/A FIELD NOT APPLICABLE"), " ", _xll.BDP($AI7,"CPN_TYP"))) -> #N/A Connection | BG7: =G7 -> XS2384355520 | BH7: 0.68264782 | BI7: 5 | BJ7: 45125 | BK7: 1
A8: SYB | B8: Affan Umair Butt | C8: 0835-3878934-0 | D8: Credit Suisse | E8: =_xll.BDP(AI8,"ds520") -> #N/A Connection | F8: =_xll.BDP(AI8,"crncy") -> #N/A Connection | G8: XS2258453443 | H8: =IF(_xll.BDP(AI8,"RTG_MOODY")="#N/A N/A","N/A",_xll.BDP(AI8,"RTG_MOODY"))&","&IF(_xll.BDP(AI8,"RTG_FITCH")="#N/A N/A","N/A",_xll.BDP(AI8,"RTG_FITCH"))&","&IF(_xll.BDP(AI8,"RTG_SP")="#N/A N/A","N/A",_xll.BDP(AI8,"RTG_SP")) -> #N/A Connection,#N/A Connection,#N/A Connection | I8: =_xll.BDP(AI8,"cpn")/100 -> #VALUE! | J8: =_xll.BDP($G8&" isin","YAS_BOND_YLD", "YAS_YLD_FLAG=15", "user_local_trade_date",AN8,"Yas_bond_px",$Q8)/100 -> #VALUE! | K8: =_xll.BDP(AI8,"PAYMENT_RANK") -> #N/A Connection | L8: =IF((TEXT(_xll.BDP(AI8,"MATURITY"),"DD/MM/YYYY")="#N/A Field Not Applicable"),"Perp",TEXT(_xll.BDP(AI8,"MATURITY"),"DD/MM/YYYY")) -> #N/A Connection | M8: =(IF(_xll.BDP($AI8&" ISIN","DU003")="#n/a n/a"," ",_xll.BDP($AI8&" ISIN","DU003"))) -> #N/A Connection | N8: =IF(_xll.BDP(AI8,"CALLABLE")="Y",_xll.BDP(AI8,"NXT_CALL_DT")," ") | O8: 300000 | P8: 101.4 | Q8: =_xll.BDP(AI8,"px_bid") -> #N/A Connection | R8: =IF(F8="USD",AG8,(((_xll.BDP(F8&"USD CURNCY","PX_LAST")))*AG8)) -> #VALUE! | S8: =IF(F8="USD",AH8,(((_xll.BDP(F8&"USD CURNCY","PX_LAST")))*AH8))+AP8 -> #VALUE! | T8: =U8*R8 -> #VALUE! | U8: =(Q8-P8)/P8 -> #VALUE! | V8: {=IFERROR(_xll.BDP($G8&" ISIN","CHG_PCT_1D")/100,"")} | W8: {=IFERROR(_xll.BDP($G8&" ISIN","CHG_PCT_5D")/100,"")} | X8: {=_xll.BDP($G8&" ISIN","CHG_PCT_1M")/100} -> #VALUE! | Y8: {=_xll.BDP($G8&" ISIN","CHG_PCT_3M")/100} -> #VALUE! | Z8: {=_xll.BDP($G8&" ISIN","CHG_PCT_6M")/100} -> #VALUE! | AA8: {=_xll.BDP($G8&" ISIN","CHG_PCT_YTD")/100} -> #VALUE! | AB8: =S8/$H$36 -> #VALUE! | AC8: =((AF8*I8)* ((TODAY()-BJ8)/360))+(Q8-P8)%*AF8 -> #VALUE! | AD8: =_xll.BDP(AI8,"DS199") -> #N/A Connection | AE8: =_xll.BDP(AI8,"px_ask") -> #N/A Connection | AF8: =IF(F8="USD",O8,(((_xll.BDP(F8&"USD CURNCY","PX_LAST")))*O8)) -> #VALUE! | AG8: =O8*P8/100 -> 304200 | AH8: =Q8*O8/100 -> #VALUE! | AI8: =G8& " ISIN" -> XS2258453443 ISIN | AJ8: {=VLOOKUP(IF(NOT(_xll.BDP($G8&" CORP",$CA$5)="#N/A N/A"),(_xll.BDP($G8&" CORP",$CA$5)),"-"), '[1]Country Codes'!$A$2:$B$253,2,0)} -> #N/A | AK8: {=IF(OR(_xll.BDP($AI8,"EX028")= "#N/A N/A", _xll.BDP($AI8,"EX028")="#N/A FIELD NOT APPLICABLE"), " ", _xll.BDP($AI8,"EX028"))} -> #N/A Connection | AL8: =(IF(_xll.BDP($AI8&" ISIN","DZ282")="Y","Single line Bonds Cocos","Single line Bonds ex Cocos")) -> Single line Bonds ex Cocos | AM8: =(IF(_xll.BDP($G8&" ISIN","SP153")="#n/a n/a"," ",_xll.BDP($G8&" ISIN","SP153"))) -> #N/A Connection | AN8: =TODAY() -> 45783 | AO8: =(((_xll.BDP(AI8,"DS032"))/365)*I8)*O8 -> #VALUE! | AP8: =IF(F8="USD",AO8,(((_xll.BDP(F8&"USD CURNCY","PX_LAST")))*AO8)) -> #VALUE! | AQ8: =S8/$S$106 -> #VALUE! | AR8: =S8-AP8 -> #VALUE! | AS8: =IF((TEXT(_xll.BDP(AI8,"MATURITY"),"DD/MM/YYYY")="#N/A Field Not Applicable"),"Perp",_xll.BDP(AI8,"DS252")) -> #N/A Connection | AT8: =(IF(_xll.BDP($AI8&" ISIN","DT247")="Y","Yes","No")) -> No | AU8: =PROPER(IF(OR(_xll.BDP($AI8,"CPN_TYP")="#n/a N/A",_xll.BDP($AI8,"CPN_TYP")= "#N/A FIELD NOT APPLICABLE"), " ", _xll.BDP($AI8,"CPN_TYP"))) -> #N/A Connection | BG8: =G8 -> XS2258453443 | BH8: 0.73308139 | BI8: 2 | BJ8: 44741 | BK8: 1
A9: SYB | B9: AKCT | C9: 4371511 | D9: Soc Gen | E9: =_xll.BDP(AI9,"ds520") -> #N/A Connection | F9: =_xll.BDP(AI9,"crncy") -> #N/A Connection | G9: XS2908172260 | H9: =IF(_xll.BDP(AI9,"RTG_MOODY")="#N/A N/A","N/A",_xll.BDP(AI9,"RTG_MOODY"))&","&IF(_xll.BDP(AI9,"RTG_FITCH")="#N/A N/A","N/A",_xll.BDP(AI9,"RTG_FITCH"))&","&IF(_xll.BDP(AI9,"RTG_SP")="#N/A N/A","N/A",_xll.BDP(AI9,"RTG_SP")) -> #N/A Connection,#N/A Connection,#N/A Connection | I9: =_xll.BDP(AI9,"cpn")/100 -> #VALUE! | J9: =_xll.BDP($G9&" isin","YAS_BOND_YLD", "YAS_YLD_FLAG=15", "user_local_trade_date",AN9,"Yas_bond_px",$Q9)/100 -> #VALUE! | K9: =_xll.BDP(AI9,"PAYMENT_RANK") -> #N/A Connection | L9: =IF((TEXT(_xll.BDP(AI9,"MATURITY"),"DD/MM/YYYY")="#N/A Field Not Applicable"),"Perp",TEXT(_xll.BDP(AI9,"MATURITY"),"DD/MM/YYYY")) -> #N/A Connection | M9: =(IF(_xll.BDP($AI9&" ISIN","DU003")="#n/a n/a"," ",_xll.BDP($AI9&" ISIN","DU003"))) -> #N/A Connection | N9: =IF(_xll.BDP(AI9,"CALLABLE")="Y",_xll.BDP(AI9,"NXT_CALL_DT")," ") | O9: 400000 | P9: 99.167 | Q9: =_xll.BDP(AI9,"px_bid") -> #N/A Connection | R9: =IF(F9="USD",AG9,(((_xll.BDP(F9&"USD CURNCY","PX_LAST")))*AG9)) -> #VALUE! | S9: =IF(F9="USD",AH9,(((_xll.BDP(F9&"USD CURNCY","PX_LAST")))*AH9))+AP9 -> #VALUE! | T9: =U9*R9 -> #VALUE! | U9: =(Q9-P9)/P9 -> #VALUE! | V9: {=IFERROR(_xll.BDP($G9&" ISIN","CHG_PCT_1D")/100,"")} | W9: {=IFERROR(_xll.BDP($G9&" ISIN","CHG_PCT_5D")/100,"")} | X9: {=_xll.BDP($G9&" ISIN","CHG_PCT_1M")/100} -> #VALUE! | Y9: {=_xll.BDP($G9&" ISIN","CHG_PCT_3M")/100} -> #VALUE! | Z9: {=_xll.BDP($G9&" ISIN","CHG_PCT_6M")/100} -> #VALUE! | AA9: {=_xll.BDP($G9&" ISIN","CHG_PCT_YTD")/100} -> #VALUE! | AB9: =S9/$H$36 -> #VALUE! | AC9: =((AF9*I9)* ((TODAY()-BJ9)/360))+(Q9-P9)%*AF9 -> #VALUE! | AD9: =_xll.BDP(AI9,"DS199") -> #N/A Connection | AE9: =_xll.BDP(AI9,"px_ask") -> #N/A Connection | AF9: =IF(F9="USD",O9,(((_xll.BDP(F9&"USD CURNCY","PX_LAST")))*O9)) -> #VALUE! | AG9: =O9*P9/100 -> 396668 | AH9: =Q9*O9/100 -> #VALUE! | AI9: =G9& " ISIN" -> XS2908172260 ISIN | AJ9: {=VLOOKUP(IF(NOT(_xll.BDP($G9&" CORP",$CA$5)="#N/A N/A"),(_xll.BDP($G9&" CORP",$CA$5)),"-"), '[1]Country Codes'!$A$2:$B$253,2,0)} -> #N/A | AK9: {=IF(OR(_xll.BDP($AI9,"EX028")= "#N/A N/A", _xll.BDP($AI9,"EX028")="#N/A FIELD NOT APPLICABLE"), " ", _xll.BDP($AI9,"EX028"))} -> #N/A Connection | AL9: =(IF(_xll.BDP($AI9&" ISIN","DZ282")="Y","Single line Bonds Cocos","Single line Bonds ex Cocos")) -> Single line Bonds ex Cocos | AM9: =(IF(_xll.BDP($G9&" ISIN","SP153")="#n/a n/a"," ",_xll.BDP($G9&" ISIN","SP153"))) -> #N/A Connection | AN9: =TODAY() -> 45783 | AO9: =(((_xll.BDP(AI9,"DS032"))/360)*I9)*O9 -> #VALUE! | AP9: =IF(F9="USD",AO9,(((_xll.BDP(F9&"USD CURNCY","PX_LAST")))*AO9)) -> #VALUE! | AQ9: =S9/#REF! -> #VALUE! | AR9: =S9-AP9 -> #VALUE! | AS9: =IF((TEXT(_xll.BDP(AI9,"MATURITY"),"DD/MM/YYYY")="#N/A Field Not Applicable"),"Perp",_xll.BDP(AI9,"DS252")) -> #N/A Connection | AT9: =(IF(_xll.BDP($AI9&" ISIN","DT247")="Y","Yes","No")) -> No | AU9: =PROPER(IF(OR(_xll.BDP($AI9,"CPN_TYP")="#n/a N/A",_xll.BDP($AI9,"CPN_TYP")= "#N/A FIELD NOT APPLICABLE"), " ", _xll.BDP($AI9,"CPN_TYP"))) -> #N/A Connection | BG9: =G9 -> XS2908172260 | BH9: 0.627 | BI9: 5 | BJ9: 45614 | BK9: 1
A10: SYB | B10: AKCT | C10: 4371511 | D10: Soc Gen | E10: =_xll.BDP(AI10,"ds520") -> #N/A Connection | F10: =_xll.BDP(AI10,"crncy") -> #N/A Connection | G10: XS2827680112 | H10: =IF(_xll.BDP(AI10,"RTG_MOODY")="#N/A N/A","N/A",_xll.BDP(AI10,"RTG_MOODY"))&","&IF(_xll.BDP(AI10,"RTG_FITCH")="#N/A N/A","N/A",_xll.BDP(AI10,"RTG_FITCH"))&","&IF(_xll.BDP(AI10,"RTG_SP")="#N/A N/A","N/A",_xll.BDP(AI10,"RTG_SP")) -> #N/A Connection,#N/A Connection,#N/A Connection | I10: =_xll.BDP(AI10,"cpn")/100 -> #VALUE! | J10: =_xll.BDP($G10&" isin","YAS_BOND_YLD", "YAS_YLD_FLAG=15", "user_local_trade_date",AN10,"Yas_bond_px",$Q10)/100 -> #VALUE! | K10: =_xll.BDP(AI10,"PAYMENT_RANK") -> #N/A Connection | L10: =IF((TEXT(_xll.BDP(AI10,"MATURITY"),"DD/MM/YYYY")="#N/A Field Not Applicable"),"Perp",TEXT(_xll.BDP(AI10,"MATURITY"),"DD/MM/YYYY")) -> #N/A Connection | M10: =(IF(_xll.BDP($AI10&" ISIN","DU003")="#n/a n/a"," ",_xll.BDP($AI10&" ISIN","DU003"))) -> #N/A Connection | N10: =IF(_xll.BDP(AI10,"CALLABLE")="Y",_xll.BDP(AI10,"NXT_CALL_DT")," ") | O10: 1000000 | P10: 100.3 | Q10: =_xll.BDP(AI10,"px_bid") -> #N/A Connection | R10: =IF(F10="USD",AG10,(((_xll.BDP(F10&"USD CURNCY","PX_LAST")))*AG10)) -> #VALUE! | S10: =IF(F10="USD",AH10,(((_xll.BDP(F10&"USD CURNCY","PX_LAST")))*AH10))+AP10 -> #VALUE! | T10: =U10*R10 -> #VALUE! | U10: =(Q10-P10)/P10 -> #VALUE! | V10: {=IFERROR(_xll.BDP($G10&" ISIN","CHG_PCT_1D")/100,"")} | W10: {=IFERROR(_xll.BDP($G10&" ISIN","CHG_PCT_5D")/100,"")} | X10: {=_xll.BDP($G10&" ISIN","CHG_PCT_1M")/100} -> #VALUE! | Y10: {=_xll.BDP($G10&" ISIN","CHG_PCT_3M")/100} -> #VALUE! | Z10: {=_xll.BDP($G10&" ISIN","CHG_PCT_6M")/100} -> #VALUE! | AA10: {=_xll.BDP($G10&" ISIN","CHG_PCT_YTD")/100} -> #VALUE! | AB10: =S10/$H$36 -> #VALUE! | AC10: =((AF10*I10)* ((TODAY()-BJ10)/360))+(Q10-P10)%*AF10 -> #VALUE! | AD10: =_xll.BDP(AI10,"DS199") -> #N/A Connection | AE10: =_xll.BDP(AI10,"px_ask") -> #N/A Connection | AF10: =IF(F10="USD",O10,(((_xll.BDP(F10&"USD CURNCY","PX_LAST")))*O10)) -> #VALUE! | AG10: =O10*P10/100 -> 1003000 | AH10: =Q10*O10/100 -> #VALUE! | AI10: =G10& " ISIN" -> XS2827680112 ISIN | AJ10: {=VLOOKUP(IF(NOT(_xll.BDP($G10&" CORP",$CA$5)="#N/A N/A"),(_xll.BDP($G10&" CORP",$CA$5)),"-"), '[1]Country Codes'!$A$2:$B$253,2,0)} -> #N/A | AK10: {=IF(OR(_xll.BDP($AI10,"EX028")= "#N/A N/A", _xll.BDP($AI10,"EX028")="#N/A FIELD NOT APPLICABLE"), " ", _xll.BDP($AI10,"EX028"))} -> #N/A Connection | AL10: =(IF(_xll.BDP($AI10&" ISIN","DZ282")="Y","Single line Bonds Cocos","Single line Bonds ex Cocos")) -> Single line Bonds ex Cocos | AM10: =(IF(_xll.BDP($G10&" ISIN","SP153")="#n/a n/a"," ",_xll.BDP($G10&" ISIN","SP153"))) -> #N/A Connection | AN10: =TODAY() -> 45783 | AO10: =(((_xll.BDP(AI10,"DS032"))/360)*I10)*O10 -> #VALUE! | AP10: =IF(F10="USD",AO10,(((_xll.BDP(F10&"USD CURNCY","PX_LAST")))*AO10)) -> #VALUE! | AQ10: =S10/#REF! -> #VALUE! | AR10: =S10-AP10 -> #VALUE! | AS10: =IF((TEXT(_xll.BDP(AI10,"MATURITY"),"DD/MM/YYYY")="#N/A Field Not Applicable"),"Perp",_xll.BDP(AI10,"DS252")) -> #N/A Connection | AT10: =(IF(_xll.BDP($AI10&" ISIN","DT247")="Y","Yes","No")) -> No | AU10: =PROPER(IF(OR(_xll.BDP($AI10,"CPN_TYP")="#n/a N/A",_xll.BDP($AI10,"CPN_TYP")= "#N/A FIELD NOT APPLICABLE"), " ", _xll.BDP($AI10,"CPN_TYP"))) -> #N/A Connection | BG10: =G10 -> XS2827680112 | BH10: 0.53 | BI10: 5 | BJ10: 45448 | BK10: 1
A11: SYB | B11: Asar Mashkoor | C11: 4380370 | D11: Soc Gen | E11: =_xll.BDP(AI11,"ds520") -> #N/A Connection | F11: =_xll.BDP(AI11,"crncy") -> #N/A Connection | G11: XS2408002769 | H11: =IF(_xll.BDP(AI11,"RTG_MOODY")="#N/A N/A","N/A",_xll.BDP(AI11,"RTG_MOODY"))&","&IF(_xll.BDP(AI11,"RTG_FITCH")="#N/A N/A","N/A",_xll.BDP(AI11,"RTG_FITCH"))&","&IF(_xll.BDP(AI11,"RTG_SP")="#N/A N/A","N/A",_xll.BDP(AI11,"RTG_SP")) -> #N/A Connection,#N/A Connection,#N/A Connection | I11: =_xll.BDP(AI11,"cpn")/100 -> #VALUE! | J11: =_xll.BDP($G11&" isin","YAS_BOND_YLD", "YAS_YLD_FLAG=15", "user_local_trade_date",AN11,"Yas_bond_px",$Q11)/100 -> #VALUE! | K11: =_xll.BDP(AI11,"PAYMENT_RANK") -> #N/A Connection | L11: =IF((TEXT(_xll.BDP(AI11,"MATURITY"),"DD/MM/YYYY")="#N/A Field Not Applicable"),"Perp",TEXT(_xll.BDP(AI11,"MATURITY"),"DD/MM/YYYY")) -> #N/A Connection | M11: =(IF(_xll.BDP($AI11&" ISIN","DU003")="#n/a n/a"," ",_xll.BDP($AI11&" ISIN","DU003"))) -> #N/A Connection | N11: =IF(_xll.BDP(AI11,"CALLABLE")="Y",_xll.BDP(AI11,"NXT_CALL_DT")," ") | O11: 600000 | P11: 100.3 | Q11: =_xll.BDP(AI11,"px_bid") -> #N/A Connection | R11: =IF(F11="USD",AG11,(((_xll.BDP(F11&"USD CURNCY","PX_LAST")))*AG11)) -> #VALUE! | S11: =IF(F11="USD",AH11,(((_xll.BDP(F11&"USD CURNCY","PX_LAST")))*AH11))+AP11 -> #VALUE! | T11: =U11*R11 -> #VALUE! | U11: =(Q11-P11)/P11 -> #VALUE! | V11: {=IFERROR(_xll.BDP($G11&" ISIN","CHG_PCT_1D")/100,"")} | W11: {=IFERROR(_xll.BDP($G11&" ISIN","CHG_PCT_5D")/100,"")} | X11: {=_xll.BDP($G11&" ISIN","CHG_PCT_1M")/100} -> #VALUE! | Y11: {=_xll.BDP($G11&" ISIN","CHG_PCT_3M")/100} -> #VALUE! | Z11: {=_xll.BDP($G11&" ISIN","CHG_PCT_6M")/100} -> #VALUE! | AA11: {=_xll.BDP($G11&" ISIN","CHG_PCT_YTD")/100} -> #VALUE! | AB11: =S11/$H$36 -> #VALUE! | AC11: =((AF11*I11)* ((TODAY()-BJ11)/360))+(Q11-P11)%*AF11 -> #VALUE! | AD11: =_xll.BDP(AI11,"DS199") -> #N/A Connection | AE11: =_xll.BDP(AI11,"px_ask") -> #N/A Connection | AF11: =IF(F11="USD",O11,(((_xll.BDP(F11&"USD CURNCY","PX_LAST")))*O11)) -> #VALUE! | AG11: =O11*P11/100 -> 601800 | AH11: =Q11*O11/100 -> #VALUE! | AI11: =G11& " ISIN" -> XS2408002769 ISIN | AJ11: {=VLOOKUP(IF(NOT(_xll.BDP($G11&" CORP",$CA$5)="#N/A N/A"),(_xll.BDP($G11&" CORP",$CA$5)),"-"), '[1]Country Codes'!$A$2:$B$253,2,0)} -> #N/A | AK11: {=IF(OR(_xll.BDP($AI11,"EX028")= "#N/A N/A", _xll.BDP($AI11,"EX028")="#N/A FIELD NOT APPLICABLE"), " ", _xll.BDP($AI11,"EX028"))} -> #N/A Connection | AL11: =(IF(_xll.BDP($AI11&" ISIN","DZ282")="Y","Single line Bonds Cocos","Single line Bonds ex Cocos")) -> Single line Bonds ex Cocos | AM11: =(IF(_xll.BDP($G11&" ISIN","SP153")="#n/a n/a"," ",_xll.BDP($G11&" ISIN","SP153"))) -> #N/A Connection | AN11: =TODAY() -> 45783 | AO11: =(((_xll.BDP(AI11,"DS032"))/360)*I11)*O11 -> #VALUE! | AP11: =IF(F11="USD",AO11,(((_xll.BDP(F11&"USD CURNCY","PX_LAST")))*AO11)) -> #VALUE! | AQ11: =S11/$S$113 -> #VALUE! | AR11: =S11-AP11 -> #VALUE! | AS11: =IF((TEXT(_xll.BDP(AI11,"MATURITY"),"DD/MM/YYYY")="#N/A Field Not Applicable"),"Perp",_xll.BDP(AI11,"DS252")) -> #N/A Connection | AT11: =(IF(_xll.BDP($AI11&" ISIN","DT247")="Y","Yes","No")) -> No | AU11: =PROPER(IF(OR(_xll.BDP($AI11,"CPN_TYP")="#n/a N/A",_xll.BDP($AI11,"CPN_TYP")= "#N/A FIELD NOT APPLICABLE"), " ", _xll.BDP($AI11,"CPN_TYP"))) -> #N/A Connection | BG11: =G11 -> XS2408002769 | BH11: 0.6445 | BI11: 5 | BJ11: 44518
A12: SYB | B12: Asar Mashkoor | C12: 4380370 | D12: Soc Gen | E12: =_xll.BDP(AI12,"ds520") -> Mazoon Assets Co SAOC | F12: =_xll.BDP(AI12,"crncy") -> USD | G12: XS2907977131 | H12: =IF(_xll.BDP(AI12,"RTG_MOODY")="#N/A N/A","N/A",_xll.BDP(AI12,"RTG_MOODY"))&","&IF(_xll.BDP(AI12,"RTG_FITCH")="#N/A N/A","N/A",_xll.BDP(AI12,"RTG_FITCH"))&","&IF(_xll.BDP(AI12,"RTG_SP")="#N/A N/A","N/A",_xll.BDP(AI12,"RTG_SP")) -> Ba1,BB+,N/A | I12: =_xll.BDP(AI12,"cpn")/100 -> 0.0525 | J12: =_xll.BDP($G12&" isin","YAS_BOND_YLD", "YAS_YLD_FLAG=15", "user_local_trade_date",AN12,"Yas_bond_px",$Q12)/100 -> 0.05640536 | K12: =_xll.BDP(AI12,"PAYMENT_RANK") -> Sr Unsecured | L12: =IF((TEXT(_xll.BDP(AI12,"MATURITY"),"DD/MM/YYYY")="#N/A Field Not Applicable"),"Perp",TEXT(_xll.BDP(AI12,"MATURITY"),"DD/MM/YYYY")) -> 09/10/2031 | M12: =(IF(_xll.BDP($AI12&" ISIN","DU003")="#n/a n/a"," ",_xll.BDP($AI12&" ISIN","DU003"))) -> 5.5211923 | N12: =IF(_xll.BDP(AI12,"CALLABLE")="Y",_xll.BDP(AI12,"NXT_CALL_DT")," ") | O12: 300000 | P12: 99.808 | Q12: =_xll.BDP(AI12,"px_bid") -> 97.916 | R12: =IF(F12="USD",AG12,(((_xll.BDP(F12&"USD CURNCY","PX_LAST")))*AG12)) -> 299424 | S12: =IF(F12="USD",AH12,(((_xll.BDP(F12&"USD CURNCY","PX_LAST")))*AH12))+AP12 -> 294754.25 | T12: =U12*R12 -> -5676 | U12: =(Q12-P12)/P12 -> -0.018956396 | V12: {=IFERROR(_xll.BDP($G12&" ISIN","CHG_PCT_1D")/100,"")} | W12: {=IFERROR(_xll.BDP($G12&" ISIN","CHG_PCT_5D")/100,"")} | X12: {=_xll.BDP($G12&" ISIN","CHG_PCT_1M")/100} -> #VALUE! | Y12: {=_xll.BDP($G12&" ISIN","CHG_PCT_3M")/100} -> #VALUE! | Z12: {=_xll.BDP($G12&" ISIN","CHG_PCT_6M")/100} -> #VALUE! | AA12: {=_xll.BDP($G12&" ISIN","CHG_PCT_YTD")/100} -> #VALUE! | AB12: =S12/$H$36 -> #VALUE! | AC12: =((AF12*I12)* ((TODAY()-BJ12)/360))+(Q12-P12)%*AF12 -> 3424 | AD12: =_xll.BDP(AI12,"DS199") -> Utilities | AE12: =_xll.BDP(AI12,"px_ask") -> 100.208 | AF12: =IF(F12="USD",O12,(((_xll.BDP(F12&"USD CURNCY","PX_LAST")))*O12)) -> 300000 | AG12: =O12*P12/100 -> 299424 | AH12: =Q12*O12/100 -> 293748 | AI12: =G12& " ISIN" -> XS2907977131 ISIN | AJ12: {=VLOOKUP(IF(NOT(_xll.BDP($G12&" CORP",$CA$5)="#N/A N/A"),(_xll.BDP($G12&" CORP",$CA$5)),"-"), '[1]Country Codes'!$A$2:$B$253,2,0)} -> #N/A | AK12: {=IF(OR(_xll.BDP($AI12,"EX028")= "#N/A N/A", _xll.BDP($AI12,"EX028")="#N/A FIELD NOT APPLICABLE"), " ", _xll.BDP($AI12,"EX028"))} -> FixedIncome | AL12: =(IF(_xll.BDP($AI12&" ISIN","DZ282")="Y","Single line Bonds Cocos","Single line Bonds ex Cocos")) -> Single line Bonds ex Cocos | AM12: =(IF(_xll.BDP($G12&" ISIN","SP153")="#n/a n/a"," ",_xll.BDP($G12&" ISIN","SP153"))) -> 193.35425 | AN12: =TODAY() -> 45783 | AO12: =(((_xll.BDP(AI12,"DS032"))/360)*I12)*O12 -> 1006.25 | AP12: =IF(F12="USD",AO12,(((_xll.BDP(F12&"USD CURNCY","PX_LAST")))*AO12)) -> 1006.25 | AQ12: =S12/$S$113 -> 0.56320734 | AR12: =S12-AP12 -> 293748 | AS12: =IF((TEXT(_xll.BDP(AI12,"MATURITY"),"DD/MM/YYYY")="#N/A Field Not Applicable"),"Perp",_xll.BDP(AI12,"DS252")) -> 6.4421629 | AT12: =(IF(_xll.BDP($AI12&" ISIN","DT247")="Y","Yes","No")) -> No | AU12: =PROPER(IF(OR(_xll.BDP($AI12,"CPN_TYP")="#n/a N/A",_xll.BDP($AI12,"CPN_TYP")= "#N/A FIELD NOT APPLICABLE"), " ", _xll.BDP($AI12,"CPN_TYP"))) -> Fixed | BG12: =G12 -> XS2907977131 | BH12: 0.74 | BI12: 5 | BJ12: 45575
A13: SYB | B13: Asar Mashkoor | C13: 4380370 | D13: Soc Gen | E13: =_xll.BDP(AI13,"ds520") -> Sharjah Sukuk Program Ltd | F13: =_xll.BDP(AI13,"crncy") -> USD | G13: XS2914525154 | H13: =IF(_xll.BDP(AI13,"RTG_MOODY")="#N/A N/A","N/A",_xll.BDP(AI13,"RTG_MOODY"))&","&IF(_xll.BDP(AI13,"RTG_FITCH")="#N/A N/A","N/A",_xll.BDP(AI13,"RTG_FITCH"))&","&IF(_xll.BDP(AI13,"RTG_SP")="#N/A N/A","N/A",_xll.BDP(AI13,"RTG_SP")) -> Ba1,N/A,BBB- | I13: =_xll.BDP(AI13,"cpn")/100 -> 0.05433 | J13: =_xll.BDP($G13&" isin","YAS_BOND_YLD", "YAS_YLD_FLAG=15", "user_local_trade_date",AN13,"Yas_bond_px",$Q13)/100 -> 0.05622212 | K13: =_xll.BDP(AI13,"PAYMENT_RANK") -> Sr Unsecured | L13: =IF((TEXT(_xll.BDP(AI13,"MATURITY"),"DD/MM/YYYY")="#N/A Field Not Applicable"),"Perp",TEXT(_xll.BDP(AI13,"MATURITY"),"DD/MM/YYYY")) -> 17/04/2035 | M13: =(IF(_xll.BDP($AI13&" ISIN","DU003")="#n/a n/a"," ",_xll.BDP($AI13&" ISIN","DU003"))) -> 7.789515 | N13: =IF(_xll.BDP(AI13,"CALLABLE")="Y",_xll.BDP(AI13,"NXT_CALL_DT")," ") | O13: 250000 | P13: 100.079 | Q13: =_xll.BDP(AI13,"px_bid") -> 98.57 | R13: =IF(F13="USD",AG13,(((_xll.BDP(F13&"USD CURNCY","PX_LAST")))*AG13)) -> 250197.5 | S13: =IF(F13="USD",AH13,(((_xll.BDP(F13&"USD CURNCY","PX_LAST")))*AH13))+AP13 -> 246990.94 | T13: =U13*R13 -> -3772.5 | U13: =(Q13-P13)/P13 -> -0.015078088 | V13: {=IFERROR(_xll.BDP($G13&" ISIN","CHG_PCT_1D")/100,"")} | W13: {=IFERROR(_xll.BDP($G13&" ISIN","CHG_PCT_5D")/100,"")} | X13: {=_xll.BDP($G13&" ISIN","CHG_PCT_1M")/100} -> #VALUE! | Y13: {=_xll.BDP($G13&" ISIN","CHG_PCT_3M")/100} -> #VALUE! | Z13: {=_xll.BDP($G13&" ISIN","CHG_PCT_6M")/100} -> #VALUE! | AA13: {=_xll.BDP($G13&" ISIN","CHG_PCT_YTD")/100} -> #VALUE! | AB13: =S13/$H$36 -> #VALUE! | AC13: =((AF13*I13)* ((TODAY()-BJ13)/360))+(Q13-P13)%*AF13 -> 4075.1667 | AD13: =_xll.BDP(AI13,"DS199") -> Government | AE13: =_xll.BDP(AI13,"px_ask") -> 99.272 | AF13: =IF(F13="USD",O13,(((_xll.BDP(F13&"USD CURNCY","PX_LAST")))*O13)) -> 250000 | AG13: =O13*P13/100 -> 250197.5 | AH13: =Q13*O13/100 -> 246425 | AI13: =G13& " ISIN" -> XS2914525154 ISIN | AJ13: {=VLOOKUP(IF(NOT(_xll.BDP($G13&" CORP",$CA$5)="#N/A N/A"),(_xll.BDP($G13&" CORP",$CA$5)),"-"), '[1]Country Codes'!$A$2:$B$253,2,0)} -> #N/A | AK13: {=IF(OR(_xll.BDP($AI13,"EX028")= "#N/A N/A", _xll.BDP($AI13,"EX028")="#N/A FIELD NOT APPLICABLE"), " ", _xll.BDP($AI13,"EX028"))} -> FixedIncome | AL13: =(IF(_xll.BDP($AI13&" ISIN","DZ282")="Y","Single line Bonds Cocos","Single line Bonds ex Cocos")) -> Single line Bonds ex Cocos | AM13: =(IF(_xll.BDP($G13&" ISIN","SP153")="#n/a n/a"," ",_xll.BDP($G13&" ISIN","SP153"))) -> 193.46811 | AN13: =TODAY() -> 45783 | AO13: =(((_xll.BDP(AI13,"DS032"))/360)*I13)*O13 -> 565.9375 | AP13: =IF(F13="USD",AO13,(((_xll.BDP(F13&"USD CURNCY","PX_LAST")))*AO13)) -> 565.9375 | AQ13: =S13/$S$113 -> 0.47194268 | AR13: =S13-AP13 -> 246425 | AS13: =IF((TEXT(_xll.BDP(AI13,"MATURITY"),"DD/MM/YYYY")="#N/A Field Not Applicable"),"Perp",_xll.BDP(AI13,"DS252")) -> 9.963039 | AT13: =(IF(_xll.BDP($AI13&" ISIN","DT247")="Y","Yes","No")) -> No | AU13: =PROPER(IF(OR(_xll.BDP($AI13,"CPN_TYP")="#n/a N/A",_xll.BDP($AI13,"CPN_TYP")= "#N/A FIELD NOT APPLICABLE"), " ", _xll.BDP($AI13,"CPN_TYP"))) -> Fixed | BG13: =G13 -> XS2914525154 | BH13: 0.8098 | BI13: 4 | BJ13: 45575
A14: SYB | B14: Asar Mashkoor | C14: 4380370 | D14: Soc Gen | E14: =_xll.BDP(AI14,"ds520") -> #N/A Connection | F14: =_xll.BDP(AI14,"crncy") -> #N/A Connection | G14: XS2384355520 | H14: =IF(_xll.BDP(AI14,"RTG_MOODY")="#N/A N/A","N/A",_xll.BDP(AI14,"RTG_MOODY"))&","&IF(_xll.BDP(AI14,"RTG_FITCH")="#N/A N/A","N/A",_xll.BDP(AI14,"RTG_FITCH"))&","&IF(_xll.BDP(AI14,"RTG_SP")="#N/A N/A","N/A",_xll.BDP(AI14,"RTG_SP")) -> #N/A Connection,#N/A Connection,#N/A Connection | I14: =_xll.BDP(AI14,"cpn")/100 -> #VALUE! | J14: =_xll.BDP($G14&" isin","YAS_BOND_YLD", "YAS_YLD_FLAG=15", "user_local_trade_date",AN14,"Yas_bond_px",$Q14)/100 -> #VALUE! | K14: =_xll.BDP(AI14,"PAYMENT_RANK") -> #N/A Connection | L14: =IF((TEXT(_xll.BDP(AI14,"MATURITY"),"DD/MM/YYYY")="#N/A Field Not Applicable"),"Perp",TEXT(_xll.BDP(AI14,"MATURITY"),"DD/MM/YYYY")) -> #N/A Connection | M14: =(IF(_xll.BDP($AI14&" ISIN","DU003")="#n/a n/a"," ",_xll.BDP($AI14&" ISIN","DU003"))) -> #N/A Connection | N14: =IF(_xll.BDP(AI14,"CALLABLE")="Y",_xll.BDP(AI14,"NXT_CALL_DT")," ") | O14: 400000 | P14: 101.3 | Q14: =_xll.BDP(AI14,"px_bid") -> #N/A Connection | R14: =IF(F14="USD",AG14,(((_xll.BDP(F14&"USD CURNCY","PX_LAST")))*AG14)) -> #VALUE! | S14: =IF(F14="USD",AH14,(((_xll.BDP(F14&"USD CURNCY","PX_LAST")))*AH14))+AP14 -> #VALUE! | T14: =U14*R14 -> #VALUE! | U14: =(Q14-P14)/P14 -> #VALUE! | V14: {=IFERROR(_xll.BDP($G14&" ISIN","CHG_PCT_1D")/100,"")} | W14: {=IFERROR(_xll.BDP($G14&" ISIN","CHG_PCT_5D")/100,"")} | X14: {=_xll.BDP($G14&" ISIN","CHG_PCT_1M")/100} -> #VALUE! | Y14: {=_xll.BDP($G14&" ISIN","CHG_PCT_3M")/100} -> #VALUE! | Z14: {=_xll.BDP($G14&" ISIN","CHG_PCT_6M")/100} -> #VALUE! | AA14: {=_xll.BDP($G14&" ISIN","CHG_PCT_YTD")/100} -> #VALUE! | AB14: =S14/$H$36 -> #VALUE! | AC14: =((AF14*I14)* ((TODAY()-BJ14)/360))+(Q14-P14)%*AF14 -> #VALUE! | AD14: =_xll.BDP(AI14,"DS199") -> #N/A Connection | AE14: =_xll.BDP(AI14,"px_ask") -> #N/A Connection | AF14: =IF(F14="USD",O14,(((_xll.BDP(F14&"USD CURNCY","PX_LAST")))*O14)) -> #VALUE! | AG14: =O14*P14/100 -> 405200 | AH14: =Q14*O14/100 -> #VALUE! | AI14: =G14& " ISIN" -> XS2384355520 ISIN | AJ14: {=VLOOKUP(IF(NOT(_xll.BDP($G14&" CORP",$CA$5)="#N/A N/A"),(_xll.BDP($G14&" CORP",$CA$5)),"-"), '[1]Country Codes'!$A$2:$B$253,2,0)} -> #N/A | AK14: {=IF(OR(_xll.BDP($AI14,"EX028")= "#N/A N/A", _xll.BDP($AI14,"EX028")="#N/A FIELD NOT APPLICABLE"), " ", _xll.BDP($AI14,"EX028"))} -> #N/A Connection | AL14: =(IF(_xll.BDP($AI14&" ISIN","DZ282")="Y","Single line Bonds Cocos","Single line Bonds ex Cocos")) -> Single line Bonds ex Cocos | AM14: =(IF(_xll.BDP($G14&" ISIN","SP153")="#n/a n/a"," ",_xll.BDP($G14&" ISIN","SP153"))) -> #N/A Connection | AN14: =TODAY() -> 45783 | AO14: =(((_xll.BDP(AI14,"DS032"))/360)*I14)*O14 -> #VALUE! | AP14: =IF(F14="USD",AO14,(((_xll.BDP(F14&"USD CURNCY","PX_LAST")))*AO14)) -> #VALUE! | AQ14: =S14/$S$113 -> #VALUE! | AR14: =S14-AP14 -> #VALUE! | AS14: =IF((TEXT(_xll.BDP(AI14,"MATURITY"),"DD/MM/YYYY")="#N/A Field Not Applicable"),"Perp",_xll.BDP(AI14,"DS252")) -> #N/A Connection | AT14: =(IF(_xll.BDP($AI14&" ISIN","DT247")="Y","Yes","No")) -> No | AU14: =PROPER(IF(OR(_xll.BDP($AI14,"CPN_TYP")="#n/a N/A",_xll.BDP($AI14,"CPN_TYP")= "#N/A FIELD NOT APPLICABLE"), " ", _xll.BDP($AI14,"CPN_TYP"))) -> #N/A Connection | BG14: =G14 -> XS2384355520 | BH14: 0.7354 | BI14: 5 | BJ14: 44455
A15: SYB | B15: Asar Mashkoor | C15: 4380370 | D15: Soc Gen | E15: =_xll.BDP(AI15,"ds520") -> #N/A Connection | F15: =_xll.BDP(AI15,"crncy") -> #N/A Connection | G15: XS2976035316 | H15: =IF(_xll.BDP(AI15,"RTG_MOODY")="#N/A N/A","N/A",_xll.BDP(AI15,"RTG_MOODY"))&","&IF(_xll.BDP(AI15,"RTG_FITCH")="#N/A N/A","N/A",_xll.BDP(AI15,"RTG_FITCH"))&","&IF(_xll.BDP(AI15,"RTG_SP")="#N/A N/A","N/A",_xll.BDP(AI15,"RTG_SP")) -> #N/A Connection,#N/A Connection,#N/A Connection | I15: =_xll.BDP(AI15,"cpn")/100 -> #VALUE! | J15: =_xll.BDP($G15&" isin","YAS_BOND_YLD", "YAS_YLD_FLAG=15", "user_local_trade_date",AN15,"Yas_bond_px",$Q15)/100 -> #VALUE! | K15: =_xll.BDP(AI15,"PAYMENT_RANK") -> #N/A Connection | L15: =IF((TEXT(_xll.BDP(AI15,"MATURITY"),"DD/MM/YYYY")="#N/A Field Not Applicable"),"Perp",TEXT(_xll.BDP(AI15,"MATURITY"),"DD/MM/YYYY")) -> #N/A Connection | M15: =(IF(_xll.BDP($AI15&" ISIN","DU003")="#n/a n/a"," ",_xll.BDP($AI15&" ISIN","DU003"))) -> #N/A Connection | N15: =IF(_xll.BDP(AI15,"CALLABLE")="Y",_xll.BDP(AI15,"NXT_CALL_DT")," ") | O15: 200000 | P15: 100.092 | Q15: =_xll.BDP(AI15,"px_bid") -> #N/A Connection | R15: =IF(F15="USD",AG15,(((_xll.BDP(F15&"USD CURNCY","PX_LAST")))*AG15)) -> #VALUE! | S15: =IF(F15="USD",AH15,(((_xll.BDP(F15&"USD CURNCY","PX_LAST")))*AH15))+AP15 -> #VALUE! | T15: =U15*R15 -> #VALUE! | U15: =(Q15-P15)/P15 -> #VALUE! | V15: {=IFERROR(_xll.BDP($G15&" ISIN","CHG_PCT_1D")/100,"")} | W15: {=IFERROR(_xll.BDP($G15&" ISIN","CHG_PCT_5D")/100,"")} | X15: {=_xll.BDP($G15&" ISIN","CHG_PCT_1M")/100} -> #VALUE! | Y15: {=_xll.BDP($G15&" ISIN","CHG_PCT_3M")/100} -> #VALUE! | Z15: {=_xll.BDP($G15&" ISIN","CHG_PCT_6M")/100} -> #VALUE! | AA15: {=_xll.BDP($G15&" ISIN","CHG_PCT_YTD")/100} -> #VALUE! | AB15: =S15/$H$36 -> #VALUE! | AC15: =((AF15*I15)* ((TODAY()-BJ15)/360))+(Q15-P15)%*AF15 -> #VALUE! | AD15: =_xll.BDP(AI15,"DS199") -> #N/A Connection | AE15: =_xll.BDP(AI15,"px_ask") -> #N/A Connection | AF15: =IF(F15="USD",O15,(((_xll.BDP(F15&"USD CURNCY","PX_LAST")))*O15)) -> #VALUE! | AG15: =O15*P15/100 -> 200184 | AH15: =Q15*O15/100 -> #VALUE! | AI15: =G15& " ISIN" -> XS2976035316 ISIN | AJ15: {=VLOOKUP(IF(NOT(_xll.BDP($G15&" CORP",$CA$5)="#N/A N/A"),(_xll.BDP($G15&" CORP",$CA$5)),"-"), '[1]Country Codes'!$A$2:$B$253,2,0)} -> #N/A | AK15: {=IF(OR(_xll.BDP($AI15,"EX028")= "#N/A N/A", _xll.BDP($AI15,"EX028")="#N/A FIELD NOT APPLICABLE"), " ", _xll.BDP($AI15,"EX028"))} -> #N/A Connection | AL15: =(IF(_xll.BDP($AI15&" ISIN","DZ282")="Y","Single line Bonds Cocos","Single line Bonds ex Cocos")) -> Single line Bonds ex Cocos | AM15: =(IF(_xll.BDP($G15&" ISIN","SP153")="#n/a n/a"," ",_xll.BDP($G15&" ISIN","SP153"))) -> #N/A Connection | AN15: =TODAY() -> 45783 | AO15: =(((_xll.BDP(AI15,"DS032"))/360)*I15)*O15 -> #VALUE! | AP15: =IF(F15="USD",AO15,(((_xll.BDP(F15&"USD CURNCY","PX_LAST")))*AO15)) -> #VALUE! | AQ15: =S15/$S$113 -> #VALUE! | AR15: =S15-AP15 -> #VALUE! | AS15: =IF((TEXT(_xll.BDP(AI15,"MATURITY"),"DD/MM/YYYY")="#N/A Field Not Applicable"),"Perp",_xll.BDP(AI15,"DS252")) -> #N/A Connection | AT15: =(IF(_xll.BDP($AI15&" ISIN","DT247")="Y","Yes","No")) -> No | AU15: =PROPER(IF(OR(_xll.BDP($AI15,"CPN_TYP")="#n/a N/A",_xll.BDP($AI15,"CPN_TYP")= "#N/A FIELD NOT APPLICABLE"), " ", _xll.BDP($AI15,"CPN_TYP"))) -> #N/A Connection | BG15: =G15 -> XS2976035316 | BH15: 0.5519 | BI15: 5 | BJ15: 45677
A16: SYB | B16: Asar Mashkoor | C16: 4380370 | D16: Soc Gen | E16: =_xll.BDP(AI16,"ds520") -> TVF Varlik Kiralama AS | F16: =_xll.BDP(AI16,"crncy") -> USD | G16: XS2911679004 | H16: =IF(_xll.BDP(AI16,"RTG_MOODY")="#N/A N/A","N/A",_xll.BDP(AI16,"RTG_MOODY"))&","&IF(_xll.BDP(AI16,"RTG_FITCH")="#N/A N/A","N/A",_xll.BDP(AI16,"RTG_FITCH"))&","&IF(_xll.BDP(AI16,"RTG_SP")="#N/A N/A","N/A",_xll.BDP(AI16,"RTG_SP")) -> N/A,BB-,N/A | I16: =_xll.BDP(AI16,"cpn")/100 -> 0.0695 | J16: =_xll.BDP($G16&" isin","YAS_BOND_YLD", "YAS_YLD_FLAG=15", "user_local_trade_date",AN16,"Yas_bond_px",$Q16)/100 -> 0.07172291 | K16: =_xll.BDP(AI16,"PAYMENT_RANK") -> Sr Unsecured | L16: =IF((TEXT(_xll.BDP(AI16,"MATURITY"),"DD/MM/YYYY")="#N/A Field Not Applicable"),"Perp",TEXT(_xll.BDP(AI16,"MATURITY"),"DD/MM/YYYY")) -> 23/01/2030 | M16: =(IF(_xll.BDP($AI16&" ISIN","DU003")="#n/a n/a"," ",_xll.BDP($AI16&" ISIN","DU003"))) -> 4.030278 | N16: =IF(_xll.BDP(AI16,"CALLABLE")="Y",_xll.BDP(AI16,"NXT_CALL_DT")," ") | O16: 200000 | P16: 100.096 | Q16: =_xll.BDP(AI16,"px_bid") -> 99.11 | R16: =IF(F16="USD",AG16,(((_xll.BDP(F16&"USD CURNCY","PX_LAST")))*AG16)) -> 200192 | S16: =IF(F16="USD",AH16,(((_xll.BDP(F16&"USD CURNCY","PX_LAST")))*AH16))+AP16 -> 202042.5 | T16: =U16*R16 -> -1972 | U16: =(Q16-P16)/P16 -> -0.0098505435 | V16: {=IFERROR(_xll.BDP($G16&" ISIN","CHG_PCT_1D")/100,"")} | W16: {=IFERROR(_xll.BDP($G16&" ISIN","CHG_PCT_5D")/100,"")} | X16: {=_xll.BDP($G16&" ISIN","CHG_PCT_1M")/100} -> #VALUE! | Y16: {=_xll.BDP($G16&" ISIN","CHG_PCT_3M")/100} -> #VALUE! | Z16: {=_xll.BDP($G16&" ISIN","CHG_PCT_6M")/100} -> #VALUE! | AA16: {=_xll.BDP($G16&" ISIN","CHG_PCT_YTD")/100} -> #VALUE! | AB16: =S16/$H$36 -> #VALUE! | AC16: =((AF16*I16)* ((TODAY()-BJ16)/360))+(Q16-P16)%*AF16 -> 49303.556 | AD16: =_xll.BDP(AI16,"DS199") -> Financial | AE16: =_xll.BDP(AI16,"px_ask") -> 99.496 | AF16: =IF(F16="USD",O16,(((_xll.BDP(F16&"USD CURNCY","PX_LAST")))*O16)) -> 200000 | AG16: =O16*P16/100 -> 200192 | AH16: =Q16*O16/100 -> 198220 | AI16: =G16& " ISIN" -> XS2911679004 ISIN | AJ16: {=VLOOKUP(IF(NOT(_xll.BDP($G16&" CORP",$CA$5)="#N/A N/A"),(_xll.BDP($G16&" CORP",$CA$5)),"-"), '[1]Country Codes'!$A$2:$B$253,2,0)} -> #N/A | AK16: {=IF(OR(_xll.BDP($AI16,"EX028")= "#N/A N/A", _xll.BDP($AI16,"EX028")="#N/A FIELD NOT APPLICABLE"), " ", _xll.BDP($AI16,"EX028"))} -> FixedIncome | AL16: =(IF(_xll.BDP($AI16&" ISIN","DZ282")="Y","Single line Bonds Cocos","Single line Bonds ex Cocos")) -> Single line Bonds ex Cocos | AM16: =(IF(_xll.BDP($G16&" ISIN","SP153")="#n/a n/a"," ",_xll.BDP($G16&" ISIN","SP153"))) -> 370.64896 | AN16: =TODAY() -> 45783 | AO16: =(((_xll.BDP(AI16,"DS032"))/360)*I16)*O16 -> 3822.5 | AP16: =IF(F16="USD",AO16,(((_xll.BDP(F16&"USD CURNCY","PX_LAST")))*AO16)) -> 3822.5 | AQ16: =S16/$S$113 -> 0.38605659 | AR16: =S16-AP16 -> 198220 | AS16: =IF((TEXT(_xll.BDP(AI16,"MATURITY"),"DD/MM/YYYY")="#N/A Field Not Applicable"),"Perp",_xll.BDP(AI16,"DS252")) -> 4.733744 | AT16: =(IF(_xll.BDP($AI16&" ISIN","DT247")="Y","Yes","No")) -> No | AU16: =PROPER(IF(OR(_xll.BDP($AI16,"CPN_TYP")="#n/a N/A",_xll.BDP($AI16,"CPN_TYP")= "#N/A FIELD NOT APPLICABLE"), " ", _xll.BDP($AI16,"CPN_TYP"))) -> Fixed | BG16: =G16 -> XS2911679004 | BH16: 0.6714 | BI16: 5 | BJ16: 44455
A17: SYB | B17: Asar Mashkoor | C17: 4380370 | D17: Soc Gen | E17: =_xll.BDP(AI17,"ds520") -> #N/A Connection | F17: =_xll.BDP(AI17,"crncy") -> #N/A Connection | G17: XS2419405274 | H17: =IF(_xll.BDP(AI17,"RTG_MOODY")="#N/A N/A","N/A",_xll.BDP(AI17,"RTG_MOODY"))&","&IF(_xll.BDP(AI17,"RTG_FITCH")="#N/A N/A","N/A",_xll.BDP(AI17,"RTG_FITCH"))&","&IF(_xll.BDP(AI17,"RTG_SP")="#N/A N/A","N/A",_xll.BDP(AI17,"RTG_SP")) -> #N/A Connection,#N/A Connection,#N/A Connection | I17: =_xll.BDP(AI17,"cpn")/100 -> #VALUE! | J17: =_xll.BDP($G17&" isin","YAS_BOND_YLD", "YAS_YLD_FLAG=15", "user_local_trade_date",AN17,"Yas_bond_px",$Q17)/100 -> #VALUE! | K17: =_xll.BDP(AI17,"PAYMENT_RANK") -> #N/A Connection | L17: =IF((TEXT(_xll.BDP(AI17,"MATURITY"),"DD/MM/YYYY")="#N/A Field Not Applicable"),"Perp",TEXT(_xll.BDP(AI17,"MATURITY"),"DD/MM/YYYY")) -> #N/A Connection | M17: =(IF(_xll.BDP($AI17&" ISIN","DU003")="#n/a n/a"," ",_xll.BDP($AI17&" ISIN","DU003"))) -> #N/A Connection | N17: =IF(_xll.BDP(AI17,"CALLABLE")="Y",_xll.BDP(AI17,"NXT_CALL_DT")," ") | O17: 400000 | P17: 99.695 | Q17: =_xll.BDP(AI17,"px_bid") -> #N/A Connection | R17: =IF(F17="USD",AG17,(((_xll.BDP(F17&"USD CURNCY","PX_LAST")))*AG17)) -> #VALUE! | S17: =IF(F17="USD",AH17,(((_xll.BDP(F17&"USD CURNCY","PX_LAST")))*AH17))+AP17 -> #VALUE! | T17: =U17*R17 -> #VALUE! | U17: =(Q17-P17)/P17 -> #VALUE! | V17: {=IFERROR(_xll.BDP($G17&" ISIN","CHG_PCT_1D")/100,"")} | W17: {=IFERROR(_xll.BDP($G17&" ISIN","CHG_PCT_5D")/100,"")} | X17: {=_xll.BDP($G17&" ISIN","CHG_PCT_1M")/100} -> #VALUE! | Y17: {=_xll.BDP($G17&" ISIN","CHG_PCT_3M")/100} -> #VALUE! | Z17: {=_xll.BDP($G17&" ISIN","CHG_PCT_6M")/100} -> #VALUE! | AA17: {=_xll.BDP($G17&" ISIN","CHG_PCT_YTD")/100} -> #VALUE! | AB17: =S17/$H$36 -> #VALUE! | AC17: =((AF17*I17)* ((TODAY()-BJ17)/360))+(Q17-P17)%*AF17 -> #VALUE! | AD17: =_xll.BDP(AI17,"DS199") -> #N/A Connection | AE17: =_xll.BDP(AI17,"px_ask") -> #N/A Connection | AF17: =IF(F17="USD",O17,(((_xll.BDP(F17&"USD CURNCY","PX_LAST")))*O17)) -> #VALUE! | AG17: =O17*P17/100 -> 398780 | AH17: =Q17*O17/100 -> #VALUE! | AI17: =G17& " ISIN" -> XS2419405274 ISIN | AJ17: {=VLOOKUP(IF(NOT(_xll.BDP($G17&" CORP",$CA$5)="#N/A N/A"),(_xll.BDP($G17&" CORP",$CA$5)),"-"), '[1]Country Codes'!$A$2:$B$253,2,0)} -> #N/A | AK17: {=IF(OR(_xll.BDP($AI17,"EX028")= "#N/A N/A", _xll.BDP($AI17,"EX028")="#N/A FIELD NOT APPLICABLE"), " ", _xll.BDP($AI17,"EX028"))} -> #N/A Connection | AL17: =(IF(_xll.BDP($AI17&" ISIN","DZ282")="Y","Single line Bonds Cocos","Single line Bonds ex Cocos")) -> Single line Bonds ex Cocos | AM17: =(IF(_xll.BDP($G17&" ISIN","SP153")="#n/a n/a"," ",_xll.BDP($G17&" ISIN","SP153"))) -> #N/A Connection | AN17: =TODAY() -> 45783 | AO17: =(((_xll.BDP(AI17,"DS032"))/360)*I17)*O17 -> #VALUE! | AP17: =IF(F17="USD",AO17,(((_xll.BDP(F17&"USD CURNCY","PX_LAST")))*AO17)) -> #VALUE! | AQ17: =S17/$S$113 -> #VALUE! | AR17: =S17-AP17 -> #VALUE! | AS17: =IF((TEXT(_xll.BDP(AI17,"MATURITY"),"DD/MM/YYYY")="#N/A Field Not Applicable"),"Perp",_xll.BDP(AI17,"DS252")) -> #N/A Connection | AT17: =(IF(_xll.BDP($AI17&" ISIN","DT247")="Y","Yes","No")) -> No | AU17: =PROPER(IF(OR(_xll.BDP($AI17,"CPN_TYP")="#n/a N/A",_xll.BDP($AI17,"CPN_TYP")= "#N/A FIELD NOT APPLICABLE"), " ", _xll.BDP($AI17,"CPN_TYP"))) -> #N/A Connection | BG17: =G17 -> XS2419405274 | BH17: 0 | BI17: 5 | BJ17: 44592
A18: SYB | B18: Asar Mashkoor | C18: 4380370 | D18: Soc Gen | E18: =_xll.BDP(AI18,"ds520") -> #N/A Connection | F18: =_xll.BDP(AI18,"crncy") -> #N/A Connection | G18: XS2756519232 | H18: =IF(_xll.BDP(AI18,"RTG_MOODY")="#N/A N/A","N/A",_xll.BDP(AI18,"RTG_MOODY"))&","&IF(_xll.BDP(AI18,"RTG_FITCH")="#N/A N/A","N/A",_xll.BDP(AI18,"RTG_FITCH"))&","&IF(_xll.BDP(AI18,"RTG_SP")="#N/A N/A","N/A",_xll.BDP(AI18,"RTG_SP")) -> #N/A Connection,#N/A Connection,#N/A Connection | I18: =_xll.BDP(AI18,"cpn")/100 -> #VALUE! | J18: =_xll.BDP($G18&" isin","YAS_BOND_YLD", "YAS_YLD_FLAG=15", "user_local_trade_date",AN18,"Yas_bond_px",$Q18)/100 -> #VALUE! | K18: =_xll.BDP(AI18,"PAYMENT_RANK") -> #N/A Connection | L18: =IF((TEXT(_xll.BDP(AI18,"MATURITY"),"DD/MM/YYYY")="#N/A Field Not Applicable"),"Perp",TEXT(_xll.BDP(AI18,"MATURITY"),"DD/MM/YYYY")) -> #N/A Connection | M18: =(IF(_xll.BDP($AI18&" ISIN","DU003")="#n/a n/a"," ",_xll.BDP($AI18&" ISIN","DU003"))) -> #N/A Connection | N18: =IF(_xll.BDP(AI18,"CALLABLE")="Y",_xll.BDP(AI18,"NXT_CALL_DT")," ") | O18: 500000 | P18: 100.04 | Q18: =_xll.BDP(AI18,"px_bid") -> #N/A Connection | R18: =IF(F18="USD",AG18,(((_xll.BDP(F18&"USD CURNCY","PX_LAST")))*AG18)) -> #VALUE! | S18: =IF(F18="USD",AH18,(((_xll.BDP(F18&"USD CURNCY","PX_LAST")))*AH18))+AP18 -> #VALUE! | T18: =U18*R18 -> #VALUE! | U18: =(Q18-P18)/P18 -> #VALUE! | V18: {=IFERROR(_xll.BDP($G18&" ISIN","CHG_PCT_1D")/100,"")} | W18: {=IFERROR(_xll.BDP($G18&" ISIN","CHG_PCT_5D")/100,"")} | X18: {=_xll.BDP($G18&" ISIN","CHG_PCT_1M")/100} -> #VALUE! | Y18: {=_xll.BDP($G18&" ISIN","CHG_PCT_3M")/100} -> #VALUE! | Z18: {=_xll.BDP($G18&" ISIN","CHG_PCT_6M")/100} -> #VALUE! | AA18: {=_xll.BDP($G18&" ISIN","CHG_PCT_YTD")/100} -> #VALUE! | AB18: =S18/$H$36 -> #VALUE! | AC18: =((AF18*I18)* ((TODAY()-BJ18)/360))+(Q18-P18)%*AF18 -> #VALUE! | AD18: =_xll.BDP(AI18,"DS199") -> #N/A Connection | AE18: =_xll.BDP(AI18,"px_ask") -> #N/A Connection | AF18: =IF(F18="USD",O18,(((_xll.BDP(F18&"USD CURNCY","PX_LAST")))*O18)) -> #VALUE! | AG18: =O18*P18/100 -> 500200 | AH18: =Q18*O18/100 -> #VALUE! | AI18: =G18& " ISIN" -> XS2756519232 ISIN | AJ18: {=VLOOKUP(IF(NOT(_xll.BDP($G18&" CORP",$CA$5)="#N/A N/A"),(_xll.BDP($G18&" CORP",$CA$5)),"-"), '[1]Country Codes'!$A$2:$B$253,2,0)} -> #N/A | AK18: {=IF(OR(_xll.BDP($AI18,"EX028")= "#N/A N/A", _xll.BDP($AI18,"EX028")="#N/A FIELD NOT APPLICABLE"), " ", _xll.BDP($AI18,"EX028"))} -> #N/A Connection | AL18: =(IF(_xll.BDP($AI18&" ISIN","DZ282")="Y","Single line Bonds Cocos","Single line Bonds ex Cocos")) -> Single line Bonds ex Cocos | AM18: =(IF(_xll.BDP($G18&" ISIN","SP153")="#n/a n/a"," ",_xll.BDP($G18&" ISIN","SP153"))) -> #N/A Connection | AN18: =TODAY() -> 45783 | AO18: =(((_xll.BDP(AI18,"DS032"))/360)*I18)*O18 -> #VALUE! | AP18: =IF(F18="USD",AO18,(((_xll.BDP(F18&"USD CURNCY","PX_LAST")))*AO18)) -> #VALUE! | AQ18: =S18/$S$113 -> #VALUE! | AR18: =S18-AP18 -> #VALUE! | AS18: =IF((TEXT(_xll.BDP(AI18,"MATURITY"),"DD/MM/YYYY")="#N/A Field Not Applicable"),"Perp",_xll.BDP(AI18,"DS252")) -> #N/A Connection | AT18: =(IF(_xll.BDP($AI18&" ISIN","DT247")="Y","Yes","No")) -> No | AU18: =PROPER(IF(OR(_xll.BDP($AI18,"CPN_TYP")="#n/a N/A",_xll.BDP($AI18,"CPN_TYP")= "#N/A FIELD NOT APPLICABLE"), " ", _xll.BDP($AI18,"CPN_TYP"))) -> #N/A Connection | BG18: =G18 -> XS2756519232 | BH18: 0.8158 | BI18: 4 | BJ18: 45352
