Workbook

Sheet Cover
B2: BONDS | L2: Notes
B3: Criteria | D3: Y/N | E3: # positions
B4: 1D Price Change < -1.0%? | D4: =IF(MIN(Bonds!V:V)<-1%,"Y","-") -> Y | E4: =COUNTIF(Bonds!V:V,"<-1.0%") -> 9
B5: 5D Price Change < -5.0%? | D5: =IF(MIN(Bonds!W:W)<-5%,"Y","-") -> Y | E5: =COUNTIF(Bonds!W:W,"<-5.0%") -> 7
B6: 1D Price Change > +1.0%? | D6: =IF(MAX(Bonds!V:V)>1%,"Y","-") -> Y | E6: =COUNTIF(Bonds!V:V,">1.0%") -> 5
B7: 5D Price Change > +5.0%? | D7: =IF(MAX(Bonds!W:W)>5%,"Y","-") -> Y | E7: =COUNTIF(Bonds!W:W,">5.0%") -> 4
B10: EQUITIES
B11: Criteria | D11: Y/N | E11: # positions
B12: 1D Price Change < -5%? | D12: =IF(MIN(Equities!V:V)<-5%,"Y","-") -> - | E12: =COUNTIF(Equities!V:V,"<-5%") -> 0
B13: 5D Price Change < -10%? | D13: =IF(MIN(Equities!W:W)<-10%,"Y","-") -> - | E13: =COUNTIF(Equities!W:W,"<-10%") -> 0
B14: 1D Price Change > +5%? | D14: =IF(MAX(Equities!V:V)>5%,"Y","-") -> Y | E14: =COUNTIF(Equities!V:V,">5%") -> 7
B15: 5D Price Change > +10%? | D15: =IF(MAX(Equities!W:W)>10%,"Y","-") -> Y | E15: =COUNTIF(Equities!W:W,">10%") -> 53
B18: MF and ETFs
B19: Criteria | D19: Y/N | E19: # positions
B20: 1D Price Change < -5%? | D20: =IF(MIN('MF and ETFs'!V:V)<-5%,"Y","-") -> - | E20: =COUNTIF('MF and ETFs'!V:V,"<-5%") -> 0
B21: 5D Price Change < -10%? | D21: =IF(MIN('MF and ETFs'!W:W)<-10%,"Y","-") -> - | E21: =COUNTIF('MF and ETFs'!W:W,"<-10%") -> 0
B22: 1D Price Change > +5%? | D22: =IF(MAX('MF and ETFs'!V:V)>5%,"Y","-") -> - | E22: =COUNTIF('MF and ETFs'!V:V,">5%") -> 0
B23: 5D Price Change > +10%? | D23: =IF(MAX('MF and ETFs'!W:W)>10%,"Y","-") -> Y | E23: =COUNTIF('MF and ETFs'!W:W,">10%") -> 5
B26: Commodities
B27: Criteria | D27: Y/N | E27: # positions
B28: 1D Price Change < -5%? | D28: =IF(MIN(Commodities!P:P)<-5%,"Y","-") -> - | E28: =COUNTIF(Commodities!P:P,"<-5%") -> 0
B29: 5D Price Change < -10%? | D29: =IF(MIN(Commodities!Q:Q)<-10%,"Y","-") -> - | E29: =COUNTIF(Commodities!Q:Q,"<-10%") -> 0
B30: 1D Price Change > +5%? | D30: =IF(MAX(Commodities!P:P)>5%,"Y","-") -> - | E30: =COUNTIF(Commodities!P:P,">5%") -> 0
B31: 5D Price Change > +10%? | D31: =IF(MAX(Commodities!Q:Q)>10%,"Y","-") -> - | E31: =COUNTIF(Commodities!Q:Q,">10%") -> 0

Sheet Cash
A2: Last Updated | F2: 45764
A4: RM | B4: Client | C4: Cash ($) | D4: Fiduciary Deposit ($) | E4: Money Market Funds ($) | F4: Total ($)
A5: SYB | B5: AKCT (ex DPM) | C5: =6558200.412952-88151 -> 6470049.4 | D5: 5159000 | E5: 0 | F5: =C5+D5+E5 -> 11629049
A6: SYB | B6: Alpha One | C6: 1544040.3 | D6: 1020256.6 | E6: 0 | F6: =C6+D6+E6 -> 2564296.8
A7: SYB | B7: Chianti | C7: 1208830.2 | D7: 1374327.1 | E7: 0 | F7: =C7+D7+E7 -> 2583157.3
A8: SYB | B8: MHM | C8: 423673.56 | D8: 419443.69 | E8: 0 | F8: =C8+D8+E8 -> 843117.25
A9: SYB | B9: MI | C9: 2464257.5 | D9: 0 | E9: 0 | F9: =C9+D9+E9 -> 2464257.5
A10: SYB | B10: Silver Chroma | C10: 4394528.4 | D10: 1000000 | E10: 0 | F10: =C10+D10+E10 -> 5394528.4
A11: SS | B11: DEEM | F11: =C11+D11+E11 -> 0
A12: SS | B12: GE | C12: 16017514 | D12: 1103872.5 | E12: 0 | F12: =C12+D12+E12 -> 17121387
A13: SS | B13: GI | C13: 20038.32 | D13: 1137000 | E13: 8485715.3 | F13: =C13+D13+E13 -> 9642753.6
A14: SS | B14: Growbiz | C14: 899476.65 | D14: 0 | E14: 0 | F14: =C14+D14+E14 -> 899476.65
A15: SS | B15: LH | C15: 5077244.6 | D15: 4400000 | E15: 0 | F15: =C15+D15+E15 -> 9477244.6
A16: SS | B16: MAG | C16: 721.31537 | D16: 0 | E16: 0 | F16: =C16+D16+E16 -> 721.31537
A17: SS | B17: Omni | C17: 279775.04 | D17: 0 | E17: 789440 | F17: =C17+D17+E17 -> 1069215

Sheet Bonds
L1: Maturity in current month highlighted | N1: Call date in current month highlighted | U1: +/- 5% higlighted | V1: +/- 1% highlighted | W1: +/- 5% highlighted
A2: RM | B2: Client | C2: Account no. | D2: Custodian | E2: Name | F2: Ccy | G2: ISIN | H2: Moodys / Fitch / S&P | I2: Coupon | J2: Yld. to Wrst. | K2: Rank | L2: Maturity | M2: Duration | N2: Next Call Dt. | O2: Notional | P2: Pur. Price | Q2: Ind. Bid | R2: Pur. Value ($) | S2: Mkt. Value + Accrued ($) | T2: P/L ($) | U2: % P/L | V2: 1D Price Change | W2: 5D Price Change | X2: 1M Price Change | Y2: 3M Price Change | Z2: 6M Price Change | AA2: YTD | AB2: Portfolio Wt % | AC2: Total Return ($) | AD2: Industry | AE2: Ind. Ask | AF2: Notional ($) | AG2: Purchase Value | AH2: Market Value | AI2: ID_ISIN | AJ2: Country of Risk | AK2: Asset Class | AL2: Sub Classification | AM2: Z Spread | AN2: For YTW Formula | AO2: Accrued Interest | AP2: Accrued Interest ($) | AQ2: Weight in bond portfolio % | AR2: Market Value ($) ex Accrued | AS2: Years to Maturity | AT2: Non-Viability Check | AU2: Coupon Type | BG2: ISIN | BH2: Pur. Date
A3: SYB | B3: AKCT | C3: 4371510 | D3: SocGen | E3: =_xll.BDP(AI3,"ds520") -> Abu Dhabi Commercial Bank PJSC | F3: =_xll.BDP(AI3,"crncy") -> USD | G3: XS2725803162 | H3: =IF(_xll.BDP(AI3,"RTG_MOODY")="#N/A N/A","N/A",_xll.BDP(AI3,"RTG_MOODY"))&","&IF(_xll.BDP(AI3,"RTG_FITCH")="#N/A N/A","N/A",_xll.BDP(AI3,"RTG_FITCH"))&","&IF(_xll.BDP(AI3,"RTG_SP")="#N/A N/A","N/A",_xll.BDP(AI3,"RTG_SP")) -> N/A,N/A,N/A | I3: =_xll.BDP(AI3,"cpn")/100 -> 0.08 | J3: =_xll.BDP($G3&" isin","YAS_BOND_YLD", "YAS_YLD_FLAG=15", "user_local_trade_date",AN3,"Yas_bond_px",$Q3)/100 -> 0.06072132 | K3: =_xll.BDP(AI3,"PAYMENT_RANK") -> Jr Subordinated | L3: =IF((TEXT(_xll.BDP(AI3,"MATURITY"),"DD/MM/YYYY")="#N/A Field Not Applicable"),"Perp",TEXT(_xll.BDP(AI3,"MATURITY"),"DD/MM/YYYY")) -> Perp | M3: =(IF(_xll.BDP($AI3&" ISIN","DU003")="#n/a n/a"," ",_xll.BDP($AI3&" ISIN","DU003"))) -> 3.0930509 | N3: =IF(_xll.BDP(AI3,"CALLABLE")="Y",_xll.BDP(AI3,"NXT_CALL_DT")," ") -> 27/11/2028 | O3: 500000 | P3: 100 | Q3: =_xll.BDP(AI3,"px_bid") -> 106.097 | R3: =IF(F3="USD",AG3,(((_xll.BDP(F3&"USD CURNCY","PX_LAST")))*AG3)) -> 500000 | S3: =IF(F3="USD",AH3,(((_xll.BDP(F3&"USD CURNCY","PX_LAST")))*AH3))+AP3 -> 547361.71 | T3: =U3*R3 -> 30485 | U3: =(Q3-P3)/P3 -> 0.06097 | V3: {=IFERROR(_xll.BDP($G3&" ISIN","CHG_PCT_1D")/100,"")} -> -9.393464e-05 | W3: {=IFERROR(_xll.BDP($G3&" ISIN","CHG_PCT_5D")/100,"")} -> -0.00041318046 | X3: {=_xll.BDP($G3&" ISIN","CHG_PCT_1M")/100} -> -0.0040512725 | Y3: {=_xll.BDP($G3&" ISIN","CHG_PCT_3M")/100} -> 0.00040412015 | Z3: {=_xll.BDP($G3&" ISIN","CHG_PCT_6M")/100} -> -0.012037793 | AA3: {=_xll.BDP($G3&" ISIN","CHG_PCT_YTD")/100} -> -0.003995359 | AB3: =S3/$H$36 -> #VALUE! | AC3: =((AF3*I3)* ((TODAY()-BH3)/360))+(Q3-P3)%*AF3 -> 88262.778 | AD3: =_xll.BDP(AI3,"DS199") -> Financial | AE3: =_xll.BDP(AI3,"px_ask") -> 106.796 | AF3: =IF(F3="USD",O3,(((_xll.BDP(F3&"USD CURNCY","PX_LAST")))*O3)) -> 500000 | AG3: =O3*P3/100 -> 500000 | AH3: =Q3*O3/100 -> 530485 | AI3: =G3& " ISIN" -> XS2725803162 ISIN | AJ3: {=VLOOKUP(IF(NOT(_xll.BDP($G3&" CORP",$BX$4)="#N/A N/A"),(_xll.BDP($G3&" CORP",$BX$4)),"-"), '[1]Country Codes'!$A$2:$B$253,2,0)} -> #N/A | AK3: {=IF(OR(_xll.BDP($AI3,"EX028")= "#N/A N/A", _xll.BDP($AI3,"EX028")="#N/A FIELD NOT APPLICABLE"), " ", _xll.BDP($AI3,"EX028"))} -> FixedIncome | AL3: =(IF(_xll.BDP($AI3&" ISIN","DZ282")="Y","Single line Bonds Cocos","Single line Bonds ex Cocos")) -> Single line Bonds ex Cocos | AM3: =(IF(_xll.BDP($G3&" ISIN","SP153")="#n/a n/a"," ",_xll.BDP($G3&" ISIN","SP153"))) -> 251.8247 | AN3: =TODAY() -> 45777 | AO3: =(((_xll.BDP(AI3,"DS032"))/365)*I3)*O3 -> 16876.712 | AP3: =IF(F3="USD",AO3,(((_xll.BDP(F3&"USD CURNCY","PX_LAST")))*AO3)) -> 16876.712 | AQ3: =S3/$S$147 -> 2.406423 | AR3: =S3-AP3 -> 530485 | AS3: =IF((TEXT(_xll.BDP(AI3,"MATURITY"),"DD/MM/YYYY")="#N/A Field Not Applicable"),"Perp",_xll.BDP(AI3,"DS252")) -> Perp | AT3: =(IF(_xll.BDP($AI3&" ISIN","DT247")="Y","Yes","No")) -> Yes | AU3: =PROPER(IF(OR(_xll.BDP($AI3,"CPN_TYP")="#n/a N/A",_xll.BDP($AI3,"CPN_TYP")= "#N/A FIELD NOT APPLICABLE"), " ", _xll.BDP($AI3,"CPN_TYP"))) -> Variable | BG3: =G3 -> XS2725803162 | BH3: 45257
A4: SYB | B4: AKCT | C4: 4371510 | D4: SocGen | E4: =_xll.BDP(AI4,"ds520") -> Alpha Holding SA de CV | F4: =_xll.BDP(AI4,"crncy") -> USD | G4: USP1000TAB37 | H4: =IF(_xll.BDP(AI4,"RTG_MOODY")="#N/A N/A","N/A",_xll.BDP(AI4,"RTG_MOODY"))&","&IF(_xll.BDP(AI4,"RTG_FITCH")="#N/A N/A","N/A",_xll.BDP(AI4,"RTG_FITCH"))&","&IF(_xll.BDP(AI4,"RTG_SP")="#N/A N/A","N/A",_xll.BDP(AI4,"RTG_SP")) -> WR,WD,NR | I4: 0 | J4: 0 | K4: =_xll.BDP(AI4,"PAYMENT_RANK") -> Sr Unsecured | L4: =IF((TEXT(_xll.BDP(AI4,"MATURITY"),"DD/MM/YYYY")="#N/A Field Not Applicable"),"Perp",TEXT(_xll.BDP(AI4,"MATURITY"),"DD/MM/YYYY")) -> 10/02/2025 | M4: =(IF(_xll.BDP($AI4&" ISIN","DU003")="#n/a n/a"," ",_xll.BDP($AI4&" ISIN","DU003"))) -> 0 | N4: =IF(_xll.BDP(AI4,"CALLABLE")="Y",_xll.BDP(AI4,"NXT_CALL_DT")," ") -> #N/A Field Not Applicable | O4: 500000 | P4: 100.8308 | Q4: =_xll.BDP(AI4,"px_bid") -> 0.358 | R4: =IF(F4="USD",AG4,(((_xll.BDP(F4&"USD CURNCY","PX_LAST")))*AG4)) -> 504154 | S4: =IF(F4="USD",AH4,(((_xll.BDP(F4&"USD CURNCY","PX_LAST")))*AH4))+AP4 -> 1790 | T4: =U4*R4 -> -502364 | U4: =(Q4-P4)/P4 -> -0.9964495 | V4: {=IFERROR(_xll.BDP($G4&" ISIN","CHG_PCT_1D")/100,"")} -> -0.0041605978 | W4: {=IFERROR(_xll.BDP($G4&" ISIN","CHG_PCT_5D")/100,"")} -> 0.0053194798 | X4: {=_xll.BDP($G4&" ISIN","CHG_PCT_1M")/100} -> -0.38676983 | Y4: {=_xll.BDP($G4&" ISIN","CHG_PCT_3M")/100} -> -0.55099547 | Z4: {=_xll.BDP($G4&" ISIN","CHG_PCT_6M")/100} -> -0.46198443 | AA4: {=_xll.BDP($G4&" ISIN","CHG_PCT_YTD")/100} -> -0.52499731 | AB4: =S4/$H$37 -> #VALUE! | AC4: =((AF4*I4)* ((TODAY()-BH4)/360))+(Q4-P4)%*AF4 -> -502364 | AD4: =_xll.BDP(AI4,"DS199") -> Financial | AE4: =_xll.BDP(AI4,"px_ask") -> 0.896 | AF4: =IF(F4="USD",O4,(((_xll.BDP(F4&"USD CURNCY","PX_LAST")))*O4)) -> 500000 | AG4: =O4*P4/100 -> 504154 | AH4: =Q4*O4/100 -> 1790 | AI4: =G4& " ISIN" -> USP1000TAB37 ISIN | AJ4: {=VLOOKUP(IF(NOT(_xll.BDP($G4&" CORP",#REF!)="#N/A N/A"),(_xll.BDP($G4&" CORP",#REF!)),"-"), '[1]Country Codes'!$A$2:$B$253,2,0)} -> #REF! | AK4: {=IF(OR(_xll.BDP($AI4,"EX028")= "#N/A N/A", _xll.BDP($AI4,"EX028")="#N/A FIELD NOT APPLICABLE"), " ", _xll.BDP($AI4,"EX028"))} -> FixedIncome | AL4: =(IF(_xll.BDP($AI4&" ISIN","DZ282")="Y","Single line Bonds Cocos","Single line Bonds ex Cocos")) -> Single line Bonds ex Cocos | AM4: =(IF(_xll.BDP($G4&" ISIN","SP153")="#n/a n/a"," ",_xll.BDP($G4&" ISIN","SP153"))) | AN4: =TODAY() -> 45777 | AO4: =(((_xll.BDP(AI4,"DS032"))/360)*I4)*O4 -> 0 | AP4: =IF(F4="USD",AO4,(((_xll.BDP(F4&"USD CURNCY","PX_LAST")))*AO4)) -> 0 | AQ4: =S4/$S$159 -> 0.001968072 | AR4: =S4-AP4 -> 1790 | AS4: =IF((TEXT(_xll.BDP(AI4,"MATURITY"),"DD/MM/YYYY")="#N/A Field Not Applicable"),"Perp",_xll.BDP(AI4,"DS252")) -> -0.21355236 | AT4: =(IF(_xll.BDP($AI4&" ISIN","DT247")="Y","Yes","No")) -> No | AU4: =PROPER(IF(OR(_xll.BDP($AI4,"CPN_TYP")="#n/a N/A",_xll.BDP($AI4,"CPN_TYP")= "#N/A FIELD NOT APPLICABLE"), " ", _xll.BDP($AI4,"CPN_TYP"))) -> Defaulted | BG4: =G4 -> USP1000TAB37 | BH4: 43871
A5: SYB | B5: AKCT | C5: 4371510 | D5: SocGen | E5: =_xll.BDP(AI5,"ds520") -> Bahrain Government International Bond | F5: =_xll.BDP(AI5,"crncy") -> USD | G5: XS2408003064 | H5: =IF(_xll.BDP(AI5,"RTG_MOODY")="#N/A N/A","N/A",_xll.BDP(AI5,"RTG_MOODY"))&","&IF(_xll.BDP(AI5,"RTG_FITCH")="#N/A N/A","N/A",_xll.BDP(AI5,"RTG_FITCH"))&","&IF(_xll.BDP(AI5,"RTG_SP")="#N/A N/A","N/A",_xll.BDP(AI5,"RTG_SP")) -> N/A,B+,B+ | I5: =_xll.BDP(AI5,"cpn")/100 -> 0.05625 | J5: =_xll.BDP($G5&" isin","YAS_BOND_YLD", "YAS_YLD_FLAG=15", "user_local_trade_date",AN5,"Yas_bond_px",$Q5)/100 -> 0.06944183 | K5: =_xll.BDP(AI5,"PAYMENT_RANK") -> Sr Unsecured | L5: =IF((TEXT(_xll.BDP(AI5,"MATURITY"),"DD/MM/YYYY")="#N/A Field Not Applicable"),"Perp",TEXT(_xll.BDP(AI5,"MATURITY"),"DD/MM/YYYY")) -> 18/05/2034 | M5: =(IF(_xll.BDP($AI5&" ISIN","DU003")="#n/a n/a"," ",_xll.BDP($AI5&" ISIN","DU003"))) -> 6.9234939 | N5: =IF(_xll.BDP(AI5,"CALLABLE")="Y",_xll.BDP(AI5,"NXT_CALL_DT")," ") | O5: 1400000 | P5: 100 | Q5: =_xll.BDP(AI5,"px_bid") -> 91.245 | R5: =IF(F5="USD",AG5,(((_xll.BDP(F5&"USD CURNCY","PX_LAST")))*AG5)) -> 1400000 | S5: =IF(F5="USD",AH5,(((_xll.BDP(F5&"USD CURNCY","PX_LAST")))*AH5))+AP5 -> 1312597.8 | T5: =U5*R5 -> -122570 | U5: =(Q5-P5)/P5 -> -0.08755 | V5: {=IFERROR(_xll.BDP($G5&" ISIN","CHG_PCT_1D")/100,"")} -> -0.0047255385 | W5: {=IFERROR(_xll.BDP($G5&" ISIN","CHG_PCT_5D")/100,"")} -> 0.0050351583 | X5: {=_xll.BDP($G5&" ISIN","CHG_PCT_1M")/100} -> -0.010369634 | Y5: {=_xll.BDP($G5&" ISIN","CHG_PCT_3M")/100} -> -0.0035781483 | Z5: {=_xll.BDP($G5&" ISIN","CHG_PCT_6M")/100} -> -0.014362097 | AA5: {=_xll.BDP($G5&" ISIN","CHG_PCT_YTD")/100} -> 0.0098985891 | AB5: =S5/$H$37 -> #VALUE! | AC5: =((AF5*I5)* ((TODAY()-BH5)/360))+(Q5-P5)%*AF5 -> 152836.25 | AD5: =_xll.BDP(AI5,"DS199") -> Government | AE5: =_xll.BDP(AI5,"px_ask") -> 91.958 | AF5: =IF(F5="USD",O5,(((_xll.BDP(F5&"USD CURNCY","PX_LAST")))*O5)) -> 1400000 | AG5: =O5*P5/100 -> 1400000 | AH5: =Q5*O5/100 -> 1277430 | AI5: =G5& " ISIN" -> XS2408003064 ISIN | AJ5: {=VLOOKUP(IF(NOT(_xll.BDP($G5&" CORP",#REF!)="#N/A N/A"),(_xll.BDP($G5&" CORP",#REF!)),"-"), '[1]Country Codes'!$A$2:$B$253,2,0)} -> #REF! | AK5: {=IF(OR(_xll.BDP($AI5,"EX028")= "#N/A N/A", _xll.BDP($AI5,"EX028")="#N/A FIELD NOT APPLICABLE"), " ", _xll.BDP($AI5,"EX028"))} -> FixedIncome | AL5: =(IF(_xll.BDP($AI5&" ISIN","DZ282")="Y","Single line Bonds Cocos","Single line Bonds ex Cocos")) -> Single line Bonds ex Cocos | AM5: =(IF(_xll.BDP($G5&" ISIN","SP153")="#n/a n/a"," ",_xll.BDP($G5&" ISIN","SP153"))) -> 320.22985 | AN5: =TODAY() -> 45777 | AO5: =(((_xll.BDP(AI5,"DS032"))/365)*I5)*O5 -> 35167.808 | AP5: =IF(F5="USD",AO5,(((_xll.BDP(F5&"USD CURNCY","PX_LAST")))*AO5)) -> 35167.808 | AQ5: =S5/#REF! -> #REF! | AR5: =S5-AP5 -> 1277430 | AS5: =IF((TEXT(_xll.BDP(AI5,"MATURITY"),"DD/MM/YYYY")="#N/A Field Not Applicable"),"Perp",_xll.BDP(AI5,"DS252")) -> 9.0513347 | AT5: =(IF(_xll.BDP($AI5&" ISIN","DT247")="Y","Yes","No")) -> No | AU5: =PROPER(IF(OR(_xll.BDP($AI5,"CPN_TYP")="#n/a N/A",_xll.BDP($AI5,"CPN_TYP")= "#N/A FIELD NOT APPLICABLE"), " ", _xll.BDP($AI5,"CPN_TYP"))) -> Fixed | BG5: =G5 -> XS2408003064 | BH5: 44518
A6: SYB | B6: AKCT | C6: 4371510 | D6: SocGen | E6: =_xll.BDP(AI6,"ds520") -> Bapco Energies Sukuk Ltd | F6: =_xll.BDP(AI6,"crncy") -> USD | G6: XS2976035316 | H6: =IF(_xll.BDP(AI6,"RTG_MOODY")="#N/A N/A","N/A",_xll.BDP(AI6,"RTG_MOODY"))&","&IF(_xll.BDP(AI6,"RTG_FITCH")="#N/A N/A","N/A",_xll.BDP(AI6,"RTG_FITCH"))&","&IF(_xll.BDP(AI6,"RTG_SP")="#N/A N/A","N/A",_xll.BDP(AI6,"RTG_SP")) -> N/A,B+,N/A | I6: =_xll.BDP(AI6,"cpn")/100 -> 0.0625 | J6: =_xll.BDP($G6&" isin","YAS_BOND_YLD", "YAS_YLD_FLAG=15", "user_local_trade_date",AN6,"Yas_bond_px",$Q6)/100 -> 0.06108459 | K6: =_xll.BDP(AI6,"PAYMENT_RANK") -> Sr Unsecured | L6: =IF((TEXT(_xll.BDP(AI6,"MATURITY"),"DD/MM/YYYY")="#N/A Field Not Applicable"),"Perp",TEXT(_xll.BDP(AI6,"MATURITY"),"DD/MM/YYYY")) -> 29/01/2035 | M6: =(IF(_xll.BDP($AI6&" ISIN","DU003")="#n/a n/a"," ",_xll.BDP($AI6&" ISIN","DU003"))) -> 7.350562 | N6: =IF(_xll.BDP(AI6,"CALLABLE")="Y",_xll.BDP(AI6,"NXT_CALL_DT")," ") | O6: 1000000 | P6: 100.3 | Q6: =_xll.BDP(AI6,"px_bid") -> 101.016 | R6: =IF(F6="USD",AG6,(((_xll.BDP(F6&"USD CURNCY","PX_LAST")))*AG6)) -> 1003000 | S6: =IF(F6="USD",AH6,(((_xll.BDP(F6&"USD CURNCY","PX_LAST")))*AH6))+AP6 -> 1025913.4 | T6: =U6*R6 -> 7160 | U6: =(Q6-P6)/P6 -> 0.0071385842 | V6: {=IFERROR(_xll.BDP($G6&" ISIN","CHG_PCT_1D")/100,"")} -> -0.0014391514 | W6: {=IFERROR(_xll.BDP($G6&" ISIN","CHG_PCT_5D")/100,"")} -> 0.0046283256 | X6: {=_xll.BDP($G6&" ISIN","CHG_PCT_1M")/100} -> 0.0080135658 | Y6: {=_xll.BDP($G6&" ISIN","CHG_PCT_3M")/100} -> #VALUE! | Z6: {=_xll.BDP($G6&" ISIN","CHG_PCT_6M")/100} -> #VALUE! | AA6: {=_xll.BDP($G6&" ISIN","CHG_PCT_YTD")/100} -> #VALUE! | AB6: =S6/$H$37 -> #VALUE! | AC6: =((AF6*I6)* ((TODAY()-BH6)/360))+(Q6-P6)%*AF6 -> 22958.611 | AD6: =_xll.BDP(AI6,"DS199") -> Energy | AE6: =_xll.BDP(AI6,"px_ask") -> 102.291 | AF6: =IF(F6="USD",O6,(((_xll.BDP(F6&"USD CURNCY","PX_LAST")))*O6)) -> 1000000 | AG6: =O6*P6/100 -> 1003000 | AH6: =Q6*O6/100 -> 1010160 | AI6: =G6& " ISIN" -> XS2976035316 ISIN | AJ6: {=VLOOKUP(IF(NOT(_xll.BDP($G6&" CORP",#REF!)="#N/A N/A"),(_xll.BDP($G6&" CORP",#REF!)),"-"), '[1]Country Codes'!$A$2:$B$253,2,0)} -> #REF! | AK6: {=IF(OR(_xll.BDP($AI6,"EX028")= "#N/A N/A", _xll.BDP($AI6,"EX028")="#N/A FIELD NOT APPLICABLE"), " ", _xll.BDP($AI6,"EX028"))} -> FixedIncome | AL6: =(IF(_xll.BDP($AI6&" ISIN","DZ282")="Y","Single line Bonds Cocos","Single line Bonds ex Cocos")) -> Single line Bonds ex Cocos | AM6: =(IF(_xll.BDP($G6&" ISIN","SP153")="#n/a n/a"," ",_xll.BDP($G6&" ISIN","SP153"))) -> 231.40355 | AN6: =TODAY() -> 45777 | AO6: =(((_xll.BDP(AI6,"DS032"))/365)*I6)*O6 -> 15753.425 | AP6: =IF(F6="USD",AO6,(((_xll.BDP(F6&"USD CURNCY","PX_LAST")))*AO6)) -> 15753.425 | AQ6: =S6/#REF! -> #REF! | AR6: =S6-AP6 -> 1010160 | AS6: =IF((TEXT(_xll.BDP(AI6,"MATURITY"),"DD/MM/YYYY")="#N/A Field Not Applicable"),"Perp",_xll.BDP(AI6,"DS252")) -> 9.7522245 | AT6: =(IF(_xll.BDP($AI6&" ISIN","DT247")="Y","Yes","No")) -> No | AU6: =PROPER(IF(OR(_xll.BDP($AI6,"CPN_TYP")="#n/a N/A",_xll.BDP($AI6,"CPN_TYP")= "#N/A FIELD NOT APPLICABLE"), " ", _xll.BDP($AI6,"CPN_TYP"))) -> Fixed | BG6: =G6 -> XS2976035316 | BH6: 45686
A7: SYB | B7: AKCT | C7: 4371510 | D7: SocGen | E7: =_xll.BDP(AI7,"ds520") -> Credit Bank of Moscow Via CBOM Finance PLC | F7: =_xll.BDP(AI7,"crncy") -> USD | G7: XS2392969395 | H7: =IF(_xll.BDP(AI7,"RTG_MOODY")="#N/A N/A","N/A",_xll.BDP(AI7,"RTG_MOODY"))&","&IF(_xll.BDP(AI7,"RTG_FITCH")="#N/A N/A","N/A",_xll.BDP(AI7,"RTG_FITCH"))&","&IF(_xll.BDP(AI7,"RTG_SP")="#N/A N/A","N/A",_xll.BDP(AI7,"RTG_SP")) -> N/A,WD,N/A | I7: 0 | J7: 0 | K7: =_xll.BDP(AI7,"PAYMENT_RANK") -> Jr Subordinated | L7: =IF((TEXT(_xll.BDP(AI7,"MATURITY"),"DD/MM/YYYY")="#N/A Field Not Applicable"),"Perp",TEXT(_xll.BDP(AI7,"MATURITY"),"DD/MM/YYYY")) -> Perp | M7: =(IF(_xll.BDP($AI7&" ISIN","DU003")="#n/a n/a"," ",_xll.BDP($AI7&" ISIN","DU003"))) -> 1.6848485 | N7: =IF(_xll.BDP(AI7,"CALLABLE")="Y",_xll.BDP(AI7,"NXT_CALL_DT")," ") -> 04/04/2027 | O7: 400000 | P7: 100.05 | Q7: =_xll.BDP(AI7,"px_bid") -> 14.564 | R7: =IF(F7="USD",AG7,(((_xll.BDP(F7&"USD CURNCY","PX_LAST")))*AG7)) -> 400200 | S7: =IF(F7="USD",AH7,(((_xll.BDP(F7&"USD CURNCY","PX_LAST")))*AH7))+AP7 -> 58256 | T7: =U7*R7 -> -341944 | U7: =(Q7-P7)/P7 -> -0.85443278 | V7: {=IFERROR(_xll.BDP($G7&" ISIN","CHG_PCT_1D")/100,"")} -> -0.0032517284 | W7: {=IFERROR(_xll.BDP($G7&" ISIN","CHG_PCT_5D")/100,"")} -> -0.021713882 | X7: {=_xll.BDP($G7&" ISIN","CHG_PCT_1M")/100} -> -0.16957428 | Y7: {=_xll.BDP($G7&" ISIN","CHG_PCT_3M")/100} -> -0.29017103 | Z7: {=_xll.BDP($G7&" ISIN","CHG_PCT_6M")/100} -> -0.30788754 | AA7: {=_xll.BDP($G7&" ISIN","CHG_PCT_YTD")/100} -> -0.28973632 | AB7: =S7/$H$37 -> #VALUE! | AC7: =((AF7*I7)* ((TODAY()-BH7)/360))+(Q7-P7)%*AF7 -> -341944 | AD7: =_xll.BDP(AI7,"DS199") -> Financial | AE7: =_xll.BDP(AI7,"px_ask") -> 23.593 | AF7: =IF(F7="USD",O7,(((_xll.BDP(F7&"USD CURNCY","PX_LAST")))*O7)) -> 400000 | AG7: =O7*P7/100 -> 400200 | AH7: =Q7*O7/100 -> 58256 | AI7: =G7& " ISIN" -> XS2392969395 ISIN | AJ7: {=VLOOKUP(IF(NOT(_xll.BDP($G7&" CORP",#REF!)="#N/A N/A"),(_xll.BDP($G7&" CORP",#REF!)),"-"), '[1]Country Codes'!$A$2:$B$253,2,0)} -> #REF! | AK7: {=IF(OR(_xll.BDP($AI7,"EX028")= "#N/A N/A", _xll.BDP($AI7,"EX028")="#N/A FIELD NOT APPLICABLE"), " ", _xll.BDP($AI7,"EX028"))} -> FixedIncome | AL7: =(IF(_xll.BDP($AI7&" ISIN","DZ282")="Y","Single line Bonds Cocos","Single line Bonds ex Cocos")) -> Single line Bonds Cocos | AM7: =(IF(_xll.BDP($G7&" ISIN","SP153")="#n/a n/a"," ",_xll.BDP($G7&" ISIN","SP153"))) -> 4414.9769 | AN7: =TODAY() -> 45777 | AO7: =(((_xll.BDP(AI7,"DS032"))/360)*I7)*O7 -> 0 | AP7: =IF(F7="USD",AO7,(((_xll.BDP(F7&"USD CURNCY","PX_LAST")))*AO7)) -> 0 | AQ7: =S7/$S$153 -> 1.318755 | AR7: =S7-AP7 -> 58256 | AS7: =IF((TEXT(_xll.BDP(AI7,"MATURITY"),"DD/MM/YYYY")="#N/A Field Not Applicable"),"Perp",_xll.BDP(AI7,"DS252")) -> Perp | AT7: =(IF(_xll.BDP($AI7&" ISIN","DT247")="Y","Yes","No")) -> Yes | AU7: =PROPER(IF(OR(_xll.BDP($AI7,"CPN_TYP")="#n/a N/A",_xll.BDP($AI7,"CPN_TYP")= "#N/A FIELD NOT APPLICABLE"), " ", _xll.BDP($AI7,"CPN_TYP"))) -> Flat Trading | BG7: =G7 -> XS2392969395 | BH7: 44473
A8: SYB | B8: AKCT | C8: 4371510 | D8: SocGen | E8: =_xll.BDP(AI8,"ds520") -> Credito Real SAB de CV SOFOM ER | F8: =_xll.BDP(AI8,"crncy") -> USD | G8: USP32506AE09 | H8: =IF(_xll.BDP(AI8,"RTG_MOODY")="#N/A N/A","N/A",_xll.BDP(AI8,"RTG_MOODY"))&","&IF(_xll.BDP(AI8,"RTG_FITCH")="#N/A N/A","N/A",_xll.BDP(AI8,"RTG_FITCH"))&","&IF(_xll.BDP(AI8,"RTG_SP")="#N/A N/A","N/A",_xll.BDP(AI8,"RTG_SP")) -> N/A,WD,NR | I8: 0 | J8: 0 | K8: =_xll.BDP(AI8,"PAYMENT_RANK") -> Sr Unsecured | L8: =IF((TEXT(_xll.BDP(AI8,"MATURITY"),"DD/MM/YYYY")="#N/A Field Not Applicable"),"Perp",TEXT(_xll.BDP(AI8,"MATURITY"),"DD/MM/YYYY")) -> 21/01/2028 | M8: =(IF(_xll.BDP($AI8&" ISIN","DU003")="#n/a n/a"," ",_xll.BDP($AI8&" ISIN","DU003"))) -> 2.1709126 | N8: =IF(_xll.BDP(AI8,"CALLABLE")="Y",_xll.BDP(AI8,"NXT_CALL_DT")," ") -> 29/05/2025 | O8: 200000 | P8: 100.0843 | Q8: =_xll.BDP(AI8,"px_bid") -> 12.525 | R8: =IF(F8="USD",AG8,(((_xll.BDP(F8&"USD CURNCY","PX_LAST")))*AG8)) -> 200168.6 | S8: =IF(F8="USD",AH8,(((_xll.BDP(F8&"USD CURNCY","PX_LAST")))*AH8))+AP8 -> 25050 | T8: =U8*R8 -> -175118.6 | U8: =(Q8-P8)/P8 -> -0.8748555 | V8: {=IFERROR(_xll.BDP($G8&" ISIN","CHG_PCT_1D")/100,"")} -> 0.002564729 | W8: {=IFERROR(_xll.BDP($G8&" ISIN","CHG_PCT_5D")/100,"")} -> -0.0021210806 | X8: {=_xll.BDP($G8&" ISIN","CHG_PCT_1M")/100} -> -0.014073419 | Y8: {=_xll.BDP($G8&" ISIN","CHG_PCT_3M")/100} -> 0.16786414 | Z8: {=_xll.BDP($G8&" ISIN","CHG_PCT_6M")/100} -> 0.21044536 | AA8: {=_xll.BDP($G8&" ISIN","CHG_PCT_YTD")/100} -> 0.17034088 | AB8: =S8/$H$37 -> #VALUE! | AC8: =((AF8*I8)* ((TODAY()-BH8)/360))+(Q8-P8)%*AF8 -> -175118.6 | AD8: =_xll.BDP(AI8,"DS199") -> Financial | AE8: =_xll.BDP(AI8,"px_ask") -> 12.673 | AF8: =IF(F8="USD",O8,(((_xll.BDP(F8&"USD CURNCY","PX_LAST")))*O8)) -> 200000 | AG8: =O8*P8/100 -> 200168.6 | AH8: =Q8*O8/100 -> 25050 | AI8: =G8& " ISIN" -> USP32506AE09 ISIN | AJ8: {=VLOOKUP(IF(NOT(_xll.BDP($G8&" CORP",#REF!)="#N/A N/A"),(_xll.BDP($G8&" CORP",#REF!)),"-"), '[1]Country Codes'!$A$2:$B$253,2,0)} -> #REF! | AK8: {=IF(OR(_xll.BDP($AI8,"EX028")= "#N/A N/A", _xll.BDP($AI8,"EX028")="#N/A FIELD NOT APPLICABLE"), " ", _xll.BDP($AI8,"EX028"))} -> FixedIncome | AL8: =(IF(_xll.BDP($AI8&" ISIN","DZ282")="Y","Single line Bonds Cocos","Single line Bonds ex Cocos")) -> Single line Bonds ex Cocos | AM8: =(IF(_xll.BDP($G8&" ISIN","SP153")="#n/a n/a"," ",_xll.BDP($G8&" ISIN","SP153"))) | AN8: =TODAY() -> 45777 | AO8: =(((_xll.BDP(AI8,"DS032"))/360)*I8)*O8 -> 0 | AP8: =IF(F8="USD",AO8,(((_xll.BDP(F8&"USD CURNCY","PX_LAST")))*AO8)) -> 0 | AQ8: =S8/$S$153 -> 0.56706282 | AR8: =S8-AP8 -> 25050 | AS8: =IF((TEXT(_xll.BDP(AI8,"MATURITY"),"DD/MM/YYYY")="#N/A Field Not Applicable"),"Perp",_xll.BDP(AI8,"DS252")) -> 2.7296372 | AT8: =(IF(_xll.BDP($AI8&" ISIN","DT247")="Y","Yes","No")) -> No | AU8: =PROPER(IF(OR(_xll.BDP($AI8,"CPN_TYP")="#n/a N/A",_xll.BDP($AI8,"CPN_TYP")= "#N/A FIELD NOT APPLICABLE"), " ", _xll.BDP($AI8,"CPN_TYP"))) -> Defaulted | BG8: =G8 -> USP32506AE09 | BH8: 44210
A9: SYB | B9: AKCT | C9: 4371510 | D9: SocGen | E9: =_xll.BDP(AI9,"ds520") -> Ghana Government International Bond | F9: =_xll.BDP(AI9,"crncy") -> USD | G9: XS2893147681 | H9: =IF(_xll.BDP(AI9,"RTG_MOODY")="#N/A N/A","N/A",_xll.BDP(AI9,"RTG_MOODY"))&","&IF(_xll.BDP(AI9,"RTG_FITCH")="#N/A N/A","N/A",_xll.BDP(AI9,"RTG_FITCH"))&","&IF(_xll.BDP(AI9,"RTG_SP")="#N/A N/A","N/A",_xll.BDP(AI9,"RTG_SP")) -> Caa2,CCC+,CCC+ | I9: =_xll.BDP(AI9,"cpn")/100 -> 0 | J9: =_xll.BDP($G9&" isin","YAS_BOND_YLD", "YAS_YLD_FLAG=15", "user_local_trade_date",AN9,"Yas_bond_px",$Q9)/100 -> 0.05943907 | K9: =_xll.BDP(AI9,"PAYMENT_RANK") -> Sr Unsecured | L9: =IF((TEXT(_xll.BDP(AI9,"MATURITY"),"DD/MM/YYYY")="#N/A Field Not Applicable"),"Perp",TEXT(_xll.BDP(AI9,"MATURITY"),"DD/MM/YYYY")) -> 03/01/2030 | M9: =(IF(_xll.BDP($AI9&" ISIN","DU003")="#n/a n/a"," ",_xll.BDP($AI9&" ISIN","DU003"))) -> 2.1833334 | N9: =IF(_xll.BDP(AI9,"CALLABLE")="Y",_xll.BDP(AI9,"NXT_CALL_DT")," ") | O9: 12043 | P9: 141.231 | Q9: =_xll.BDP(AI9,"px_bid") -> 76.071 | R9: =IF(F9="USD",AG9,(((_xll.BDP(F9&"USD CURNCY","PX_LAST")))*AG9)) -> 17008.449 | S9: =IF(F9="USD",AH9,(((_xll.BDP(F9&"USD CURNCY","PX_LAST")))*AH9))+AP9 -> 9161.2305 | T9: =U9*R9 -> -7847.2188 | U9: =(Q9-P9)/P9 -> -0.4613718 | V9: {=IFERROR(_xll.BDP($G9&" ISIN","CHG_PCT_1D")/100,"")} -> -0.0038616063 | W9: {=IFERROR(_xll.BDP($G9&" ISIN","CHG_PCT_5D")/100,"")} -> 0.04471262 | X9: {=_xll.BDP($G9&" ISIN","CHG_PCT_1M")/100} -> -0.010308479 | Y9: {=_xll.BDP($G9&" ISIN","CHG_PCT_3M")/100} -> -0.014851676 | Z9: {=_xll.BDP($G9&" ISIN","CHG_PCT_6M")/100} -> 0.009886112 | AA9: {=_xll.BDP($G9&" ISIN","CHG_PCT_YTD")/100} -> -0.010730196 | AB9: =S9/$H$37 -> #VALUE! | AC9: =((AF9*I9)* ((TODAY()-BH9)/360))+(Q9-P9)%*AF9 -> -7847.2188 | AD9: =_xll.BDP(AI9,"DS199") -> Government | AE9: =_xll.BDP(AI9,"px_ask") -> 77.149 | AF9: =IF(F9="USD",O9,(((_xll.BDP(F9&"USD CURNCY","PX_LAST")))*O9)) -> 12043 | AG9: =O9*P9/100 -> 17008.449 | AH9: =Q9*O9/100 -> 9161.2305 | AI9: =G9& " ISIN" -> XS2893147681 ISIN | AJ9: {=VLOOKUP(IF(NOT(_xll.BDP($G9&" CORP",#REF!)="#N/A N/A"),(_xll.BDP($G9&" CORP",#REF!)),"-"), '[1]Country Codes'!$A$2:$B$253,2,0)} -> #REF! | AK9: {=IF(OR(_xll.BDP($AI9,"EX028")= "#N/A N/A", _xll.BDP($AI9,"EX028")="#N/A FIELD NOT APPLICABLE"), " ", _xll.BDP($AI9,"EX028"))} -> FixedIncome | AL9: =(IF(_xll.BDP($AI9&" ISIN","DZ282")="Y","Single line Bonds Cocos","Single line Bonds ex Cocos")) -> Single line Bonds ex Cocos | AM9: =(IF(_xll.BDP($G9&" ISIN","SP153")="#n/a n/a"," ",_xll.BDP($G9&" ISIN","SP153"))) -> 838.83468 | AN9: =TODAY() -> 45777 | AO9: 0 | AP9: =IF(F9="USD",AO9,(((_xll.BDP(F9&"USD CURNCY","PX_LAST")))*AO9)) -> 0 | AQ9: =S9/$S$153 -> 0.20738496 | AR9: =S9-AP9 -> 9161.2305 | AS9: =IF((TEXT(_xll.BDP(AI9,"MATURITY"),"DD/MM/YYYY")="#N/A Field Not Applicable"),"Perp",_xll.BDP(AI9,"DS252")) -> 4.6817248 | AT9: =(IF(_xll.BDP($AI9&" ISIN","DT247")="Y","Yes","No")) -> No | AU9: =PROPER(IF(OR(_xll.BDP($AI9,"CPN_TYP")="#n/a N/A",_xll.BDP($AI9,"CPN_TYP")= "#N/A FIELD NOT APPLICABLE"), " ", _xll.BDP($AI9,"CPN_TYP"))) -> Zero Coupon | BG9: =G9 -> XS2893147681 | BH9: 44294
A10: SYB | B10: AKCT | C10: 4371510 | D10: SocGen | E10: =_xll.BDP(AI10,"ds520") -> Ghana Government International Bond | F10: =_xll.BDP(AI10,"crncy") -> USD | G10: XS2893146873 | H10: =IF(_xll.BDP(AI10,"RTG_MOODY")="#N/A N/A","N/A",_xll.BDP(AI10,"RTG_MOODY"))&","&IF(_xll.BDP(AI10,"RTG_FITCH")="#N/A N/A","N/A",_xll.BDP(AI10,"RTG_FITCH"))&","&IF(_xll.BDP(AI10,"RTG_SP")="#N/A N/A","N/A",_xll.BDP(AI10,"RTG_SP")) -> Caa2,CCC+,CCC+ | I10: =_xll.BDP(AI10,"cpn")/100 -> 0 | J10: =_xll.BDP($G10&" isin","YAS_BOND_YLD", "YAS_YLD_FLAG=15", "user_local_trade_date",AN10,"Yas_bond_px",$Q10)/100 -> 0.05033698 | K10: =_xll.BDP(AI10,"PAYMENT_RANK") -> Sr Unsecured | L10: =IF((TEXT(_xll.BDP(AI10,"MATURITY"),"DD/MM/YYYY")="#N/A Field Not Applicable"),"Perp",TEXT(_xll.BDP(AI10,"MATURITY"),"DD/MM/YYYY")) -> 03/07/2026 | M10: =(IF(_xll.BDP($AI10&" ISIN","DU003")="#n/a n/a"," ",_xll.BDP($AI10&" ISIN","DU003"))) -> 0.65833334 | N10: =IF(_xll.BDP(AI10,"CALLABLE")="Y",_xll.BDP(AI10,"NXT_CALL_DT")," ") | O10: 8000 | P10: 157.63 | Q10: =_xll.BDP(AI10,"px_bid") -> 94.352 | R10: =IF(F10="USD",AG10,(((_xll.BDP(F10&"USD CURNCY","PX_LAST")))*AG10)) -> 12610.4 | S10: =IF(F10="USD",AH10,(((_xll.BDP(F10&"USD CURNCY","PX_LAST")))*AH10))+AP10 -> 7548.16 | T10: =U10*R10 -> -5062.24 | U10: =(Q10-P10)/P10 -> -0.40143374 | V10: {=IFERROR(_xll.BDP($G10&" ISIN","CHG_PCT_1D")/100,"")} -> -0.0010528532 | W10: {=IFERROR(_xll.BDP($G10&" ISIN","CHG_PCT_5D")/100,"")} -> 0.0072935356 | X10: {=_xll.BDP($G10&" ISIN","CHG_PCT_1M")/100} -> 0.0080855088 | Y10: {=_xll.BDP($G10&" ISIN","CHG_PCT_3M")/100} -> 0.015150218 | Z10: {=_xll.BDP($G10&" ISIN","CHG_PCT_6M")/100} -> 0.022634188 | AA10: {=_xll.BDP($G10&" ISIN","CHG_PCT_YTD")/100} -> 0.021852215 | AB10: =S10/$H$37 -> #VALUE! | AC10: =((AF10*I10)* ((TODAY()-BH10)/360))+(Q10-P10)%*AF10 -> -5062.24 | AD10: =_xll.BDP(AI10,"DS199") -> Government | AE10: =_xll.BDP(AI10,"px_ask") -> 95.409 | AF10: =IF(F10="USD",O10,(((_xll.BDP(F10&"USD CURNCY","PX_LAST")))*O10)) -> 8000 | AG10: =O10*P10/100 -> 12610.4 | AH10: =Q10*O10/100 -> 7548.16 | AI10: =G10& " ISIN" -> XS2893146873 ISIN | AJ10: {=VLOOKUP(IF(NOT(_xll.BDP($G10&" CORP",#REF!)="#N/A N/A"),(_xll.BDP($G10&" CORP",#REF!)),"-"), '[1]Country Codes'!$A$2:$B$253,2,0)} -> #REF! | AK10: {=IF(OR(_xll.BDP($AI10,"EX028")= "#N/A N/A", _xll.BDP($AI10,"EX028")="#N/A FIELD NOT APPLICABLE"), " ", _xll.BDP($AI10,"EX028"))} -> FixedIncome | AL10: =(IF(_xll.BDP($AI10&" ISIN","DZ282")="Y","Single line Bonds Cocos","Single line Bonds ex Cocos")) -> Single line Bonds ex Cocos | AM10: =(IF(_xll.BDP($G10&" ISIN","SP153")="#n/a n/a"," ",_xll.BDP($G10&" ISIN","SP153"))) -> 415.38878 | AN10: =TODAY() -> 45777 | AO10: 0 | AP10: =IF(F10="USD",AO10,(((_xll.BDP(F10&"USD CURNCY","PX_LAST")))*AO10)) -> 0 | AQ10: =S10/$S$153 -> 0.1708695 | AR10: =S10-AP10 -> 7548.16 | AS10: =IF((TEXT(_xll.BDP(AI10,"MATURITY"),"DD/MM/YYYY")="#N/A Field Not Applicable"),"Perp",_xll.BDP(AI10,"DS252")) -> 1.1772758 | AT10: =(IF(_xll.BDP($AI10&" ISIN","DT247")="Y","Yes","No")) -> No | AU10: =PROPER(IF(OR(_xll.BDP($AI10,"CPN_TYP")="#n/a N/A",_xll.BDP($AI10,"CPN_TYP")= "#N/A FIELD NOT APPLICABLE"), " ", _xll.BDP($AI10,"CPN_TYP"))) -> Zero Coupon | BG10: =G10 -> XS2893146873 | BH10: 44294
A11: SYB | B11: AKCT | C11: 4371510 | D11: SocGen | E11: =_xll.BDP(AI11,"ds520") -> Ghana Government International Bond | F11: =_xll.BDP(AI11,"crncy") -> USD | G11: XS2893165584 | H11: =IF(_xll.BDP(AI11,"RTG_MOODY")="#N/A N/A","N/A",_xll.BDP(AI11,"RTG_MOODY"))&","&IF(_xll.BDP(AI11,"RTG_FITCH")="#N/A N/A","N/A",_xll.BDP(AI11,"RTG_FITCH"))&","&IF(_xll.BDP(AI11,"RTG_SP")="#N/A N/A","N/A",_xll.BDP(AI11,"RTG_SP")) -> Caa2,CCC+,CCC+ | I11: =_xll.BDP(AI11,"cpn")/100 -> 0.015 | J11: =_xll.BDP($G11&" isin","YAS_BOND_YLD", "YAS_YLD_FLAG=15", "user_local_trade_date",AN11,"Yas_bond_px",$Q11)/100 -> 0.10264295 | K11: =_xll.BDP(AI11,"PAYMENT_RANK") -> Sr Unsecured | L11: =IF((TEXT(_xll.BDP(AI11,"MATURITY"),"DD/MM/YYYY")="#N/A Field Not Applicable"),"Perp",TEXT(_xll.BDP(AI11,"MATURITY"),"DD/MM/YYYY")) -> 03/01/2037 | M11: =(IF(_xll.BDP($AI11&" ISIN","DU003")="#n/a n/a"," ",_xll.BDP($AI11&" ISIN","DU003"))) -> 9.5649667 | N11: =IF(_xll.BDP(AI11,"CALLABLE")="Y",_xll.BDP(AI11,"NXT_CALL_DT")," ") | O11: 192000 | P11: 86.296 | Q11: =_xll.BDP(AI11,"px_bid") -> 41.162 | R11: =IF(F11="USD",AG11,(((_xll.BDP(F11&"USD CURNCY","PX_LAST")))*AG11)) -> 165688.32 | S11: =IF(F11="USD",AH11,(((_xll.BDP(F11&"USD CURNCY","PX_LAST")))*AH11))+AP11 -> 79975.04 | T11: =U11*R11 -> -86657.28 | U11: =(Q11-P11)/P11 -> -0.52301381 | V11: {=IFERROR(_xll.BDP($G11&" ISIN","CHG_PCT_1D")/100,"")} -> 0.0080389356 | W11: {=IFERROR(_xll.BDP($G11&" ISIN","CHG_PCT_5D")/100,"")} -> 0.071196995 | X11: {=_xll.BDP($G11&" ISIN","CHG_PCT_1M")/100} -> -0.010176181 | Y11: {=_xll.BDP($G11&" ISIN","CHG_PCT_3M")/100} -> -0.002252846 | Z11: {=_xll.BDP($G11&" ISIN","CHG_PCT_6M")/100} -> -0.026243772 | AA11: {=_xll.BDP($G11&" ISIN","CHG_PCT_YTD")/100} -> 0.031977393 | AB11: =S11/$H$37 -> #VALUE! | AC11: =((AF11*I11)* ((TODAY()-BH11)/360))+(Q11-P11)%*AF11 -> -74793.28 | AD11: =_xll.BDP(AI11,"DS199") -> Government | AE11: =_xll.BDP(AI11,"px_ask") -> 42.541 | AF11: =IF(F11="USD",O11,(((_xll.BDP(F11&"USD CURNCY","PX_LAST")))*O11)) -> 192000 | AG11: =O11*P11/100 -> 165688.32 | AH11: =Q11*O11/100 -> 79031.04 | AI11: =G11& " ISIN" -> XS2893165584 ISIN | AJ11: {=VLOOKUP(IF(NOT(_xll.BDP($G11&" CORP",#REF!)="#N/A N/A"),(_xll.BDP($G11&" CORP",#REF!)),"-"), '[1]Country Codes'!$A$2:$B$253,2,0)} -> #REF! | AK11: {=IF(OR(_xll.BDP($AI11,"EX028")= "#N/A N/A", _xll.BDP($AI11,"EX028")="#N/A FIELD NOT APPLICABLE"), " ", _xll.BDP($AI11,"EX028"))} -> FixedIncome | AL11: =(IF(_xll.BDP($AI11&" ISIN","DZ282")="Y","Single line Bonds Cocos","Single line Bonds ex Cocos")) -> Single line Bonds ex Cocos | AM11: =(IF(_xll.BDP($G11&" ISIN","SP153")="#n/a n/a"," ",_xll.BDP($G11&" ISIN","SP153"))) -> 663.04958 | AN11: =TODAY() -> 45777 | AO11: =(((_xll.BDP(AI11,"DS032"))/360)*I11)*O11 -> 944 | AP11: =IF(F11="USD",AO11,(((_xll.BDP(F11&"USD CURNCY","PX_LAST")))*AO11)) -> 944 | AQ11: =S11/$S$153 -> 1.810414 | AR11: =S11-AP11 -> 79031.04 | AS11: =IF((TEXT(_xll.BDP(AI11,"MATURITY"),"DD/MM/YYYY")="#N/A Field Not Applicable"),"Perp",_xll.BDP(AI11,"DS252")) -> 11.682409 | AT11: =(IF(_xll.BDP($AI11&" ISIN","DT247")="Y","Yes","No")) -> No | AU11: =PROPER(IF(OR(_xll.BDP($AI11,"CPN_TYP")="#n/a N/A",_xll.BDP($AI11,"CPN_TYP")= "#N/A FIELD NOT APPLICABLE"), " ", _xll.BDP($AI11,"CPN_TYP"))) -> Fixed | BG11: =G11 -> XS2893165584 | BH11: 44294
A12: SYB | B12: AKCT | C12: 4371510 | D12: SocGen | E12: =_xll.BDP(AI12,"ds520") -> Lukoil Capital DAC | F12: =_xll.BDP(AI12,"crncy") -> USD | G12: XS2401571448 | H12: =IF(_xll.BDP(AI12,"RTG_MOODY")="#N/A N/A","N/A",_xll.BDP(AI12,"RTG_MOODY"))&","&IF(_xll.BDP(AI12,"RTG_FITCH")="#N/A N/A","N/A",_xll.BDP(AI12,"RTG_FITCH"))&","&IF(_xll.BDP(AI12,"RTG_SP")="#N/A N/A","N/A",_xll.BDP(AI12,"RTG_SP")) -> WR,WD,N/A | I12: =_xll.BDP(AI12,"cpn")/100 -> 0.028 | J12: =_xll.BDP($G12&" isin","YAS_BOND_YLD", "YAS_YLD_FLAG=15", "user_local_trade_date",AN12,"Yas_bond_px",$Q12)/100 -> 0.15204747 | K12: =_xll.BDP(AI12,"PAYMENT_RANK") -> Sr Unsecured | L12: =IF((TEXT(_xll.BDP(AI12,"MATURITY"),"DD/MM/YYYY")="#N/A Field Not Applicable"),"Perp",TEXT(_xll.BDP(AI12,"MATURITY"),"DD/MM/YYYY")) -> 26/04/2027 | M12: =(IF(_xll.BDP($AI12&" ISIN","DU003")="#n/a n/a"," ",_xll.BDP($AI12&" ISIN","DU003"))) -> 1.9395357 | N12: =IF(_xll.BDP(AI12,"CALLABLE")="Y",_xll.BDP(AI12,"NXT_CALL_DT")," ") -> 26/01/2027 | O12: 300000 | P12: 100 | Q12: =_xll.BDP(AI12,"px_bid") -> 79.421 | R12: =IF(F12="USD",AG12,(((_xll.BDP(F12&"USD CURNCY","PX_LAST")))*AG12)) -> 300000 | S12: =IF(F12="USD",AH12,(((_xll.BDP(F12&"USD CURNCY","PX_LAST")))*AH12))+AP12 -> 238379.67 | T12: =U12*R12 -> -61737 | U12: =(Q12-P12)/P12 -> -0.20579 | V12: {=IFERROR(_xll.BDP($G12&" ISIN","CHG_PCT_1D")/100,"")} -> 0.00037410972 | W12: {=IFERROR(_xll.BDP($G12&" ISIN","CHG_PCT_5D")/100,"")} -> 6.8439545e-05 | X12: {=_xll.BDP($G12&" ISIN","CHG_PCT_1M")/100} -> -2.9062236e-05 | Y12: {=_xll.BDP($G12&" ISIN","CHG_PCT_3M")/100} -> 0.053060768 | Z12: {=_xll.BDP($G12&" ISIN","CHG_PCT_6M")/100} -> 0.046652253 | AA12: {=_xll.BDP($G12&" ISIN","CHG_PCT_YTD")/100} -> 0.052084195 | AB12: =S12/$H$37 -> #VALUE! | AC12: =((AF12*I12)* ((TODAY()-BH12)/360))+(Q12-P12)%*AF12 -> -31823.667 | AD12: =_xll.BDP(AI12,"DS199") -> Energy | AE12: =_xll.BDP(AI12,"px_ask") -> 81.608 | AF12: =IF(F12="USD",O12,(((_xll.BDP(F12&"USD CURNCY","PX_LAST")))*O12)) -> 300000 | AG12: =O12*P12/100 -> 300000 | AH12: =Q12*O12/100 -> 238263 | AI12: =G12& " ISIN" -> XS2401571448 ISIN | AJ12: {=VLOOKUP(IF(NOT(_xll.BDP($G12&" CORP",#REF!)="#N/A N/A"),(_xll.BDP($G12&" CORP",#REF!)),"-"), '[1]Country Codes'!$A$2:$B$253,2,0)} -> #REF! | AK12: {=IF(OR(_xll.BDP($AI12,"EX028")= "#N/A N/A", _xll.BDP($AI12,"EX028")="#N/A FIELD NOT APPLICABLE"), " ", _xll.BDP($AI12,"EX028"))} -> FixedIncome | AL12: =(IF(_xll.BDP($AI12&" ISIN","DZ282")="Y","Single line Bonds Cocos","Single line Bonds ex Cocos")) -> Single line Bonds ex Cocos | AM12: =(IF(_xll.BDP($G12&" ISIN","SP153")="#n/a n/a"," ",_xll.BDP($G12&" ISIN","SP153"))) -> 1093.278 | AN12: =TODAY() -> 45777 | AO12: =(((_xll.BDP(AI12,"DS032"))/360)*I12)*O12 -> 116.66667 | AP12: =IF(F12="USD",AO12,(((_xll.BDP(F12&"USD CURNCY","PX_LAST")))*AO12)) -> 116.66667 | AQ12: =S12/$S$153 -> 5.3962573 | AR12: =S12-AP12 -> 238263 | AS12: =IF((TEXT(_xll.BDP(AI12,"MATURITY"),"DD/MM/YYYY")="#N/A Field Not Applicable"),"Perp",_xll.BDP(AI12,"DS252")) -> 1.9904175 | AT12: =(IF(_xll.BDP($AI12&" ISIN","DT247")="Y","Yes","No")) -> No | AU12: =PROPER(IF(OR(_xll.BDP($AI12,"CPN_TYP")="#n/a N/A",_xll.BDP($AI12,"CPN_TYP")= "#N/A FIELD NOT APPLICABLE"), " ", _xll.BDP($AI12,"CPN_TYP"))) -> Fixed | BG12: =G12 -> XS2401571448 | BH12: 44495
A13: SYB | B13: AKCT | C13: 4371510 | D13: SocGen | E13: =_xll.BDP(AI13,"ds520") -> Mashreqbank PSC | F13: =_xll.BDP(AI13,"crncy") -> USD | G13: XS2827680112 | H13: =IF(_xll.BDP(AI13,"RTG_MOODY")="#N/A N/A","N/A",_xll.BDP(AI13,"RTG_MOODY"))&","&IF(_xll.BDP(AI13,"RTG_FITCH")="#N/A N/A","N/A",_xll.BDP(AI13,"RTG_FITCH"))&","&IF(_xll.BDP(AI13,"RTG_SP")="#N/A N/A","N/A",_xll.BDP(AI13,"RTG_SP")) -> N/A,N/A,N/A | I13: =_xll.BDP(AI13,"cpn")/100 -> 0.07125 | J13: =_xll.BDP($G13&" isin","YAS_BOND_YLD", "YAS_YLD_FLAG=15", "user_local_trade_date",AN13,"Yas_bond_px",$Q13)/100 -> 0.06563178 | K13: =_xll.BDP(AI13,"PAYMENT_RANK") -> Jr Subordinated | L13: =IF((TEXT(_xll.BDP(AI13,"MATURITY"),"DD/MM/YYYY")="#N/A Field Not Applicable"),"Perp",TEXT(_xll.BDP(AI13,"MATURITY"),"DD/MM/YYYY")) -> Perp | M13: =(IF(_xll.BDP($AI13&" ISIN","DU003")="#n/a n/a"," ",_xll.BDP($AI13&" ISIN","DU003"))) -> 3.9115883 | N13: =IF(_xll.BDP(AI13,"CALLABLE")="Y",_xll.BDP(AI13,"NXT_CALL_DT")," ") -> 10/06/2029 | O13: 1000000 | P13: 100.3 | Q13: =_xll.BDP(AI13,"px_bid") -> 101.984 | R13: =IF(F13="USD",AG13,(((_xll.BDP(F13&"USD CURNCY","PX_LAST")))*AG13)) -> 1003000 | S13: =IF(F13="USD",AH13,(((_xll.BDP(F13&"USD CURNCY","PX_LAST")))*AH13))+AP13 -> 1047364 | T13: =U13*R13 -> 16840 | U13: =(Q13-P13)/P13 -> 0.016789631 | V13: {=IFERROR(_xll.BDP($G13&" ISIN","CHG_PCT_1D")/100,"")} -> -0.00040055492 | W13: {=IFERROR(_xll.BDP($G13&" ISIN","CHG_PCT_5D")/100,"")} -> 0.00059654201 | X13: {=_xll.BDP($G13&" ISIN","CHG_PCT_1M")/100} -> -0.0078255304 | Y13: {=_xll.BDP($G13&" ISIN","CHG_PCT_3M")/100} -> 0.0017427232 | Z13: {=_xll.BDP($G13&" ISIN","CHG_PCT_6M")/100} -> -0.015889352 | AA13: {=_xll.BDP($G13&" ISIN","CHG_PCT_YTD")/100} -> -0.0040202473 | AB13: =S13/$H$37 -> #VALUE! | AC13: =((AF13*I13)* ((TODAY()-BH13)/360))+(Q13-P13)%*AF13 -> 80965 | AD13: =_xll.BDP(AI13,"DS199") -> Financial | AE13: =_xll.BDP(AI13,"px_ask") -> 102.699 | AF13: =IF(F13="USD",O13,(((_xll.BDP(F13&"USD CURNCY","PX_LAST")))*O13)) -> 1000000 | AG13: =O13*P13/100 -> 1003000 | AH13: =Q13*O13/100 -> 1019840 | AI13: =G13& " ISIN" -> XS2827680112 ISIN | AJ13: {=VLOOKUP(IF(NOT(_xll.BDP($G13&" CORP",#REF!)="#N/A N/A"),(_xll.BDP($G13&" CORP",#REF!)),"-"), '[1]Country Codes'!$A$2:$B$253,2,0)} -> #REF! | AK13: {=IF(OR(_xll.BDP($AI13,"EX028")= "#N/A N/A", _xll.BDP($AI13,"EX028")="#N/A FIELD NOT APPLICABLE"), " ", _xll.BDP($AI13,"EX028"))} -> FixedIncome | AL13: =(IF(_xll.BDP($AI13&" ISIN","DZ282")="Y","Single line Bonds Cocos","Single line Bonds ex Cocos")) -> Single line Bonds ex Cocos | AM13: =(IF(_xll.BDP($G13&" ISIN","SP153")="#n/a n/a"," ",_xll.BDP($G13&" ISIN","SP153"))) -> 304.23923 | AN13: =TODAY() -> 45777 | AO13: =(((_xll.BDP(AI13,"DS032"))/365)*I13)*O13 -> 27523.973 | AP13: =IF(F13="USD",AO13,(((_xll.BDP(F13&"USD CURNCY","PX_LAST")))*AO13)) -> 27523.973 | AQ13: =S13/#REF! -> #REF! | AR13: =S13-AP13 -> 1019840 | AS13: =IF((TEXT(_xll.BDP(AI13,"MATURITY"),"DD/MM/YYYY")="#N/A Field Not Applicable"),"Perp",_xll.BDP(AI13,"DS252")) -> Perp | AT13: =(IF(_xll.BDP($AI13&" ISIN","DT247")="Y","Yes","No")) -> Yes | AU13: =PROPER(IF(OR(_xll.BDP($AI13,"CPN_TYP")="#n/a N/A",_xll.BDP($AI13,"CPN_TYP")= "#N/A FIELD NOT APPLICABLE"), " ", _xll.BDP($AI13,"CPN_TYP"))) -> Variable | BG13: =G13 -> XS2827680112 | BH13: 45453
A14: SYB | B14: AKCT | C14: 4371510 | D14: SocGen | E14: =_xll.BDP(AI14,"ds520") -> Mazoon Assets Co SAOC | F14: =_xll.BDP(AI14,"crncy") -> USD | G14: XS2907977131 | H14: =IF(_xll.BDP(AI14,"RTG_MOODY")="#N/A N/A","N/A",_xll.BDP(AI14,"RTG_MOODY"))&","&IF(_xll.BDP(AI14,"RTG_FITCH")="#N/A N/A","N/A",_xll.BDP(AI14,"RTG_FITCH"))&","&IF(_xll.BDP(AI14,"RTG_SP")="#N/A N/A","N/A",_xll.BDP(AI14,"RTG_SP")) -> Ba1,BB+,N/A | I14: =_xll.BDP(AI14,"cpn")/100 -> 0.0525 | J14: =_xll.BDP($G14&" isin","YAS_BOND_YLD", "YAS_YLD_FLAG=15", "user_local_trade_date",AN14,"Yas_bond_px",$Q14)/100 -> 0.05639848 | K14: =_xll.BDP(AI14,"PAYMENT_RANK") -> Sr Unsecured | L14: =IF((TEXT(_xll.BDP(AI14,"MATURITY"),"DD/MM/YYYY")="#N/A Field Not Applicable"),"Perp",TEXT(_xll.BDP(AI14,"MATURITY"),"DD/MM/YYYY")) -> 09/10/2031 | M14: =(IF(_xll.BDP($AI14&" ISIN","DU003")="#n/a n/a"," ",_xll.BDP($AI14&" ISIN","DU003"))) -> 5.5211923 | N14: =IF(_xll.BDP(AI14,"CALLABLE")="Y",_xll.BDP(AI14,"NXT_CALL_DT")," ") | O14: 500000 | P14: 100.095 | Q14: =_xll.BDP(AI14,"px_bid") -> 97.916 | R14: =IF(F14="USD",AG14,(((_xll.BDP(F14&"USD CURNCY","PX_LAST")))*AG14)) -> 500475 | S14: =IF(F14="USD",AH14,(((_xll.BDP(F14&"USD CURNCY","PX_LAST")))*AH14))+AP14 -> 491234.11 | T14: =U14*R14 -> -10895 | U14: =(Q14-P14)/P14 -> -0.021769319 | V14: {=IFERROR(_xll.BDP($G14&" ISIN","CHG_PCT_1D")/100,"")} -> -0.0013407654 | W14: {=IFERROR(_xll.BDP($G14&" ISIN","CHG_PCT_5D")/100,"")} -> 0.0020032822 | X14: {=_xll.BDP($G14&" ISIN","CHG_PCT_1M")/100} -> -0.00079096942 | Y14: {=_xll.BDP($G14&" ISIN","CHG_PCT_3M")/100} -> 0.016169757 | Z14: {=_xll.BDP($G14&" ISIN","CHG_PCT_6M")/100} -> -0.0067873642 | AA14: {=_xll.BDP($G14&" ISIN","CHG_PCT_YTD")/100} -> 0.0044454455 | AB14: =S14/$H$37 -> #VALUE! | AC14: =((AF14*I14)* ((TODAY()-BH14)/360))+(Q14-P14)%*AF14 -> 3907.0833 | AD14: =_xll.BDP(AI14,"DS199") -> Utilities | AE14: =_xll.BDP(AI14,"px_ask") -> 100.208 | AF14: =IF(F14="USD",O14,(((_xll.BDP(F14&"USD CURNCY","PX_LAST")))*O14)) -> 500000 | AG14: =O14*P14/100 -> 500475 | AH14: =Q14*O14/100 -> 489580 | AI14: =G14& " ISIN" -> XS2907977131 ISIN | AJ14: {=VLOOKUP(IF(NOT(_xll.BDP($G14&" CORP",#REF!)="#N/A N/A"),(_xll.BDP($G14&" CORP",#REF!)),"-"), '[1]Country Codes'!$A$2:$B$253,2,0)} -> #REF! | AK14: {=IF(OR(_xll.BDP($AI14,"EX028")= "#N/A N/A", _xll.BDP($AI14,"EX028")="#N/A FIELD NOT APPLICABLE"), " ", _xll.BDP($AI14,"EX028"))} -> FixedIncome | AL14: =(IF(_xll.BDP($AI14&" ISIN","DZ282")="Y","Single line Bonds Cocos","Single line Bonds ex Cocos")) -> Single line Bonds ex Cocos | AM14: =(IF(_xll.BDP($G14&" ISIN","SP153")="#n/a n/a"," ",_xll.BDP($G14&" ISIN","SP153"))) -> 191.65638 | AN14: =TODAY() -> 45777 | AO14: =(((_xll.BDP(AI14,"DS032"))/365)*I14)*O14 -> 1654.1096 | AP14: =IF(F14="USD",AO14,(((_xll.BDP(F14&"USD CURNCY","PX_LAST")))*AO14)) -> 1654.1096 | AQ14: =S14/#REF! -> #REF! | AR14: =S14-AP14 -> 489580 | AS14: =IF((TEXT(_xll.BDP(AI14,"MATURITY"),"DD/MM/YYYY")="#N/A Field Not Applicable"),"Perp",_xll.BDP(AI14,"DS252")) -> 6.4421629 | AT14: =(IF(_xll.BDP($AI14&" ISIN","DT247")="Y","Yes","No")) -> No | AU14: =PROPER(IF(OR(_xll.BDP($AI14,"CPN_TYP")="#n/a N/A",_xll.BDP($AI14,"CPN_TYP")= "#N/A FIELD NOT APPLICABLE"), " ", _xll.BDP($AI14,"CPN_TYP"))) -> Fixed | BG14: =G14 -> XS2907977131 | BH14: 45574
A15: SYB | B15: AKCT | C15: 4371510 | D15: SocGen | E15: =_xll.BDP(AI15,"ds520") -> National Bank of Ras Al-Khaimah PSC/The | F15: =_xll.BDP(AI15,"crncy") -> USD | G15: XS2630917107 | H15: =IF(_xll.BDP(AI15,"RTG_MOODY")="#N/A N/A","N/A",_xll.BDP(AI15,"RTG_MOODY"))&","&IF(_xll.BDP(AI15,"RTG_FITCH")="#N/A N/A","N/A",_xll.BDP(AI15,"RTG_FITCH"))&","&IF(_xll.BDP(AI15,"RTG_SP")="#N/A N/A","N/A",_xll.BDP(AI15,"RTG_SP")) -> N/A,BBB-,N/A | I15: =_xll.BDP(AI15,"cpn")/100 -> 0.058732 | J15: =_xll.BDP($G15&" isin","YAS_BOND_YLD", "YAS_YLD_FLAG=15", "user_local_trade_date",AN15,"Yas_bond_px",$Q15)/100 -> 0.05785198 | K15: =_xll.BDP(AI15,"PAYMENT_RANK") -> Subordinated | L15: =IF((TEXT(_xll.BDP(AI15,"MATURITY"),"DD/MM/YYYY")="#N/A Field Not Applicable"),"Perp",TEXT(_xll.BDP(AI15,"MATURITY"),"DD/MM/YYYY")) -> 10/12/2034 | M15: =(IF(_xll.BDP($AI15&" ISIN","DU003")="#n/a n/a"," ",_xll.BDP($AI15&" ISIN","DU003"))) -> 4.0726441 | N15: =IF(_xll.BDP(AI15,"CALLABLE")="Y",_xll.BDP(AI15,"NXT_CALL_DT")," ") -> 10/09/2029 | O15: 1800000 | P15: 100.3 | Q15: =_xll.BDP(AI15,"px_bid") -> 100.326 | R15: =IF(F15="USD",AG15,(((_xll.BDP(F15&"USD CURNCY","PX_LAST")))*AG15)) -> 1805400 | S15: =IF(F15="USD",AH15,(((_xll.BDP(F15&"USD CURNCY","PX_LAST")))*AH15))+AP15 -> 1820844.7 | T15: =U15*R15 -> 468 | U15: =(Q15-P15)/P15 -> 0.00025922233 | V15: {=IFERROR(_xll.BDP($G15&" ISIN","CHG_PCT_1D")/100,"")} -> -0.0009352568 | W15: {=IFERROR(_xll.BDP($G15&" ISIN","CHG_PCT_5D")/100,"")} -> 0.0018598168 | X15: {=_xll.BDP($G15&" ISIN","CHG_PCT_1M")/100} -> -0.00086085778 | Y15: {=_xll.BDP($G15&" ISIN","CHG_PCT_3M")/100} -> #VALUE! | Z15: {=_xll.BDP($G15&" ISIN","CHG_PCT_6M")/100} -> #VALUE! | AA15: {=_xll.BDP($G15&" ISIN","CHG_PCT_YTD")/100} -> #VALUE! | AB15: =S15/$H$37 -> #VALUE! | AC15: =((AF15*I15)* ((TODAY()-BH15)/360))+(Q15-P15)%*AF15 -> 68597.12 | AD15: =_xll.BDP(AI15,"DS199") -> Financial | AE15: =_xll.BDP(AI15,"px_ask") -> 101.104 | AF15: =IF(F15="USD",O15,(((_xll.BDP(F15&"USD CURNCY","PX_LAST")))*O15)) -> 1800000 | AG15: =O15*P15/100 -> 1805400 | AH15: =Q15*O15/100 -> 1805868 | AI15: =G15& " ISIN" -> XS2630917107 ISIN | AJ15: {=VLOOKUP(IF(NOT(_xll.BDP($G15&" CORP",#REF!)="#N/A N/A"),(_xll.BDP($G15&" CORP",#REF!)),"-"), '[1]Country Codes'!$A$2:$B$253,2,0)} -> #REF! | AK15: {=IF(OR(_xll.BDP($AI15,"EX028")= "#N/A N/A", _xll.BDP($AI15,"EX028")="#N/A FIELD NOT APPLICABLE"), " ", _xll.BDP($AI15,"EX028"))} -> FixedIncome | AL15: =(IF(_xll.BDP($AI15&" ISIN","DZ282")="Y","Single line Bonds Cocos","Single line Bonds ex Cocos")) -> Single line Bonds ex Cocos | AM15: =(IF(_xll.BDP($G15&" ISIN","SP153")="#n/a n/a"," ",_xll.BDP($G15&" ISIN","SP153"))) -> 221.18282 | AN15: =TODAY() -> 45777 | AO15: =(((_xll.BDP(AI15,"DS032"))/360)*I15)*O15 -> 14976.66 | AP15: =IF(F15="USD",AO15,(((_xll.BDP(F15&"USD CURNCY","PX_LAST")))*AO15)) -> 14976.66 | AQ15: =S15/$S$159 -> 2.0019852 | AR15: =S15-AP15 -> 1805868 | AS15: =IF((TEXT(_xll.BDP(AI15,"MATURITY"),"DD/MM/YYYY")="#N/A Field Not Applicable"),"Perp",_xll.BDP(AI15,"DS252")) -> 9.615332 | AT15: =(IF(_xll.BDP($AI15&" ISIN","DT247")="Y","Yes","No")) -> Yes | AU15: =PROPER(IF(OR(_xll.BDP($AI15,"CPN_TYP")="#n/a N/A",_xll.BDP($AI15,"CPN_TYP")= "#N/A FIELD NOT APPLICABLE"), " ", _xll.BDP($AI15,"CPN_TYP"))) -> Variable | BG15: =G15 -> XS2630917107 | BH15: 45545
A16: SYB | B16: AKCT | C16: 4371510 | D16: SocGen | E16: =_xll.BDP(AI16,"ds520") -> National Bank of Uzbekistan | F16: =_xll.BDP(AI16,"crncy") -> USD | G16: XS2853544398 | H16: =IF(_xll.BDP(AI16,"RTG_MOODY")="#N/A N/A","N/A",_xll.BDP(AI16,"RTG_MOODY"))&","&IF(_xll.BDP(AI16,"RTG_FITCH")="#N/A N/A","N/A",_xll.BDP(AI16,"RTG_FITCH"))&","&IF(_xll.BDP(AI16,"RTG_SP")="#N/A N/A","N/A",_xll.BDP(AI16,"RTG_SP")) -> N/A,BB-,BB- | I16: =_xll.BDP(AI16,"cpn")/100 -> 0.085 | J16: =_xll.BDP($G16&" isin","YAS_BOND_YLD", "YAS_YLD_FLAG=15", "user_local_trade_date",AN16,"Yas_bond_px",$Q16)/100 -> 0.08011522 | K16: =_xll.BDP(AI16,"PAYMENT_RANK") -> Sr Unsecured | L16: =IF((TEXT(_xll.BDP(AI16,"MATURITY"),"DD/MM/YYYY")="#N/A Field Not Applicable"),"Perp",TEXT(_xll.BDP(AI16,"MATURITY"),"DD/MM/YYYY")) -> 05/07/2029 | M16: =(IF(_xll.BDP($AI16&" ISIN","DU003")="#n/a n/a"," ",_xll.BDP($AI16&" ISIN","DU003"))) -> 3.3383233 | N16: =IF(_xll.BDP(AI16,"CALLABLE")="Y",_xll.BDP(AI16,"NXT_CALL_DT")," ") -> 05/04/2029 | O16: 500000 | P16: 99.875 | Q16: =_xll.BDP(AI16,"px_bid") -> 101.614 | R16: =IF(F16="USD",AG16,(((_xll.BDP(F16&"USD CURNCY","PX_LAST")))*AG16)) -> 499375 | S16: =IF(F16="USD",AH16,(((_xll.BDP(F16&"USD CURNCY","PX_LAST")))*AH16))+AP16 -> 521764.44 | T16: =U16*R16 -> 8695 | U16: =(Q16-P16)/P16 -> 0.017411765 | V16: {=IFERROR(_xll.BDP($G16&" ISIN","CHG_PCT_1D")/100,"")} -> -0.0032891526 | W16: {=IFERROR(_xll.BDP($G16&" ISIN","CHG_PCT_5D")/100,"")} -> 0.015634168 | X16: {=_xll.BDP($G16&" ISIN","CHG_PCT_1M")/100} -> -0.015160136 | Y16: {=_xll.BDP($G16&" ISIN","CHG_PCT_3M")/100} -> -0.0022959084 | Z16: {=_xll.BDP($G16&" ISIN","CHG_PCT_6M")/100} -> -0.0077729521 | AA16: {=_xll.BDP($G16&" ISIN","CHG_PCT_YTD")/100} -> -0.001417871 | AB16: =S16/$H$37 -> #VALUE! | AC16: =((AF16*I16)* ((TODAY()-BH16)/360))+(Q16-P16)%*AF16 -> 43993.611 | AD16: =_xll.BDP(AI16,"DS199") -> Financial | AE16: =_xll.BDP(AI16,"px_ask") -> 102.627 | AF16: =IF(F16="USD",O16,(((_xll.BDP(F16&"USD CURNCY","PX_LAST")))*O16)) -> 500000 | AG16: =O16*P16/100 -> 499375 | AH16: =Q16*O16/100 -> 508070 | AI16: =G16& " ISIN" -> XS2853544398 ISIN | AJ16: {=VLOOKUP(IF(NOT(_xll.BDP($G16&" CORP",#REF!)="#N/A N/A"),(_xll.BDP($G16&" CORP",#REF!)),"-"), '[1]Country Codes'!$A$2:$B$253,2,0)} -> #REF! | AK16: {=IF(OR(_xll.BDP($AI16,"EX028")= "#N/A N/A", _xll.BDP($AI16,"EX028")="#N/A FIELD NOT APPLICABLE"), " ", _xll.BDP($AI16,"EX028"))} -> FixedIncome | AL16: =(IF(_xll.BDP($AI16&" ISIN","DZ282")="Y","Single line Bonds Cocos","Single line Bonds ex Cocos")) -> Single line Bonds ex Cocos | AM16: =(IF(_xll.BDP($G16&" ISIN","SP153")="#n/a n/a"," ",_xll.BDP($G16&" ISIN","SP153"))) -> 440.83352 | AN16: =TODAY() -> 45777 | AO16: =(((_xll.BDP(AI16,"DS032"))/360)*I16)*O16 -> 13694.444 | AP16: =IF(F16="USD",AO16,(((_xll.BDP(F16&"USD CURNCY","PX_LAST")))*AO16)) -> 13694.444 | AQ16: =S16/$S$159 -> 0.5736704 | AR16: =S16-AP16 -> 508070 | AS16: =IF((TEXT(_xll.BDP(AI16,"MATURITY"),"DD/MM/YYYY")="#N/A Field Not Applicable"),"Perp",_xll.BDP(AI16,"DS252")) -> 4.183436 | AT16: =(IF(_xll.BDP($AI16&" ISIN","DT247")="Y","Yes","No")) -> No | AU16: =PROPER(IF(OR(_xll.BDP($AI16,"CPN_TYP")="#n/a N/A",_xll.BDP($AI16,"CPN_TYP")= "#N/A FIELD NOT APPLICABLE"), " ", _xll.BDP($AI16,"CPN_TYP"))) -> Fixed | BG16: =G16 -> XS2853544398 | BH16: 45478
A17: SYB | B17: AKCT | C17: 4371510 | D17: SocGen | E17: =_xll.BDP(AI17,"ds520") -> Nigeria Government International Bond | F17: =_xll.BDP(AI17,"crncy") -> USD | G17: XS2384698994 | H17: =IF(_xll.BDP(AI17,"RTG_MOODY")="#N/A N/A","N/A",_xll.BDP(AI17,"RTG_MOODY"))&","&IF(_xll.BDP(AI17,"RTG_FITCH")="#N/A N/A","N/A",_xll.BDP(AI17,"RTG_FITCH"))&","&IF(_xll.BDP(AI17,"RTG_SP")="#N/A N/A","N/A",_xll.BDP(AI17,"RTG_SP")) -> Caa1,B,B- | I17: =_xll.BDP(AI17,"cpn")/100 -> 0.06125 | J17: =_xll.BDP($G17&" isin","YAS_BOND_YLD", "YAS_YLD_FLAG=15", "user_local_trade_date",AN17,"Yas_bond_px",$Q17)/100 -> 0.09477491 | K17: =_xll.BDP(AI17,"PAYMENT_RANK") -> Sr Unsecured | L17: =IF((TEXT(_xll.BDP(AI17,"MATURITY"),"DD/MM/YYYY")="#N/A Field Not Applicable"),"Perp",TEXT(_xll.BDP(AI17,"MATURITY"),"DD/MM/YYYY")) -> 28/09/2028 | M17: =(IF(_xll.BDP($AI17&" ISIN","DU003")="#n/a n/a"," ",_xll.BDP($AI17&" ISIN","DU003"))) -> 3.0934804 | N17: =IF(_xll.BDP(AI17,"CALLABLE")="Y",_xll.BDP(AI17,"NXT_CALL_DT")," ") | O17: 500000 | P17: 100.03 | Q17: =_xll.BDP(AI17,"px_bid") -> 90.422 | R17: =IF(F17="USD",AG17,(((_xll.BDP(F17&"USD CURNCY","PX_LAST")))*AG17)) -> 500150 | S17: =IF(F17="USD",AH17,(((_xll.BDP(F17&"USD CURNCY","PX_LAST")))*AH17))+AP17 -> 454917.29 | T17: =U17*R17 -> -48040 | U17: =(Q17-P17)/P17 -> -0.096051185 | V17: {=IFERROR(_xll.BDP($G17&" ISIN","CHG_PCT_1D")/100,"")} -> -0.002765766 | W17: {=IFERROR(_xll.BDP($G17&" ISIN","CHG_PCT_5D")/100,"")} -> 0.021334472 | X17: {=_xll.BDP($G17&" ISIN","CHG_PCT_1M")/100} -> -0.0069943826 | Y17: {=_xll.BDP($G17&" ISIN","CHG_PCT_3M")/100} -> -0.011133482 | Z17: {=_xll.BDP($G17&" ISIN","CHG_PCT_6M")/100} -> 0.0011900302 | AA17: {=_xll.BDP($G17&" ISIN","CHG_PCT_YTD")/100} -> 0.0018744762 | AB17: =S17/$H$37 -> #VALUE! | AC17: =((AF17*I17)* ((TODAY()-BH17)/360))+(Q17-P17)%*AF17 -> 63400.972 | AD17: =_xll.BDP(AI17,"DS199") -> Government | AE17: =_xll.BDP(AI17,"px_ask") -> 91.306 | AF17: =IF(F17="USD",O17,(((_xll.BDP(F17&"USD CURNCY","PX_LAST")))*O17)) -> 500000 | AG17: =O17*P17/100 -> 500150 | AH17: =Q17*O17/100 -> 452110 | AI17: =G17& " ISIN" -> XS2384698994 ISIN | AJ17: {=VLOOKUP(IF(NOT(_xll.BDP($G17&" CORP",#REF!)="#N/A N/A"),(_xll.BDP($G17&" CORP",#REF!)),"-"), '[1]Country Codes'!$A$2:$B$253,2,0)} -> #REF! | AK17: {=IF(OR(_xll.BDP($AI17,"EX028")= "#N/A N/A", _xll.BDP($AI17,"EX028")="#N/A FIELD NOT APPLICABLE"), " ", _xll.BDP($AI17,"EX028"))} -> FixedIncome | AL17: =(IF(_xll.BDP($AI17&" ISIN","DZ282")="Y","Single line Bonds Cocos","Single line Bonds ex Cocos")) -> Single line Bonds ex Cocos | AM17: =(IF(_xll.BDP($G17&" ISIN","SP153")="#n/a n/a"," ",_xll.BDP($G17&" ISIN","SP153"))) -> 585.94219 | AN17: =TODAY() -> 45777 | AO17: =(((_xll.BDP(AI17,"DS032"))/360)*I17)*O17 -> 2807.2917 | AP17: =IF(F17="USD",AO17,(((_xll.BDP(F17&"USD CURNCY","PX_LAST")))*AO17)) -> 2807.2917 | AQ17: =S17/$S$159 -> 0.50017318 | AR17: =S17-AP17 -> 452110 | AS17: =IF((TEXT(_xll.BDP(AI17,"MATURITY"),"DD/MM/YYYY")="#N/A Field Not Applicable"),"Perp",_xll.BDP(AI17,"DS252")) -> 3.4168378 | AT17: =(IF(_xll.BDP($AI17&" ISIN","DT247")="Y","Yes","No")) -> No | AU17: =PROPER(IF(OR(_xll.BDP($AI17,"CPN_TYP")="#n/a N/A",_xll.BDP($AI17,"CPN_TYP")= "#N/A FIELD NOT APPLICABLE"), " ", _xll.BDP($AI17,"CPN_TYP"))) -> Fixed | BG17: =G17 -> XS2384698994 | BH17: 44467
A18: SYB | B18: AKCT | C18: 4371510 | D18: SocGen | E18: =_xll.BDP(AI18,"ds520") -> Panama Bonos del Tesoro | F18: =_xll.BDP(AI18,"crncy") -> USD | G18: PAL63444B5A9 | H18: =IF(_xll.BDP(AI18,"RTG_MOODY")="#N/A N/A","N/A",_xll.BDP(AI18,"RTG_MOODY"))&","&IF(_xll.BDP(AI18,"RTG_FITCH")="#N/A N/A","N/A",_xll.BDP(AI18,"RTG_FITCH"))&","&IF(_xll.BDP(AI18,"RTG_SP")="#N/A N/A","N/A",_xll.BDP(AI18,"RTG_SP")) -> Baa3,BB+,BBB- | I18: =_xll.BDP(AI18,"cpn")/100 -> 0.06375 | J18: =_xll.BDP($G18&" isin","YAS_BOND_YLD", "YAS_YLD_FLAG=15", "user_local_trade_date",AN18,"Yas_bond_px",$Q18)/100 -> 0.07791898 | K18: =_xll.BDP(AI18,"PAYMENT_RANK") -> Sr Unsecured | L18: =IF((TEXT(_xll.BDP(AI18,"MATURITY"),"DD/MM/YYYY")="#N/A Field Not Applicable"),"Perp",TEXT(_xll.BDP(AI18,"MATURITY"),"DD/MM/YYYY")) -> 25/07/2033 | M18: =(IF(_xll.BDP($AI18&" ISIN","DU003")="#n/a n/a"," ",_xll.BDP($AI18&" ISIN","DU003"))) -> 6.331365 | N18: =IF(_xll.BDP(AI18,"CALLABLE")="Y",_xll.BDP(AI18,"NXT_CALL_DT")," ") | O18: 500000 | P18: 98.785 | Q18: =_xll.BDP(AI18,"px_bid") -> 91.5 | R18: =IF(F18="USD",AG18,(((_xll.BDP(F18&"USD CURNCY","PX_LAST")))*AG18)) -> 493925 | S18: =IF(F18="USD",AH18,(((_xll.BDP(F18&"USD CURNCY","PX_LAST")))*AH18))+AP18 -> 466088.54 | T18: =U18*R18 -> -36425 | U18: =(Q18-P18)/P18 -> -0.073746014 | V18: {=IFERROR(_xll.BDP($G18&" ISIN","CHG_PCT_1D")/100,"")} -> -0.0018566561 | W18: {=IFERROR(_xll.BDP($G18&" ISIN","CHG_PCT_5D")/100,"")} -> -5.642254e-06 | X18: {=_xll.BDP($G18&" ISIN","CHG_PCT_1M")/100} -> -0.028234903 | Y18: {=_xll.BDP($G18&" ISIN","CHG_PCT_3M")/100} -> -0.022820485 | Z18: {=_xll.BDP($G18&" ISIN","CHG_PCT_6M")/100} -> -0.049322641 | AA18: {=_xll.BDP($G18&" ISIN","CHG_PCT_YTD")/100} -> 0.016328641 | AB18: =S18/$H$37 -> #VALUE! | AC18: =((AF18*I18)* ((TODAY()-BH18)/360))+(Q18-P18)%*AF18 -> 20684.375 | AD18: =_xll.BDP(AI18,"DS199") -> Government | AE18: =_xll.BDP(AI18,"px_ask") -> 92.822 | AF18: =IF(F18="USD",O18,(((_xll.BDP(F18&"USD CURNCY","PX_LAST")))*O18)) -> 500000 | AG18: =O18*P18/100 -> 493925 | AH18: =Q18*O18/100 -> 457500 | AI18: =G18& " ISIN" -> PAL63444B5A9 ISIN | AJ18: {=VLOOKUP(IF(NOT(_xll.BDP($G18&" CORP",#REF!)="#N/A N/A"),(_xll.BDP($G18&" CORP",#REF!)),"-"), '[1]Country Codes'!$A$2:$B$253,2,0)} -> #REF! | AK18: {=IF(OR(_xll.BDP($AI18,"EX028")= "#N/A N/A", _xll.BDP($AI18,"EX028")="#N/A FIELD NOT APPLICABLE"), " ", _xll.BDP($AI18,"EX028"))} -> FixedIncome | AL18: =(IF(_xll.BDP($AI18&" ISIN","DZ282")="Y","Single line Bonds Cocos","Single line Bonds ex Cocos")) -> Single line Bonds ex Cocos | AM18: =(IF(_xll.BDP($G18&" ISIN","SP153")="#n/a n/a"," ",_xll.BDP($G18&" ISIN","SP153"))) -> 402.66535 | AN18: =TODAY() -> 45777 | AO18: =(((_xll.BDP(AI18,"DS032"))/360)*I18)*O18 -> 8588.5417 | AP18: =IF(F18="USD",AO18,(((_xll.BDP(F18&"USD CURNCY","PX_LAST")))*AO18)) -> 8588.5417 | AQ18: =S18/$S$159 -> 0.51245577 | AR18: =S18-AP18 -> 457500 | AS18: =IF((TEXT(_xll.BDP(AI18,"MATURITY"),"DD/MM/YYYY")="#N/A Field Not Applicable"),"Perp",_xll.BDP(AI18,"DS252")) -> 8.238193 | AT18: =(IF(_xll.BDP($AI18&" ISIN","DT247")="Y","Yes","No")) -> No | AU18: =PROPER(IF(OR(_xll.BDP($AI18,"CPN_TYP")="#n/a N/A",_xll.BDP($AI18,"CPN_TYP")= "#N/A FIELD NOT APPLICABLE"), " ", _xll.BDP($AI18,"CPN_TYP"))) -> Fixed | BG18: =G18 -> PAL63444B5A9 | BH18: 45132
A19: SYB | B19: AKCT | C19: 4371510 | D19: SocGen | E19: =_xll.BDP(AI19,"ds520") -> SA Global Sukuk Ltd | F19: =_xll.BDP(AI19,"crncy") -> USD | G19: XS2908722783 | H19: =IF(_xll.BDP(AI19,"RTG_MOODY")="#N/A N/A","N/A",_xll.BDP(AI19,"RTG_MOODY"))&","&IF(_xll.BDP(AI19,"RTG_FITCH")="#N/A N/A","N/A",_xll.BDP(AI19,"RTG_FITCH"))&","&IF(_xll.BDP(AI19,"RTG_SP")="#N/A N/A","N/A",_xll.BDP(AI19,"RTG_SP")) -> Aa3,A+,N/A | I19: =_xll.BDP(AI19,"cpn")/100 -> 0.0425 | J19: =_xll.BDP($G19&" isin","YAS_BOND_YLD", "YAS_YLD_FLAG=15", "user_local_trade_date",AN19,"Yas_bond_px",$Q19)/100 -> 0.04731386 | K19: =_xll.BDP(AI19,"PAYMENT_RANK") -> Sr Unsecured | L19: =IF((TEXT(_xll.BDP(AI19,"MATURITY"),"DD/MM/YYYY")="#N/A Field Not Applicable"),"Perp",TEXT(_xll.BDP(AI19,"MATURITY"),"DD/MM/YYYY")) -> 02/10/2029 | M19: =(IF(_xll.BDP($AI19&" ISIN","DU003")="#n/a n/a"," ",_xll.BDP($AI19&" ISIN","DU003"))) -> 4.0585686 | N19: =IF(_xll.BDP(AI19,"CALLABLE")="Y",_xll.BDP(AI19,"NXT_CALL_DT")," ") -> 02/09/2029 | O19: 200000 | P19: 99.457 | Q19: =_xll.BDP(AI19,"px_bid") -> 98.098 | R19: =IF(F19="USD",AG19,(((_xll.BDP(F19&"USD CURNCY","PX_LAST")))*AG19)) -> 198914 | S19: =IF(F19="USD",AH19,(((_xll.BDP(F19&"USD CURNCY","PX_LAST")))*AH19))+AP19 -> 196880.72 | T19: =U19*R19 -> -2718 | U19: =(Q19-P19)/P19 -> -0.013664197 | V19: {=IFERROR(_xll.BDP($G19&" ISIN","CHG_PCT_1D")/100,"")} -> -0.00095301368 | W19: {=IFERROR(_xll.BDP($G19&" ISIN","CHG_PCT_5D")/100,"")} -> 0.0041165044 | X19: {=_xll.BDP($G19&" ISIN","CHG_PCT_1M")/100} -> 0.0026206185 | Y19: {=_xll.BDP($G19&" ISIN","CHG_PCT_3M")/100} -> 0.016804934 | Z19: {=_xll.BDP($G19&" ISIN","CHG_PCT_6M")/100} -> 0.0065599695 | AA19: {=_xll.BDP($G19&" ISIN","CHG_PCT_YTD")/100} -> 0.01517817 | AB19: =S19/$H$37 -> #VALUE! | AC19: =((AF19*I19)* ((TODAY()-BH19)/360))+(Q19-P19)%*AF19 -> 2240.3333 | AD19: =_xll.BDP(AI19,"DS199") -> Energy | AE19: =_xll.BDP(AI19,"px_ask") -> 98.352 | AF19: =IF(F19="USD",O19,(((_xll.BDP(F19&"USD CURNCY","PX_LAST")))*O19)) -> 200000 | AG19: =O19*P19/100 -> 198914 | AH19: =Q19*O19/100 -> 196196 | AI19: =G19& " ISIN" -> XS2908722783 ISIN | AJ19: {=VLOOKUP(IF(NOT(_xll.BDP($G19&" CORP",#REF!)="#N/A N/A"),(_xll.BDP($G19&" CORP",#REF!)),"-"), '[1]Country Codes'!$A$2:$B$253,2,0)} -> #REF! | AK19: {=IF(OR(_xll.BDP($AI19,"EX028")= "#N/A N/A", _xll.BDP($AI19,"EX028")="#N/A FIELD NOT APPLICABLE"), " ", _xll.BDP($AI19,"EX028"))} -> FixedIncome | AL19: =(IF(_xll.BDP($AI19&" ISIN","DZ282")="Y","Single line Bonds Cocos","Single line Bonds ex Cocos")) -> Single line Bonds ex Cocos | AM19: =(IF(_xll.BDP($G19&" ISIN","SP153")="#n/a n/a"," ",_xll.BDP($G19&" ISIN","SP153"))) -> 123.16472 | AN19: =TODAY() -> 45777 | AO19: =(((_xll.BDP(AI19,"DS032"))/360)*I19)*O19 -> 684.72222 | AP19: =IF(F19="USD",AO19,(((_xll.BDP(F19&"USD CURNCY","PX_LAST")))*AO19)) -> 684.72222 | AQ19: =S19/$S$159 -> 0.21646673 | AR19: =S19-AP19 -> 196196 | AS19: =IF((TEXT(_xll.BDP(AI19,"MATURITY"),"DD/MM/YYYY")="#N/A Field Not Applicable"),"Perp",_xll.BDP(AI19,"DS252")) -> 4.4271047 | AT19: =(IF(_xll.BDP($AI19&" ISIN","DT247")="Y","Yes","No")) -> No | AU19: =PROPER(IF(OR(_xll.BDP($AI19,"CPN_TYP")="#n/a N/A",_xll.BDP($AI19,"CPN_TYP")= "#N/A FIELD NOT APPLICABLE"), " ", _xll.BDP($AI19,"CPN_TYP"))) -> Fixed | BG19: =G19 -> XS2908722783 | BH19: 45567
