Workbook

Sheet Current Asset Allocation
G2: Creation Date: | H2: =NOW() -> 45769.598
A5: Investor Details | S5: Data Input Section --> | V5: Currency Exhange Rates | Y5: Complex Products IC Breach Check | AE5: Industry Exposure | AI5: Asset Allocation | BQ5: CNTRY_OF_RISK
A6: Custodian Name | C6: LGT Geneva | S6: Manual Input Color Code --> | AE6: Direct Equity only
A7: Account No. | C7: 2620173 | V7: Currency | W7: Exchange Rate | Y7: =A8 -> Investment Risk Profile | Z7: =C8 -> Moderate | AE7: Country | AF7: % | AG7: Market Value ($) | AI7: Asset Class | AJ7: % of Gross Assets | AK7: Market Value ($) | AM7: SP Dropdown List
A8: Investment Risk Profile | C8: Moderate | V8: USD | AE8: Energy | AF8: =AG8/$AG$19 -> 0 | AG8: =+SUMIF($D$155:$D$157,AE8,$O$155:$O$157) -> 0 | AI8: Cash | AJ8: =AK8/$AK$12 -> #VALUE! | AK8: =D25 -> 8652.57 | AM8: Rates Linked Notes
A9: Investment Objective/ Return Expectations | C9: Capital preservation accepting small degree of risk and volatility to seek some degree of appreciation. | S9: Last updated | V9: GBP | W9: =_xll.BDP("GBPUSD CURNCY", "PX_LAST") -> 1.3379 | Y9: Complex Products | Z9: USD | AA9: % of gross | AE9: Materials | AF9: =AG9/$AG$19 -> 1 | AG9: =+SUMIF($D$155:$D$157,AE9,$O$155:$O$157) -> 43120.836 | AI9: Fixed Income | AJ9: =AK9/$AK$12 -> #VALUE! | AK9: =D29 -> #VALUE! | AM9: Equity Linked Structured Products
A10: Restrictions/ Exclusions, If Any | C10: None | S10: XX | V10: EUR | W10: =_xll.BDP("EURUSD CURNCY", "PX_LAST") -> 1.1503 | Y10: Equity Structured Products | Z10: =D39 -> 0 | AA10: =Z10/$C$14 -> #VALUE! | AE10: Industrials | AF10: =AG10/$AG$19 -> 0 | AG10: =+SUMIF($D$155:$D$157,AE10,$O$155:$O$157) -> 0 | AI10: Equity | AJ10: =AK10/$AK$12 -> #VALUE! | AK10: =D35 -> #VALUE! | AM10: Commodities Linked Structured Products
A11: Complex Products/ Derivatives K&E | C11: Yes | S11: 45470 | V11: AED | W11: =_xll.BDP("AEDUSD CURNCY", "PX_LAST") -> 0.27225327 | Y11: Credit Structured Products/CLNs/Bond Repacks | Z11: =D33 -> 0 | AA11: =Z11/$C$14 -> #VALUE! | AE11: Consumer Discretionary | AF11: =AG11/$AG$19 -> 0 | AG11: =+SUMIF($D$155:$D$157,AE11,$O$155:$O$157) -> 0 | AI11: Alternatives | AJ11: =AK11/$AK$12 -> #VALUE! | AK11: =D40 -> 0 | AM11: 100% Cap Protected FRN
V12: CHF | W12: =_xll.BDP("CHFUSD CURNCY", "PX_LAST") -> 1.2343 | Y12: FRNs/Rates Structured Products | Z12: =D34 -> 0 | AA12: =Z12/$C$14 -> #VALUE! | AE12: Consumer Staples | AF12: =AG12/$AG$19 -> 0 | AG12: =+SUMIF($D$155:$D$157,AE12,$O$155:$O$157) -> 0 | AI12: Total | AJ12: =SUM(AJ8:AJ11) -> #VALUE! | AK12: =SUM(AK8:AK11) -> #VALUE! | AM12: Credit Linked Notes
A13: Consolidated AUMs | V13: AUD | W13: =_xll.BDP("AUDUSD CURNCY", "PX_LAST") -> 0.6406 | Y13: FX & Commodity linked Notes/Accu (remaining large notional) | Z13: =D42 -> 0 | AA13: =Z13/$C$14 -> #VALUE! | AE13: Health Care | AF13: =AG13/$AG$19 -> 0 | AG13: =+SUMIF($D$155:$D$157,AE13,$O$155:$O$157) -> 0 | AI13: Balance check | AK13: =AK12-C14 -> #VALUE!
A14: Gross Assets ($) | C14: =D49 -> #VALUE! | V14: HKD | W14: =_xll.BDP("HKDUSD CURNCY", "PX_LAST") -> 0.12892 | Y14: Cocos | Z14: =D31 -> 0 | AA14: =Z14/$C$14 -> #VALUE! | AE14: Financials | AF14: =AG14/$AG$19 -> 0 | AG14: =+SUMIF($D$155:$D$157,AE14,$O$155:$O$157) -> 0
A15: Total Liabilities ($) | C15: =N139 -> 0 | Y15: Hedge Funds/Private Markets/VC | Z15: =D45+D46 -> 0 | AA15: =Z15/$C$14 -> #VALUE! | AE15: Information Technology | AF15: =AG15/$AG$19 -> 0 | AG15: =+SUMIF($D$155:$D$157,AE15,$O$155:$O$157) -> 0
A16: Net Assets ($) | C16: =C14-C15 -> #VALUE! | Y16: Total | Z16: =SUM(Z10:Z15) -> 0 | AA16: =Z16/$C$14 -> #VALUE! | AE16: Communication Services | AF16: =AG16/$AG$19 -> 0 | AG16: =+SUMIF($D$155:$D$157,AE16,$O$155:$O$157) -> 0
A17: Wtd Avg Lending Rate p.a. | C17: =O139 -> 0 | AE17: Utilities | AF17: =AG17/$AG$19 -> 0 | AG17: =+SUMIF($D$155:$D$157,AE17,$O$155:$O$157) -> 0
A18: Loan Interest ($) | C18: =IFERROR(C15*C17,0) -> 0 | AE18: Real Estate | AF18: =AG18/$AG$19 -> 0 | AG18: =+SUMIF($D$155:$D$157,AE18,$O$155:$O$157) -> 0
A19: Annual Cashflows | C19: =G49 -> 0 | AE19: Total | AF19: =SUM(AF8:AF18) -> 1 | AG19: =SUM(AG8:AG18) -> 43120.836
A20: Net Cashflows | C20: =C19-C18 -> 0
A21: Net Cashflow Yield % | C21: =C20/C16 -> #VALUE!
A23: Current Asset Allocation - Consolidated
A24: Product | B24: Allocation % | C24: Notional Value $ | D24: Mkt. Value $ | E24: Wtd Avg. Yield % | F24: Wtd Avg. Cpn/ Dvd Inc % | G24: Annual Cashflows $ | H24: P/L ($) | I24: P/L % | S24: Manual Entry
A25: Cash | B25: =SUM(B26:B28) -> #VALUE! | C25: =SUM(C26:C28) -> 8652.57 | D25: =SUM(D26:D28) -> 8652.57 | F25: =SUMPRODUCT(C26:C28,F26:F28)/C25 -> 0 | G25: =IFERROR(C25*F25,0) -> 0 | H25: =SUM(H26:H28) -> 0 | I25: =IFERROR(H25/(D25-H25), 0) -> 0 | S25: Performance Tracking | T25: NAV | U25: Cumulative Deposit/ Withdrawal | V25: YTD Performance as per statement | X25: Cumulative Deposit/ Withdrawal | Z25: {=LOOKUP(2,1/(U28:U40<>""),U28:U40)} -> 2000
A26: Cash | B26: =D26/$D$49 -> #VALUE! | C26: =SUM(E131:E136) -> 8652.57 | D26: =C26 -> 8652.57 | F26: =G26/D26 -> 0 | G26: =SUM(I131:I136) -> 0 | I26: =IFERROR(H26/(D26-H26), 0) -> 0
A27: Fiduciary Deposits | B27: =D27/$D$49 -> #VALUE! | C27: =SUM(E137:E138) -> 0 | D27: =C27 -> 0 | F27: =IFERROR(G27/D27,0) -> 0 | G27: =SUM(I137:I138) -> 0 | I27: =IFERROR(H27/(D27-H27), 0) -> 0 | X27: YTD Performance %
A28: Cash Management Solutions (100% Cap Protected FRN) | B28: =D28/$D$49 -> #VALUE! | C28: =C242 -> 0 | D28: =D242 -> 0 | F28: =F242 -> 0 | G28: =IFERROR(C28*F28,0) -> 0 | H28: =H242 -> 0 | I28: =IFERROR(H28/(D28-H28), 0) -> 0 | S28: =DATE(2024,12,1) -> 45627 | T28: 785000 | U28: 7000
A29: Fixed Income | B29: =SUM(B30:B34) -> #VALUE! | C29: =SUM(C30:C34) -> #VALUE! | D29: =SUM(D30:D34) -> #VALUE! | F29: =SUMPRODUCT(C30:C34,F30:F34)/C29 -> #VALUE! | G29: =IFERROR(C29*F29,0) -> 0 | H29: =SUM(H30:H34) -> #VALUE! | I29: =IFERROR(H29/(D29-H29), 0) -> 0 | S29: =EDATE(S28,1) -> 45658 | T29: 780000 | U29: 2000 | X29: =(($C$16 - $T$28) - $Z$25) /($T$28) -> #VALUE!
A30: Single line Bonds ex Cocos | B30: =D30/$D$49 -> #VALUE! | C30: =C243 -> #VALUE! | D30: =D243 -> #VALUE! | E30: =E243 -> 0 | F30: =F243 -> 0 | G30: =IFERROR(C30*F30,0) -> 0 | H30: =H243 -> #VALUE! | I30: =G243 -> 0 | S30: =EDATE(S29,1) -> 45689 | T30: 800000
A31: Single line Bonds Cocos | B31: =D31/$D$49 -> #VALUE! | C31: =C244 -> 0 | D31: =D244 -> 0 | E31: =E244 -> 0 | F31: =F244 -> 0 | G31: =IFERROR(C31*F31,0) -> 0 | H31: =H244 -> 0 | I31: =G244 -> 0 | S31: =EDATE(S30,1) -> 45717 | T31: 1000000
A32: FI Bond Funds/ ETFs | B32: =D32/$D$49 -> #VALUE! | C32: =C245 -> 0 | D32: =D245 -> 0 | E32: =E245 -> - | F32: =F245 -> 0 | G32: =IFERROR(C32*F32,0) -> 0 | H32: =H245 -> 0 | I32: =IFERROR(H32/(D32-H32), 0) -> 0 | S32: =EDATE(S31,1) -> 45748
A33: Credit Linked Notes | B33: =D33/$D$49 -> #VALUE! | C33: =C246 -> 0 | D33: =D246 -> 0 | E33: =E246 -> - | F33: =F246 -> 0 | G33: =IFERROR(C33*F33,0) -> 0 | H33: =H246 -> 0 | I33: =IFERROR(H33/(D33-H33), 0) -> 0 | S33: =EDATE(S32,1) -> 45778
A34: Rates Linked Notes | B34: =D34/$D$49 -> #VALUE! | C34: =C247 -> 0 | D34: =D247 -> 0 | E34: =E247 -> - | F34: =F247 -> 0 | G34: =IFERROR(C34*F34,0) -> 0 | H34: =H247 -> 0 | I34: =IFERROR(H34/(D34-H34), 0) -> 0 | S34: =EDATE(S33,1) -> 45809
A35: Equity | B35: =SUM(B36:B39) -> #VALUE! | C35: =SUM(C36:C39) -> #VALUE! | D35: =SUM(D36:D39) -> #VALUE! | F35: =SUMPRODUCT(C36:C39,F36:F39)/C35 -> #VALUE! | G35: =IFERROR(C35*F35,0) -> 0 | H35: =SUM(H36:H39) -> #VALUE! | I35: =IFERROR(H35/(D35-H35), 0) -> 0 | S35: =EDATE(S34,1) -> 45839
A36: Single Line Equity | B36: =D36/$D$49 -> #VALUE! | C36: =C248 -> #VALUE! | D36: =D248 -> #VALUE! | E36: =E248 -> - | F36: =F248 -> 0 | G36: =IFERROR(C36*F36,0) -> 0 | H36: =H248 -> #VALUE! | I36: =IFERROR(H36/(D36-H36), 0) -> 0 | S36: =EDATE(S35,1) -> 45870
A37: Equity Funds/ ETFs | B37: =D37/$D$49 -> #VALUE! | C37: =C249 -> 0 | D37: =D249 -> 0 | E37: =E249 -> - | F37: =F249 -> 0 | G37: =IFERROR(C37*F37,0) -> 0 | H37: =H249 -> 0 | I37: =IFERROR(H37/(D37-H37), 0) -> 0 | S37: =EDATE(S36,1) -> 45901
A38: Mixed Allocation Funds | B38: =D38/$D$49 -> #VALUE! | C38: =C250 -> 0 | D38: =D250 -> 0 | E38: =E250 -> - | F38: =F250 -> 0 | G38: =IFERROR(C38*F38,0) -> 0 | H38: =H250 -> 0 | I38: =IFERROR(H38/(D38-H38), 0) -> 0 | S38: =EDATE(S37,1) -> 45931
A39: Equity Linked Str. Products | B39: =D39/$D$49 -> #VALUE! | C39: =C251 -> 0 | D39: =D251 -> 0 | E39: =E251 -> - | F39: =F251 -> 0 | G39: =IFERROR(C39*F39,0) -> 0 | H39: =H251 -> 0 | I39: =IFERROR(H39/(D39-H39), 0) -> 0 | S39: =EDATE(S38,1) -> 45962
A40: Alternatives | B40: =SUM(B41:B47) -> #VALUE! | C40: =SUM(C41:C47) -> 0 | D40: =SUM(D41:D47) -> 0 | F40: =IFERROR(SUMPRODUCT(C41:C47,F41:F47)/C40,0) -> 0 | G40: =IFERROR(C40*F40,0) -> 0 | H40: =SUM(H41:H47) -> 0 | I40: =IFERROR(H40/(D40-H40), 0) -> 0 | S40: =EDATE(S39,1) -> 45992
A41: Commodities & Precious Metals | B41: =D41/$D$49 -> #VALUE! | C41: =C252 -> 0 | D41: =D252 -> 0 | E41: =E252 -> - | F41: =F252 -> 0 | G41: =IFERROR(C41*F41,0) -> 0 | H41: =H252 -> 0 | I41: =IFERROR(H41/(D41-H41), 0) -> 0
A42: Commodities Linked Str. Products | B42: =D42/$D$49 -> #VALUE! | C42: =C253 -> 0 | D42: =D253 -> 0 | E42: =E253 -> - | F42: =F253 -> 0 | G42: =IFERROR(C42*F42,0) -> 0 | H42: =H253 -> 0 | I42: =IFERROR(H42/(D42-H42), 0) -> 0
A43: Commodity ETFs | B43: =D43/$D$49 -> #VALUE! | C43: =C254 -> 0 | D43: =D254 -> 0 | E43: =E254 -> - | F43: =F254 -> 0 | G43: =IFERROR(C43*F43,0) -> 0 | H43: =H254 -> 0 | I43: =IFERROR(H43/(D43-H43), 0) -> 0
A44: Alternative ETFs | B44: =D44/$D$49 -> #VALUE! | C44: =C255 -> 0 | D44: =D255 -> 0 | E44: =E255 -> - | F44: =F255 -> 0 | G44: =IFERROR(C44*F44,0) -> 0 | H44: =H255 -> 0 | I44: =IFERROR(H44/(D44-H44), 0) -> 0
...

Sheet PRR reference
A2: Investment Risk Profile | B2: Corresponding PRR Allowed | C2: Corresponding PRR Allowed with K &E
A3: Conservative | B3: 1 | C3: 2
A4: Moderately Conservative | B4: 2 | C4: 3
A5: Moderate | B5: 3 | C5: 4
A6: Moderately Aggressive | B6: 4 | C6: 5
A7: Aggressive | B7: 5 | C7: 5
A10: Product | B10: Product - Sub Category | C10: PRR | E10: PRR | F10: Risk Definition
A11: Fiduciary Deposits - A Rated Banks | C11: 1 | E11: 1 | F11: Low Risk
A12: US Treasuries | C12: 2 | E12: 2 | F12: Moderately Low Risk
A13: Money Market Funds | C13: 2 | E13: 3 | F13: Moderate Risk
A14: Bonds | B14: AA+, AA, AA-, | C14: 2 | E14: 4 | F14: Moderately High Risk
B15: A+, A, A-, BBB+, BBB, BBB- | C15: 3 | E15: 5 | F15: High Risk
B16: BB+, BB, BB- | C16: 4
B17: B+, B, B-, CCC+, CCC, CCC-, Not rated | C17: 5
B18: Payment Rank Tier1, Tier 2, TLACs - irrespective of Rating | C18: 5
A19: Bond Repacks | B19: Underlying Bond - AA+, AA, AA-, A+, A, A- | C19: 3
B20: Underlying Bond - BBB+, BBB, BBB- | C20: 4
B21: Underlying Bond - BB+, BB, BB- | C21: 5
B22: Underlying Bond - B+, B, B-, CCC+, CCC, CCC-, Not rated | C22: 5
A23: Equity | B23: DM Blue Chips/ Large Caps | C23: 4
B24: DM Mid Cap/Small Cap | C24: 5
B25: EM Large Cap/ Mid Cap/ Small Cap | C25: 5
B26: Accumulators/ Decumulators | C26: 5
B27: Short Equity options | C27: 5
B28: Short Index Options | C28: 5
A29: Funds | B29: Equity Sectoral | C29: 5
B30: Equity Thematic | C30: 5
B31: Hedge Funds | C31: 5
B32: Private Equity Funds | C32: 5
B33: Real Estate Funds | C33: 5
B34: Bond Funds - IG DM | C34: 3
B35: Bond Funds - IG EM | C35: 4
B36: Bond Funds - HY | C36: 5
B37: Mixed Allocation | C37: 4/5
A38: Structured Products | B38: Capital Protected Structure Notes | C38: 3
B39: Fixed Coupon Notes | C39: 5
B40: Index Linked Notes | C40: 5
B41: Reverse Convertible | C41: 5
B42: Warrants | C42: 5
B43: Discount Certificate | C43: 5
...

Sheet Bond Graph Data Sheet
A1: ISIN | B1: Security Name | C1: Weight | D1: Maturity | E1: Country | F1: Sector | G1: Coupon | H1: YTW | I1: Duration | J1: Currency | K1: Ratings | L1: BBG COMPOSITE | M1: Rating Score | N1: IG / HY | O1: Years to Maturity
A2: ='Current Asset Allocation'!C147 -> PAL63444B5A9 | B2: ='Current Asset Allocation'!A147 -> Panama Bonos del Tesoro | C2: ='Current Asset Allocation'!AG147 -> #DIV/0! | D2: ='Current Asset Allocation'!H147 -> 25/07/2033 | E2: ='Current Asset Allocation'!Z147 -> Panama | F2: ='Current Asset Allocation'!T147 -> Government | G2: ='Current Asset Allocation'!E147 -> 0.06375 | H2: ='Current Asset Allocation'!F147 -> 0.07836704 | I2: ='Current Asset Allocation'!I147 -> 6.3524976 | J2: ='Current Asset Allocation'!B147 -> USD | K2: ='Current Asset Allocation'!D147 -> Baa3,BB+,BBB- | L2: {=_xll.BDP(A2&" ISIN","RA007")} -> BB+ | M2: =VLOOKUP(L2,$A$51:$D$69,4,0) -> 7 | N2: =VLOOKUP(L2,$E$51:$F$69,2,0) -> HY | O2: ='Current Asset Allocation'!AI147 -> 8.257358
A3: ='Current Asset Allocation'!C148 -> US404280DT33 | B3: ='Current Asset Allocation'!A148 -> #N/A Connection | C3: ='Current Asset Allocation'!AG148 -> #VALUE! | D3: ='Current Asset Allocation'!H148 -> #N/A Connection | E3: ='Current Asset Allocation'!Z148 -> United Kingdom | F3: ='Current Asset Allocation'!T148 -> #N/A Connection | G3: ='Current Asset Allocation'!E148 -> #VALUE! | H3: ='Current Asset Allocation'!F148 -> #VALUE! | I3: ='Current Asset Allocation'!I148 -> #N/A Connection | J3: ='Current Asset Allocation'!B148 -> #N/A Connection | K3: ='Current Asset Allocation'!D148 -> #N/A Connection,#N/A Connection,#N/A Connection | L3: {=_xll.BDP(A3&" ISIN","RA007")} -> #N/A Connection | M3: =VLOOKUP(L3,$A$51:$D$69,4,0) -> #N/A | N3: =VLOOKUP(L3,$E$51:$F$69,2,0) -> #N/A | O3: ='Current Asset Allocation'!AI148 -> #N/A Connection
A4: ='Current Asset Allocation'!C149 -> XS2451768720 | B4: ='Current Asset Allocation'!A149 -> QIC Cayman Ltd | C4: ='Current Asset Allocation'!AG149 -> #DIV/0! | D4: ='Current Asset Allocation'!H149 -> Perp | E4: ='Current Asset Allocation'!Z149 -> Qatar | F4: ='Current Asset Allocation'!T149 -> Financial | G4: ='Current Asset Allocation'!E149 -> 0.0675 | H4: ='Current Asset Allocation'!F149 -> 0.06210726 | I4: ='Current Asset Allocation'!I149 -> 2.6764249 | J4: ='Current Asset Allocation'!B149 -> USD | K4: ='Current Asset Allocation'!D149 -> N/A,N/A,BBB | L4: BBB | M4: =VLOOKUP(L4,$A$51:$D$69,4,0) -> 5 | N4: =VLOOKUP(L4,$E$51:$F$69,2,0) -> IG | O4: ='Current Asset Allocation'!AI149 -> Perp
C29: =SUM(C2:C28) -> #DIV/0! | G29: =SUMPRODUCT($C$2:$C$28,G2:G28) -> #DIV/0! | H29: =SUMPRODUCT($C$2:$C$28,H2:H28) -> #DIV/0! | I29: =SUMPRODUCT($C$2:$C$28,I2:I28) -> #DIV/0! | M29: =SUMPRODUCT($C$2:$C$28,M2:M28) -> #DIV/0!
A32: MATURITY PROFILE
A34: Year | B34: # Positions | C34: Weight | E34: Year | F34: Weight
A35: >0 | B35: =COUNTIFS($O$2:$O$28,$A$35,$O$2:$O$28,$A$36) -> 0 | C35: =SUMIFS($C$2:$C$28,$O$2:$O$28,$A$35,$O$2:$O$28,$A$36) -> 0 | E35: 0-1.5 | F35: =C35 -> 0
A36: <1.5 | E36: 1.5-4 | F36: =C37 -> 0
A37: >=1.5 | B37: =COUNTIFS($O$2:$O$28,$A$37,$O$2:$O$28,$A$38) -> 0 | C37: =SUMIFS($C$2:$C$28,$O$2:$O$28,$A$37,$O$2:$O$28,$A$38) -> 0 | E37: 4-7 | F37: =C39 -> 0
A38: <4 | E38: 7-15 | F38: =C41 -> #DIV/0!
A39: >=4 | B39: =COUNTIFS($O$2:$O$28,$A$39,$O$2:$O$28,$A$40) -> 0 | C39: =SUMIFS($C$2:$C$28,$O$2:$O$28,$A$39,$O$2:$O$28,$A$40) -> 0 | E39: 15+ | F39: =C43 -> 0
A40: <7 | E40: Perpetual | F40: =C44 -> #DIV/0!
A41: >=7 | B41: =COUNTIFS($O$2:$O$28,$A$41,$O$2:$O$28,$A$42) -> 1 | C41: =SUMIFS($C$2:$C$28,$O$2:$O$28,$A$41,$O$2:$O$28,$A$42) -> #DIV/0! | F41: =SUM(F35:F40) -> #DIV/0!
A42: <15
A43: >=15 | B43: =COUNTIF($O$2:$O$28,$A$43) -> 0 | C43: =SUMIF($O$2:$O$28,$A$43,$C$2:$C$28) -> 0
A44: Perp | B44: =COUNTIF($O$2:$O$28,$A$44) -> 1 | C44: =SUMIF($O$2:$O$28,$A$44,$C$2:$C$28) -> #DIV/0!
B45: =SUM(B35:B44) -> 2 | C45: =SUM(C35:C44) -> #DIV/0!
A48: CREDIT RATING METRICS
A51: A+ | B51: =COUNTIF($L$2:$L$28,A51) -> 0 | C51: =SUMIF($L$2:$L$28,A51,$C$2:$C$28) -> 0 | D51: 1 | E51: A+ | F51: IG
A52: A | B52: =COUNTIF($L$2:$L$28,A52) -> 0 | C52: =SUMIF($L$2:$L$28,A52,$C$2:$C$28) -> 0 | D52: 2 | E52: A | F52: IG
A53: A- | B53: =COUNTIF($L$2:$L$28,A53) -> 0 | C53: =SUMIF($L$2:$L$28,A53,$C$2:$C$28) -> 0 | D53: 3 | E53: A- | F53: IG
A54: BBB+ | B54: =COUNTIF($L$2:$L$28,A54) -> 0 | C54: =SUMIF($L$2:$L$28,A54,$C$2:$C$28) -> 0 | D54: 4 | E54: BBB+ | F54: IG
A55: BBB | B55: =COUNTIF($L$2:$L$28,A55) -> 1 | C55: =SUMIF($L$2:$L$28,A55,$C$2:$C$28) -> #DIV/0! | D55: 5 | E55: BBB | F55: IG
A56: BBB- | B56: =COUNTIF($L$2:$L$28,A56) -> 0 | C56: =SUMIF($L$2:$L$28,A56,$C$2:$C$28) -> 0 | D56: 6 | E56: BBB- | F56: IG
A57: BB+ | B57: =COUNTIF($L$2:$L$28,A57) -> 1 | C57: =SUMIF($L$2:$L$28,A57,$C$2:$C$28) -> #DIV/0! | D57: 7 | E57: BB+ | F57: HY
A58: BB | B58: =COUNTIF($L$2:$L$28,A58) -> 0 | C58: =SUMIF($L$2:$L$28,A58,$C$2:$C$28) -> 0 | D58: 8 | E58: BB | F58: HY
A59: BB- | B59: =COUNTIF($L$2:$L$28,A59) -> 0 | C59: =SUMIF($L$2:$L$28,A59,$C$2:$C$28) -> 0 | D59: 9 | E59: BB- | F59: HY
A60: B+ | B60: =COUNTIF($L$2:$L$28,A60) -> 0 | C60: =SUMIF($L$2:$L$28,A60,$C$2:$C$28) -> 0 | D60: 10 | E60: B+ | F60: HY
A61: B | B61: =COUNTIF($L$2:$L$28,A61) -> 0 | C61: =SUMIF($L$2:$L$28,A61,$C$2:$C$28) -> 0 | D61: 11 | E61: B | F61: HY
A62: B- | B62: =COUNTIF($L$2:$L$28,A62) -> 0 | C62: =SUMIF($L$2:$L$28,A62,$C$2:$C$28) -> 0 | D62: 12 | E62: B- | F62: HY
... A68: below C | B68: =COUNTIF($L$2:$L$28,A68) -> 0 | C68: =SUMIF($L$2:$L$28,A68,$C$2:$C$28) -> 0 | D68: 18 | E68: below C | F68: HY
B69: =SUM(B51:B59) -> 2 | C69: =SUM(C51:C59) -> #DIV/0!
A72: COUNTRY EXPOSURE (below list of countries not exhaustive - will need to add as and when needed)
A74: Country | B74: Exposure
A75: India | B75: =SUMIF($E$2:$E$28,A75,$C$2:$C$28) -> 0
A76: Ireland | B76: =SUMIF($E$2:$E$28,A76,$C$2:$C$28) -> 0
A77: UAE | B77: =SUMIF($E$2:$E$28,A77,$C$2:$C$28) -> 0
A78: Brazil | B78: =SUMIF($E$2:$E$28,A78,$C$2:$C$28) -> 0
A79: Saudi Arabia | B79: =SUMIF($E$2:$E$28,A79,$C$2:$C$28) -> 0
...
